Workbook

Sheet Guide
A1: RPG tour par tour : bestiaire de la tour et zones de chasse
A2: Stats des monstres, altérations, dégâts élémentaires, zones de chasse, XP, or et butin, d'après le diagramme du projet.
A4: OBJECTIF
A5: Contenu | B5: 92 monstres répartis en 30 zones et 10 biomes (un élément par biome). Chaque monstre a ses stats (proportionnelles à son niveau), ses altérations, son élément de dégâts, ses faiblesses ses récompenses et son butin (chance de drop et rareté des objets).
A6: Principe de niveau | B6: Un monstre a le niveau de son étage (étage 84 → niveau 84). En zone de chasse, son niveau est tiré entre l'étage de la zone et cet étage + 10 (étage 55 → niveaux 55 à 65).
A7: ONGLETS
A8: Monstres | B8: Les 92 monstres. Les stats sont calculées au niveau d'étage de la zone ; la cellule jaune du haut force un autre niveau pour tous. Colonnes « Butin » : chance de drop et probabilité de chaque rareté.
A9: Calculateur | B9: Un monstre à un niveau choisi, plus ses stats aux niveaux minimum et maximum de sa zone de chasse, et la chance réelle d'appliquer ses altérations.
A10: Zones | B10: Les 30 zones : étages concernés, déblocage de la zone de chasse, niveaux, XP et or par heure de chasse.
A11: Étages | B11: Les 100 étages : type (normal, boss, dragon), durée, dégâts subis estimés et récompenses.
A12: Simulation | B12: Combien de temps faut-il pour atteindre l'étage 100 ? Le joueur farme les zones de chasse quand il est en retard de niveau.
A13: Récompenses | B13: Courbes d'XP et d'or par niveau (1 à 110), XP pour monter de niveau et prix des équipements (Commun → Légendaire), repris dans l'onglet Boutique.
A14: Butin | B14: Chance de drop par rang, rareté des objets par biome (monstres, boss, dragons), Uniques par biome et butin attendu pendant la montée.
A15: Altérations | B15: Les 17 altérations (debuffs) avec effet, durée, cumul maximum et limites.
A16: Éléments | B16: Biomes, faiblesses et résistances de chaque élément (source : fichier Éléments/Fusions).
A17: Rôles | B17: Multiplicateurs de stats par rôle (bête, brute, mage…) et par rang (faible, normal, fort, boss, dragon).
A18: Paramètres | B18: Tous les chiffres d'équilibrage : courbe de niveau, joueur de référence, composition des étages, XP, or, durée de jeu.
A19: RÈGLES DE LA TOUR
A20: Étage normal | B20: 3 vagues de 3 monstres tirés dans la zone de la tranche de 5 étages (étages 1–4 : Forêt de chasse, 6–8 : Village gobelin, etc.).
A21: Étage boss (×5) | B21: 5 vagues : 4 vagues normales, puis le boss accompagné de 2 escortes. Battre l'étage débloque la zone de chasse de même numéro.
A22: Étage dragon (×9) | B22: Une seule vague : le dragon de l'élément du biome, un sac à PV (20 tours pour le tuer, coups modérés).
A23: Zones de chasse | B23: Mêmes monstres que la zone, sans le boss, affrontables à l'infini. Les tannières de dragon n'ont que le boss : pas de zone de chasse.
A24: Butin | B24: Faible 3 %, Normal 5 %, Fort 8 % de chance d'objet ; boss 1,4 objet, dragon 2,5 objets. La rareté dépend du biome : Super rare dès l'étage 11, Épique 21, Mythique 31, Légendaire 51 ; boss et dragons ont de l'avance et font tomber les Uniques de leur biome.
A25: FORMULES
A26: Facteur de niveau | B26: a + (1 − a) × ((N − 1) / 99) ^ p, avec a = 5 % et p = 1,2. Même courbe que les équipements : 1,00 au niveau 100.
A27: PV | B27: Dégâts moyens du joueur par tour (niveau 100 : 788) × facteur de niveau × tours pour tuer (rang) × PV du rôle.
A28: Force / Magie | B28: PV du joueur de référence × facteur de niveau × dégâts par coup (rang) × attaque du rôle ÷ (1 − réduction moyenne du joueur). Les attaques Mixtes donnent 75 % en Force et 75 % en Magie.
A29: Défenses | B29: Résistance, Armure et Agilité étalon × facteur de niveau × rôle (× rang pour les défenses). Précision, critique et pénétration ne dépendent pas du niveau.
A30: Dégâts élémentaires | B30: Chaque monstre inflige l'élément de son biome. La part élémentaire de ses dégâts dépend du rôle (100 % pour un élémentaire, 40 % pour une brute) ; seule cette part subit les avantages ×1,5 / ×0,75 et la Résistance élémentaire du joueur. Biome Neutre : 0 %.
A31: XP et or | B31: XP et or d'un monstre Normal = coefficient × niveau ^ exposant ; × rang (faible 0,7 ; fort 1,4 ; boss 8 ; dragon 12). XP pour monter = XP monstre × (10 + 0,7 × niveau).
A32: HYPOTHÈSES À VALIDER
A33: Joueur de référence | B33: Le diagramme ne donne pas les stats du joueur : niveau 100 = 1 600 Vitalité (PV = Vitalité × 10), 700 en Force/Magie. Les monstres sont calibrés dessus ; modifiez-les dans Paramètres §2.
A34: Composition des vagues | B34: 3 monstres par vague, 2 escortes avec le boss : à confirmer. Les attaques de zone économisent 25 % des tours.
A35: Zones et étages | B35: Les étages intermédiaires utilisent les monstres de la zone de leur tranche de 5 (hypothèse). L'étage ×9 est la tannière du dragon.
A36: Durée de jeu | B36: Résultat de la simulation : environ 7 h pour atteindre l'étage 100 (3 h de combats + 4 h de farm). En 1 h, c'est impossible : même sans farmer, les combats de la tour durent plus de 3 h.
A37: Difficulté | B37: Le seuil « Trop dur » (70 % des PV perdus sur la pire vague) ne tient pas compte des soins entre vagues ni des boucliers, non définis dans le diagramme.
A38: Prix | B38: Boutique de la taverne détaillée dans l'onglet Boutique : renouvellement toutes les heures, ressources, équipements (Commun → Épique) et personnages, avec le temps de chasse équivalent.
A39: Butin | B39: Objet pour la classe du joueur, slot au hasard, amélioration +0, matériau du palier de l'étage. Taux de départ calibrés pour ~1 objet par slot et par biome pendant la montée : à ajuster après tests.
A40: POINTS À VÉRIFIER DANS LE DIAGRAMME
A41: Noms de zones | B41: « Orage » apparaît pour les étages 80 et 90 : la zone 90 (anges) s'appelle ici « Orage (90) » comme dans le diagramme, à renommer (Palais céleste ?). « Maris des morts » est lu « Marais des morts ».
...

Sheet Monstres
A1: Bestiaire : stats, altérations, dégâts élémentaires et butin des 92 monstres
A2: Les stats sont calculées au niveau d'étage de la zone (étage 84 → niveau 84). Pour un autre niveau, utilisez la cellule jaune ou le Calculateur. Colonnes AK à AT : chance de butin et rareté de l'objet (réglages dans l'onglet Butin).
A3: Niveau forcé (laisser vide = niveau d'étage de la zone)
A4: Légende : texte bleu sur fond jaune = donnée modifiable ; le reste est calculé. Altérations : chance d'application avant résistance du joueur.
A6: ID | B6: Étage de la zone | C6: Zone | D6: Biome | E6: Élément | F6: Monstre | G6: Boss ? | H6: Rang | I6: Rôle | J6: Type d'attaque | K6: Niveau | L6: PV | M6: Force | N6: Magie | O6: Résistance | P6: Armure | Q6: Agilité | R6: Initiative | S6: Précision | T6: Chance de critique | U6: Dégâts critiques | V6: Pénétration | W6: Rés. aux altérations | X6: Réduction physique (estim.) | Y6: Réduction magique (estim.) | Z6: Part de dégâts élémentaires | AA6: Dégâts par coup (% PV joueur) | AB6: Tours pour le tuer | AC6: Récompenses × | AD6: Faible contre (×1,5) | AE6: Résiste à (×0,75) | AF6: Altération 1 | AG6: Chance 1 | AH6: Altération 2 | AI6: Chance 2 | AJ6: XP | AK6: Or | AL6: Chance de butin | AM6: Objets attendus / victoire | AN6: % Commun | AO6: % Rare | AP6: % Super rare | AQ6: % Épique | AR6: % Mythique | AS6: % Légendaire | AT6: % Unique | AU6: Unique possible (Guerrier · Mage · Tireur) | AV6: Nom dans le diagramme | AW6: (aide) Clé | AX6: (aide) Facteur niveau | AY6: (aide) N° rôle | AZ6: (aide) N° rang
A7: MON-001 | B7: 5 | C7: {=INDEX(Zones!$B$6:$B$35,MATCH(B7,Zones!$A$6:$A$35,0))} -> Forêt de chasse | D7: {=INDEX(Éléments!$B$5:$B$14,MATCH(B7,Éléments!$C$5:$C$14,1))} -> Forêt | E7: {=INDEX(Éléments!$A$5:$A$14,MATCH(B7,Éléments!$C$5:$C$14,1))} -> Neutre | F7: Sanglier | G7: =IF(OR(H7="Boss",H7="Dragon"),"Oui","Non") -> Non | H7: Normal | I7: Bête | J7: Physique | K7: =IF($F$3="",B7,$F$3) -> 5 | L7: {=ROUND(Paramètres!$B$16*(Paramètres!$B$5+(1-Paramètres!$B$5)*((K7-Paramètres!$B$7)/(Paramètres!$B$8-Paramètres!$B$7))^Paramètres!$B$6)*INDEX(Rôles!$B$18:$B$22,AZ7)*INDEX(Rôles!$B$5:$B$13,AY7),0)} -> 105 | M7: {=ROUND(IF(J7="Physique",1,IF(J7="Mixte",Paramètres!$B$32,0))*Paramètres!$B$12*(Paramètres!$B$5+(1-Paramètres!$B$5)*((K7-Paramètres!$B$7)/(Paramètres!$B$8-Paramètres!$B$7))^Paramètres!$B$6)*INDEX(Rôles!$C$18:$C$22,AZ7)*INDEX(Rôles!$C$5:$C$13,AY7)/(Paramètres!$B$35*(1-Paramètres!$B$36)),0)} -> 25 | N7: {=ROUND(IF(J7="Magique",1,IF(J7="Mixte",Paramètres!$B$32,0))*Paramètres!$B$12*(Paramètres!$B$5+(1-Paramètres!$B$5)*((K7-Paramètres!$B$7)/(Paramètres!$B$8-Paramètres!$B$7))^Paramètres!$B$6)*INDEX(Rôles!$C$18:$C$22,AZ7)*INDEX(Rôles!$C$5:$C$13,AY7)/(Paramètres!$B$35*(1-Paramètres!$B$36)),0)} -> 0 | O7: {=ROUND(Paramètres!$B$18*(Paramètres!$B$5+(1-Paramètres!$B$5)*((K7-Paramètres!$B$7)/(Paramètres!$B$8-Paramètres!$B$7))^Paramètres!$B$6)*INDEX(Rôles!$D$5:$D$13,AY7)*INDEX(Rôles!$D$18:$D$22,AZ7),0)} -> 19 | P7: {=ROUND(Paramètres!$B$19*(Paramètres!$B$5+(1-Paramètres!$B$5)*((K7-Paramètres!$B$7)/(Paramètres!$B$8-Paramètres!$B$7))^Paramètres!$B$6)*INDEX(Rôles!$E$5:$E$13,AY7)*INDEX(Rôles!$D$18:$D$22,AZ7),0)} -> 20 | Q7: {=ROUND(Paramètres!$B$20*(Paramètres!$B$5+(1-Paramètres!$B$5)*((K7-Paramètres!$B$7)/(Paramètres!$B$8-Paramètres!$B$7))^Paramètres!$B$6)*INDEX(Rôles!$F$5:$F$13,AY7),0)} -> 10 | R7: =ROUND(Paramètres!$B$64*$AX7*INDEX(Rôles!$N$5:$N$13,$AY7)*INDEX(Rôles!$I$18:$I$22,$AZ7),0) -> 8 | S7: {=MIN(1,ROUND(Paramètres!$B$21*INDEX(Rôles!$G$5:$G$13,AY7),3))} -> 0.9 | T7: {=MIN(Paramètres!$B$28,ROUND(Paramètres!$B$22*INDEX(Rôles!$H$5:$H$13,AY7),3))} -> 0.05 | U7: {=ROUND(Paramètres!$B$23*INDEX(Rôles!$I$5:$I$13,AY7),3)} -> 0.5 | V7: {=MIN(Paramètres!$B$29,ROUND(Paramètres!$B$24*INDEX(Rôles!$J$5:$J$13,AY7),3))} -> 0.025 | W7: {=MIN(Paramètres!$B$27,ROUND((Paramètres!$B$25+(Paramètres!$B$26-Paramètres!$B$25)*(K7-Paramètres!$B$7)/(Paramètres!$B$8-Paramètres!$B$7))*INDEX(Rôles!$K$5:$K$13,AY7)+INDEX(Rôles!$G$18:$G$22,AZ7),3))} -> 0.048 | X7: =ROUND(1-(1-P7/(P7+(Paramètres!$B$19*(Paramètres!$B$5+(1-Paramètres!$B$5)*((K7-Paramètres!$B$7)/(Paramètres!$B$8-Paramètres!$B$7))^Paramètres!$B$6)*(1-Paramètres!$B$30)/Paramètres!$B$30)))*(1-O7/(O7+(Paramètres!$B$18*(Paramètres!$B$5+(1-Paramètres!$B$5)*((K7-Paramètres!$B$7)/(Paramètres!$B$8-Paramètres!$B$7))^Paramètres!$B$6)*(1-Paramètres!$B$31)/Paramètres!$B$31))),3) -> 0.233 | Y7: =ROUND(O7/(O7+(Paramètres!$B$18*(Paramètres!$B$5+(1-Paramètres!$B$5)*((K7-Paramètres!$B$7)/(Paramètres!$B$8-Paramètres!$B$7))^Paramètres!$B$6)*(1-Paramètres!$B$31)/Paramètres!$B$31)),3) -> 0.096 | Z7: {=IF(E7="Neutre",0,MIN(1,INDEX(Rôles!$L$5:$L$13,AY7)+INDEX(Rôles!$F$18:$F$22,AZ7)))} -> 0 | AA7: {=ROUND(INDEX(Rôles!$C$18:$C$22,AZ7)*INDEX(Rôles!$C$5:$C$13,AY7),4)} -> 0.0158 | AB7: {=ROUND(INDEX(Rôles!$B$18:$B$22,AZ7)*INDEX(Rôles!$B$5:$B$13,AY7),2)} -> 1.9 | AC7: {=INDEX(Rôles!$E$18:$E$22,AZ7)} -> 1 | AD7: {=INDEX(Éléments!$F$5:$F$14,MATCH(E7,Éléments!$A$5:$A$14,0))} -> — | AE7: {=INDEX(Éléments!$G$5:$G$14,MATCH(E7,Éléments!$A$5:$A$14,0))} -> — | AF7: Saignement | AG7: 0.2 | AH7: Assommé | AI7: 0.08 | AJ7: {=ROUND(ROUND(Paramètres!$B$49*K7^Paramètres!$B$50,0)*INDEX(Rôles!$E$18:$E$22,AZ7),0)} -> 45 | AK7: {=ROUND(ROUND(Paramètres!$B$53*K7^Paramètres!$B$54,0)*INDEX(Rôles!$E$18:$E$22,AZ7),0)} -> 26 | AL7: =INDEX(Butin!$B$7:$B$11,AZ7) -> 0.05 | AM7: =INDEX(Butin!$E$7:$E$11,AZ7) -> 0.05 | AN7: =IF($H7="Boss",INDEX(Butin!$E$28:$K$37,MATCH($B7,Éléments!$C$5:$C$14,1),1),IF($H7="Dragon",INDEX(Butin!$E$41:$K$50,MATCH($B7,Éléments!$C$5:$C$14,1),1),INDEX(Butin!$E$15:$K$24,MATCH($B7,Éléments!$C$5:$C$14,1),1))) -> 0.8 | AO7: =IF($H7="Boss",INDEX(Butin!$E$28:$K$37,MATCH($B7,Éléments!$C$5:$C$14,1),2),IF($H7="Dragon",INDEX(Butin!$E$41:$K$50,MATCH($B7,Éléments!$C$5:$C$14,1),2),INDEX(Butin!$E$15:$K$24,MATCH($B7,Éléments!$C$5:$C$14,1),2))) -> 0.2 | AP7: =IF($H7="Boss",INDEX(Butin!$E$28:$K$37,MATCH($B7,Éléments!$C$5:$C$14,1),3),IF($H7="Dragon",INDEX(Butin!$E$41:$K$50,MATCH($B7,Éléments!$C$5:$C$14,1),3),INDEX(Butin!$E$15:$K$24,MATCH($B7,Éléments!$C$5:$C$14,1),3))) -> 0 | AQ7: =IF($H7="Boss",INDEX(Butin!$E$28:$K$37,MATCH($B7,Éléments!$C$5:$C$14,1),4),IF($H7="Dragon",INDEX(Butin!$E$41:$K$50,MATCH($B7,Éléments!$C$5:$C$14,1),4),INDEX(Butin!$E$15:$K$24,MATCH($B7,Éléments!$C$5:$C$14,1),4))) -> 0 | AR7: =IF($H7="Boss",INDEX(Butin!$E$28:$K$37,MATCH($B7,Éléments!$C$5:$C$14,1),5),IF($H7="Dragon",INDEX(Butin!$E$41:$K$50,MATCH($B7,Éléments!$C$5:$C$14,1),5),INDEX(Butin!$E$15:$K$24,MATCH($B7,Éléments!$C$5:$C$14,1),5))) -> 0 | AS7: =IF($H7="Boss",INDEX(Butin!$E$28:$K$37,MATCH($B7,Éléments!$C$5:$C$14,1),6),IF($H7="Dragon",INDEX(Butin!$E$41:$K$50,MATCH($B7,Éléments!$C$5:$C$14,1),6),INDEX(Butin!$E$15:$K$24,MATCH($B7,Éléments!$C$5:$C$14,1),6))) -> 0 | AT7: =IF($H7="Boss",INDEX(Butin!$E$28:$K$37,MATCH($B7,Éléments!$C$5:$C$14,1),7),IF($H7="Dragon",INDEX(Butin!$E$41:$K$50,MATCH($B7,Éléments!$C$5:$C$14,1),7),INDEX(Butin!$E$15:$K$24,MATCH($B7,Éléments!$C$5:$C$14,1),7))) -> 0 | AU7: =IF(AT7=0,"—",INDEX(Butin!$D$54:$D$63,MATCH($B7,Éléments!$C$5:$C$14,1))&" · "&INDEX(Butin!$F$54:$F$63,MATCH($B7,Éléments!$C$5:$C$14,1))&" · "&INDEX(Butin!$H$54:$H$63,MATCH($B7,Éléments!$C$5:$C$14,1))) -> — | AV7: Sanglier | AW7: =B7&IF(G7="Oui","|B","|N") -> 5|N | AX7: =(Paramètres!$B$5+(1-Paramètres!$B$5)*((K7-Paramètres!$B$7)/(Paramètres!$B$8-Paramètres!$B$7))^Paramètres!$B$6) -> 0.070203814 | AY7: =MATCH(I7,Rôles!$A$5:$A$13,0) -> 1 | AZ7: =MATCH(H7,Rôles!$A$18:$A$22,0) -> 2
A8: MON-002 | B8: 5 | C8: {=INDEX(Zones!$B$6:$B$35,MATCH(B8,Zones!$A$6:$A$35,0))} -> Forêt de chasse | D8: {=INDEX(Éléments!$B$5:$B$14,MATCH(B8,Éléments!$C$5:$C$14,1))} -> Forêt | E8: {=INDEX(Éléments!$A$5:$A$14,MATCH(B8,Éléments!$C$5:$C$14,1))} -> Neutre | F8: Loup | G8: =IF(OR(H8="Boss",H8="Dragon"),"Oui","Non") -> Non | H8: Normal | I8: Assassin | J8: Physique | K8: =IF($F$3="",B8,$F$3) -> 5 | L8: {=ROUND(Paramètres!$B$16*(Paramètres!$B$5+(1-Paramètres!$B$5)*((K8-Paramètres!$B$7)/(Paramètres!$B$8-Paramètres!$B$7))^Paramètres!$B$6)*INDEX(Rôles!$B$18:$B$22,AZ8)*INDEX(Rôles!$B$5:$B$13,AY8),0)} -> 83 | M8: {=ROUND(IF(J8="Physique",1,IF(J8="Mixte",Paramètres!$B$32,0))*Paramètres!$B$12*(Paramètres!$B$5+(1-Paramètres!$B$5)*((K8-Paramètres!$B$7)/(Paramètres!$B$8-Paramètres!$B$7))^Paramètres!$B$6)*INDEX(Rôles!$C$18:$C$22,AZ8)*INDEX(Rôles!$C$5:$C$13,AY8)/(Paramètres!$B$35*(1-Paramètres!$B$36)),0)} -> 29 | N8: {=ROUND(IF(J8="Magique",1,IF(J8="Mixte",Paramètres!$B$32,0))*Paramètres!$B$12*(Paramètres!$B$5+(1-Paramètres!$B$5)*((K8-Paramètres!$B$7)/(Paramètres!$B$8-Paramètres!$B$7))^Paramètres!$B$6)*INDEX(Rôles!$C$18:$C$22,AZ8)*INDEX(Rôles!$C$5:$C$13,AY8)/(Paramètres!$B$35*(1-Paramètres!$B$36)),0)} -> 0 | O8: {=ROUND(Paramètres!$B$18*(Paramètres!$B$5+(1-Paramètres!$B$5)*((K8-Paramètres!$B$7)/(Paramètres!$B$8-Paramètres!$B$7))^Paramètres!$B$6)*INDEX(Rôles!$D$5:$D$13,AY8)*INDEX(Rôles!$D$18:$D$22,AZ8),0)} -> 19 | P8: {=ROUND(Paramètres!$B$19*(Paramètres!$B$5+(1-Paramètres!$B$5)*((K8-Paramètres!$B$7)/(Paramètres!$B$8-Paramètres!$B$7))^Paramètres!$B$6)*INDEX(Rôles!$E$5:$E$13,AY8)*INDEX(Rôles!$D$18:$D$22,AZ8),0)} -> 14 | Q8: {=ROUND(Paramètres!$B$20*(Paramètres!$B$5+(1-Paramètres!$B$5)*((K8-Paramètres!$B$7)/(Paramètres!$B$8-Paramètres!$B$7))^Paramètres!$B$6)*INDEX(Rôles!$F$5:$F$13,AY8),0)} -> 13 | R8: =ROUND(Paramètres!$B$64*$AX8*INDEX(Rôles!$N$5:$N$13,$AY8)*INDEX(Rôles!$I$18:$I$22,$AZ8),0) -> 11 | S8: {=MIN(1,ROUND(Paramètres!$B$21*INDEX(Rôles!$G$5:$G$13,AY8),3))} -> 1 | T8: {=MIN(Paramètres!$B$28,ROUND(Paramètres!$B$22*INDEX(Rôles!$H$5:$H$13,AY8),3))} -> 0.08 | U8: {=ROUND(Paramètres!$B$23*INDEX(Rôles!$I$5:$I$13,AY8),3)} -> 0.7 | V8: {=MIN(Paramètres!$B$29,ROUND(Paramètres!$B$24*INDEX(Rôles!$J$5:$J$13,AY8),3))} -> 0.06 | W8: {=MIN(Paramètres!$B$27,ROUND((Paramètres!$B$25+(Paramètres!$B$26-Paramètres!$B$25)*(K8-Paramètres!$B$7)/(Paramètres!$B$8-Paramètres!$B$7))*INDEX(Rôles!$K$5:$K$13,AY8)+INDEX(Rôles!$G$18:$G$22,AZ8),3))} -> 0.048 | X8: =ROUND(1-(1-P8/(P8+(Paramètres!$B$19*(Paramètres!$B$5+(1-Paramètres!$B$5)*((K8-Paramètres!$B$7)/(Paramètres!$B$8-Paramètres!$B$7))^Paramètres!$B$6)*(1-Paramètres!$B$30)/Paramètres!$B$30)))*(1-O8/(O8+(Paramètres!$B$18*(Paramètres!$B$5+(1-Paramètres!$B$5)*((K8-Paramètres!$B$7)/(Paramètres!$B$8-Paramètres!$B$7))^Paramètres!$B$6)*(1-Paramètres!$B$31)/Paramètres!$B$31))),3) -> 0.196 | Y8: =ROUND(O8/(O8+(Paramètres!$B$18*(Paramètres!$B$5+(1-Paramètres!$B$5)*((K8-Paramètres!$B$7)/(Paramètres!$B$8-Paramètres!$B$7))^Paramètres!$B$6)*(1-Paramètres!$B$31)/Paramètres!$B$31)),3) -> 0.096 | Z8: {=IF(E8="Neutre",0,MIN(1,INDEX(Rôles!$L$5:$L$13,AY8)+INDEX(Rôles!$F$18:$F$22,AZ8)))} -> 0 | AA8: {=ROUND(INDEX(Rôles!$C$18:$C$22,AZ8)*INDEX(Rôles!$C$5:$C$13,AY8),4)} -> 0.018 | AB8: {=ROUND(INDEX(Rôles!$B$18:$B$22,AZ8)*INDEX(Rôles!$B$5:$B$13,AY8),2)} -> 1.5 | AC8: {=INDEX(Rôles!$E$18:$E$22,AZ8)} -> 1 | AD8: {=INDEX(Éléments!$F$5:$F$14,MATCH(E8,Éléments!$A$5:$A$14,0))} -> — | AE8: {=INDEX(Éléments!$G$5:$G$14,MATCH(E8,Éléments!$A$5:$A$14,0))} -> — | AF8: Saignement | AG8: 0.3 | AJ8: {=ROUND(ROUND(Paramètres!$B$49*K8^Paramètres!$B$50,0)*INDEX(Rôles!$E$18:$E$22,AZ8),0)} -> 45 | AK8: {=ROUND(ROUND(Paramètres!$B$53*K8^Paramètres!$B$54,0)*INDEX(Rôles!$E$18:$E$22,AZ8),0)} -> 26 | AL8: =INDEX(Butin!$B$7:$B$11,AZ8) -> 0.05 | AM8: =INDEX(Butin!$E$7:$E$11,AZ8) -> 0.05 | AN8: =IF($H8="Boss",INDEX(Butin!$E$28:$K$37,MATCH($B8,Éléments!$C$5:$C$14,1),1),IF($H8="Dragon",INDEX(Butin!$E$41:$K$50,MATCH($B8,Éléments!$C$5:$C$14,1),1),INDEX(Butin!$E$15:$K$24,MATCH($B8,Éléments!$C$5:$C$14,1),1))) -> 0.8 | AO8: =IF($H8="Boss",INDEX(Butin!$E$28:$K$37,MATCH($B8,Éléments!$C$5:$C$14,1),2),IF($H8="Dragon",INDEX(Butin!$E$41:$K$50,MATCH($B8,Éléments!$C$5:$C$14,1),2),INDEX(Butin!$E$15:$K$24,MATCH($B8,Éléments!$C$5:$C$14,1),2))) -> 0.2 | AP8: =IF($H8="Boss",INDEX(Butin!$E$28:$K$37,MATCH($B8,Éléments!$C$5:$C$14,1),3),IF($H8="Dragon",INDEX(Butin!$E$41:$K$50,MATCH($B8,Éléments!$C$5:$C$14,1),3),INDEX(Butin!$E$15:$K$24,MATCH($B8,Éléments!$C$5:$C$14,1),3))) -> 0 | AQ8: =IF($H8="Boss",INDEX(Butin!$E$28:$K$37,MATCH($B8,Éléments!$C$5:$C$14,1),4),IF($H8="Dragon",INDEX(Butin!$E$41:$K$50,MATCH($B8,Éléments!$C$5:$C$14,1),4),INDEX(Butin!$E$15:$K$24,MATCH($B8,Éléments!$C$5:$C$14,1),4))) -> 0 | AR8: =IF($H8="Boss",INDEX(Butin!$E$28:$K$37,MATCH($B8,Éléments!$C$5:$C$14,1),5),IF($H8="Dragon",INDEX(Butin!$E$41:$K$50,MATCH($B8,Éléments!$C$5:$C$14,1),5),INDEX(Butin!$E$15:$K$24,MATCH($B8,Éléments!$C$5:$C$14,1),5))) -> 0 | AS8: =IF($H8="Boss",INDEX(Butin!$E$28:$K$37,MATCH($B8,Éléments!$C$5:$C$14,1),6),IF($H8="Dragon",INDEX(Butin!$E$41:$K$50,MATCH($B8,Éléments!$C$5:$C$14,1),6),INDEX(Butin!$E$15:$K$24,MATCH($B8,Éléments!$C$5:$C$14,1),6))) -> 0 | AT8: =IF($H8="Boss",INDEX(Butin!$E$28:$K$37,MATCH($B8,Éléments!$C$5:$C$14,1),7),IF($H8="Dragon",INDEX(Butin!$E$41:$K$50,MATCH($B8,Éléments!$C$5:$C$14,1),7),INDEX(Butin!$E$15:$K$24,MATCH($B8,Éléments!$C$5:$C$14,1),7))) -> 0 | AU8: =IF(AT8=0,"—",INDEX(Butin!$D$54:$D$63,MATCH($B8,Éléments!$C$5:$C$14,1))&" · "&INDEX(Butin!$F$54:$F$63,MATCH($B8,Éléments!$C$5:$C$14,1))&" · "&INDEX(Butin!$H$54:$H$63,MATCH($B8,Éléments!$C$5:$C$14,1))) -> — | AV8: Loup | AW8: =B8&IF(G8="Oui","|B","|N") -> 5|N | AX8: =(Paramètres!$B$5+(1-Paramètres!$B$5)*((K8-Paramètres!$B$7)/(Paramètres!$B$8-Paramètres!$B$7))^Paramètres!$B$6) -> 0.070203814 | AY8: =MATCH(I8,Rôles!$A$5:$A$13,0) -> 7 | AZ8: =MATCH(H8,Rôles!$A$18:$A$22,0) -> 2
A9: MON-003 | B9: 5 | C9: {=INDEX(Zones!$B$6:$B$35,MATCH(B9,Zones!$A$6:$A$35,0))} -> Forêt de chasse | D9: {=INDEX(Éléments!$B$5:$B$14,MATCH(B9,Éléments!$C$5:$C$14,1))} -> Forêt | E9: {=INDEX(Éléments!$A$5:$A$14,MATCH(B9,Éléments!$C$5:$C$14,1))} -> Neutre | F9: Ours | G9: =IF(OR(H9="Boss",H9="Dragon"),"Oui","Non") -> Non | H9: Fort | I9: Brute | J9: Physique | K9: =IF($F$3="",B9,$F$3) -> 5 | L9: {=ROUND(Paramètres!$B$16*(Paramètres!$B$5+(1-Paramètres!$B$5)*((K9-Paramètres!$B$7)/(Paramètres!$B$8-Paramètres!$B$7))^Paramètres!$B$6)*INDEX(Rôles!$B$18:$B$22,AZ9)*INDEX(Rôles!$B$5:$B$13,AY9),0)} -> 232 | M9: {=ROUND(IF(J9="Physique",1,IF(J9="Mixte",Paramètres!$B$32,0))*Paramètres!$B$12*(Paramètres!$B$5+(1-Paramètres!$B$5)*((K9-Paramètres!$B$7)/(Paramètres!$B$8-Paramètres!$B$7))^Paramètres!$B$6)*INDEX(Rôles!$C$18:$C$22,AZ9)*INDEX(Rôles!$C$5:$C$13,AY9)/(Paramètres!$B$35*(1-Paramètres!$B$36)),0)} -> 29 | N9: {=ROUND(IF(J9="Magique",1,IF(J9="Mixte",Paramètres!$B$32,0))*Paramètres!$B$12*(Paramètres!$B$5+(1-Paramètres!$B$5)*((K9-Paramètres!$B$7)/(Paramètres!$B$8-Paramètres!$B$7))^Paramètres!$B$6)*INDEX(Rôles!$C$18:$C$22,AZ9)*INDEX(Rôles!$C$5:$C$13,AY9)/(Paramètres!$B$35*(1-Paramètres!$B$36)),0)} -> 0 | O9: {=ROUND(Paramètres!$B$18*(Paramètres!$B$5+(1-Paramètres!$B$5)*((K9-Paramètres!$B$7)/(Paramètres!$B$8-Paramètres!$B$7))^Paramètres!$B$6)*INDEX(Rôles!$D$5:$D$13,AY9)*INDEX(Rôles!$D$18:$D$22,AZ9),0)} -> 44 | P9: {=ROUND(Paramètres!$B$19*(Paramètres!$B$5+(1-Paramètres!$B$5)*((K9-Paramètres!$B$7)/(Paramètres!$B$8-Paramètres!$B$7))^Paramètres!$B$6)*INDEX(Rôles!$E$5:$E$13,AY9)*INDEX(Rôles!$D$18:$D$22,AZ9),0)} -> 48 | Q9: {=ROUND(Paramètres!$B$20*(Paramètres!$B$5+(1-Paramètres!$B$5)*((K9-Paramètres!$B$7)/(Paramètres!$B$8-Paramètres!$B$7))^Paramètres!$B$6)*INDEX(Rôles!$F$5:$F$13,AY9),0)} -> 5 | R9: =ROUND(Paramètres!$B$64*$AX9*INDEX(Rôles!$N$5:$N$13,$AY9)*INDEX(Rôles!$I$18:$I$22,$AZ9),0) -> 5 | S9: {=MIN(1,ROUND(Paramètres!$B$21*INDEX(Rôles!$G$5:$G$13,AY9),3))} -> 0.765 | T9: {=MIN(Paramètres!$B$28,ROUND(Paramètres!$B$22*INDEX(Rôles!$H$5:$H$13,AY9),3))} -> 0.03 | U9: {=ROUND(Paramètres!$B$23*INDEX(Rôles!$I$5:$I$13,AY9),3)} -> 0.5 | V9: {=MIN(Paramètres!$B$29,ROUND(Paramètres!$B$24*INDEX(Rôles!$J$5:$J$13,AY9),3))} -> 0.04 | W9: {=MIN(Paramètres!$B$27,ROUND((Paramètres!$B$25+(Paramètres!$B$26-Paramètres!$B$25)*(K9-Paramètres!$B$7)/(Paramètres!$B$8-Paramètres!$B$7))*INDEX(Rôles!$K$5:$K$13,AY9)+INDEX(Rôles!$G$18:$G$22,AZ9),3))} -> 0.072 | X9: =ROUND(1-(1-P9/(P9+(Paramètres!$B$19*(Paramètres!$B$5+(1-Paramètres!$B$5)*((K9-Paramètres!$B$7)/(Paramètres!$B$8-Paramètres!$B$7))^Paramètres!$B$6)*(1-Paramètres!$B$30)/Paramètres!$B$30)))*(1-O9/(O9+(Paramètres!$B$18*(Paramètres!$B$5+(1-Paramètres!$B$5)*((K9-Paramètres!$B$7)/(Paramètres!$B$8-Paramètres!$B$7))^Paramètres!$B$6)*(1-Paramètres!$B$31)/Paramètres!$B$31))),3) -> 0.438 | Y9: =ROUND(O9/(O9+(Paramètres!$B$18*(Paramètres!$B$5+(1-Paramètres!$B$5)*((K9-Paramètres!$B$7)/(Paramètres!$B$8-Paramètres!$B$7))^Paramètres!$B$6)*(1-Paramètres!$B$31)/Paramètres!$B$31)),3) -> 0.197 | Z9: {=IF(E9="Neutre",0,MIN(1,INDEX(Rôles!$L$5:$L$13,AY9)+INDEX(Rôles!$F$18:$F$22,AZ9)))} -> 0 | AA9: {=ROUND(INDEX(Rôles!$C$18:$C$22,AZ9)*INDEX(Rôles!$C$5:$C$13,AY9),4)} -> 0.0181 | AB9: {=ROUND(INDEX(Rôles!$B$18:$B$22,AZ9)*INDEX(Rôles!$B$5:$B$13,AY9),2)} -> 4.2 | AC9: {=INDEX(Rôles!$E$18:$E$22,AZ9)} -> 1.4 | AD9: {=INDEX(Éléments!$F$5:$F$14,MATCH(E9,Éléments!$A$5:$A$14,0))} -> — | AE9: {=INDEX(Éléments!$G$5:$G$14,MATCH(E9,Éléments!$A$5:$A$14,0))} -> — | AF9: Assommé | AG9: 0.15 | AH9: Saignement | AI9: 0.15 | AJ9: {=ROUND(ROUND(Paramètres!$B$49*K9^Paramètres!$B$50,0)*INDEX(Rôles!$E$18:$E$22,AZ9),0)} -> 63 | AK9: {=ROUND(ROUND(Paramètres!$B$53*K9^Paramètres!$B$54,0)*INDEX(Rôles!$E$18:$E$22,AZ9),0)} -> 36 | AL9: =INDEX(Butin!$B$7:$B$11,AZ9) -> 0.08 | AM9: =INDEX(Butin!$E$7:$E$11,AZ9) -> 0.08 | AN9: =IF($H9="Boss",INDEX(Butin!$E$28:$K$37,MATCH($B9,Éléments!$C$5:$C$14,1),1),IF($H9="Dragon",INDEX(Butin!$E$41:$K$50,MATCH($B9,Éléments!$C$5:$C$14,1),1),INDEX(Butin!$E$15:$K$24,MATCH($B9,Éléments!$C$5:$C$14,1),1))) -> 0.8 | AO9: =IF($H9="Boss",INDEX(Butin!$E$28:$K$37,MATCH($B9,Éléments!$C$5:$C$14,1),2),IF($H9="Dragon",INDEX(Butin!$E$41:$K$50,MATCH($B9,Éléments!$C$5:$C$14,1),2),INDEX(Butin!$E$15:$K$24,MATCH($B9,Éléments!$C$5:$C$14,1),2))) -> 0.2 | AP9: =IF($H9="Boss",INDEX(Butin!$E$28:$K$37,MATCH($B9,Éléments!$C$5:$C$14,1),3),IF($H9="Dragon",INDEX(Butin!$E$41:$K$50,MATCH($B9,Éléments!$C$5:$C$14,1),3),INDEX(Butin!$E$15:$K$24,MATCH($B9,Éléments!$C$5:$C$14,1),3))) -> 0 | AQ9: =IF($H9="Boss",INDEX(Butin!$E$28:$K$37,MATCH($B9,Éléments!$C$5:$C$14,1),4),IF($H9="Dragon",INDEX(Butin!$E$41:$K$50,MATCH($B9,Éléments!$C$5:$C$14,1),4),INDEX(Butin!$E$15:$K$24,MATCH($B9,Éléments!$C$5:$C$14,1),4))) -> 0 | AR9: =IF($H9="Boss",INDEX(Butin!$E$28:$K$37,MATCH($B9,Éléments!$C$5:$C$14,1),5),IF($H9="Dragon",INDEX(Butin!$E$41:$K$50,MATCH($B9,Éléments!$C$5:$C$14,1),5),INDEX(Butin!$E$15:$K$24,MATCH($B9,Éléments!$C$5:$C$14,1),5))) -> 0 | AS9: =IF($H9="Boss",INDEX(Butin!$E$28:$K$37,MATCH($B9,Éléments!$C$5:$C$14,1),6),IF($H9="Dragon",INDEX(Butin!$E$41:$K$50,MATCH($B9,Éléments!$C$5:$C$14,1),6),INDEX(Butin!$E$15:$K$24,MATCH($B9,Éléments!$C$5:$C$14,1),6))) -> 0 | AT9: =IF($H9="Boss",INDEX(Butin!$E$28:$K$37,MATCH($B9,Éléments!$C$5:$C$14,1),7),IF($H9="Dragon",INDEX(Butin!$E$41:$K$50,MATCH($B9,Éléments!$C$5:$C$14,1),7),INDEX(Butin!$E$15:$K$24,MATCH($B9,Éléments!$C$5:$C$14,1),7))) -> 0 | AU9: =IF(AT9=0,"—",INDEX(Butin!$D$54:$D$63,MATCH($B9,Éléments!$C$5:$C$14,1))&" · "&INDEX(Butin!$F$54:$F$63,MATCH($B9,Éléments!$C$5:$C$14,1))&" · "&INDEX(Butin!$H$54:$H$63,MATCH($B9,Éléments!$C$5:$C$14,1))) -> — | AV9: Ours | AW9: =B9&IF(G9="Oui","|B","|N") -> 5|N | AX9: =(Paramètres!$B$5+(1-Paramètres!$B$5)*((K9-Paramètres!$B$7)/(Paramètres!$B$8-Paramètres!$B$7))^Paramètres!$B$6) -> 0.070203814 | AY9: =MATCH(I9,Rôles!$A$5:$A$13,0) -> 2 | AZ9: =MATCH(H9,Rôles!$A$18:$A$22,0) -> 3
A10: MON-004 | B10: 5 | C10: {=INDEX(Zones!$B$6:$B$35,MATCH(B10,Zones!$A$6:$A$35,0))} -> Forêt de chasse | D10: {=INDEX(Éléments!$B$5:$B$14,MATCH(B10,Éléments!$C$5:$C$14,1))} -> Forêt | E10: {=INDEX(Éléments!$A$5:$A$14,MATCH(B10,Éléments!$C$5:$C$14,1))} -> Neutre | F10: Ours enragé | G10: =IF(OR(H10="Boss",H10="Dragon"),"Oui","Non") -> Oui | H10: Boss | I10: Brute | J10: Physique | K10: =IF($F$3="",B10,$F$3) -> 5 | L10: {=ROUND(Paramètres!$B$16*(Paramètres!$B$5+(1-Paramètres!$B$5)*((K10-Paramètres!$B$7)/(Paramètres!$B$8-Paramètres!$B$7))^Paramètres!$B$6)*INDEX(Rôles!$B$18:$B$22,AZ10)*INDEX(Rôles!$B$5:$B$13,AY10),0)} -> 995 | M10: {=ROUND(IF(J10="Physique",1,IF(J10="Mixte",Paramètres!$B$32,0))*Paramètres!$B$12*(Paramètres!$B$5+(1-Paramètres!$B$5)*((K10-Paramètres!$B$7)/(Paramètres!$B$8-Paramètres!$B$7))^Paramètres!$B$6)*INDEX(Rôles!$C$18:$C$22,AZ10)*INDEX(Rôles!$C$5:$C$13,AY10)/(Paramètres!$B$35*(1-Paramètres!$B$36)),0)} -> 46 | N10: {=ROUND(IF(J10="Magique",1,IF(J10="Mixte",Paramètres!$B$32,0))*Paramètres!$B$12*(Paramètres!$B$5+(1-Paramètres!$B$5)*((K10-Paramètres!$B$7)/(Paramètres!$B$8-Paramètres!$B$7))^Paramètres!$B$6)*INDEX(Rôles!$C$18:$C$22,AZ10)*INDEX(Rôles!$C$5:$C$13,AY10)/(Paramètres!$B$35*(1-Paramètres!$B$36)),0)} -> 0 | O10: {=ROUND(Paramètres!$B$18*(Paramètres!$B$5+(1-Paramètres!$B$5)*((K10-Paramètres!$B$7)/(Paramètres!$B$8-Paramètres!$B$7))^Paramètres!$B$6)*INDEX(Rôles!$D$5:$D$13,AY10)*INDEX(Rôles!$D$18:$D$22,AZ10),0)} -> 49 | P10: {=ROUND(Paramètres!$B$19*(Paramètres!$B$5+(1-Paramètres!$B$5)*((K10-Paramètres!$B$7)/(Paramètres!$B$8-Paramètres!$B$7))^Paramètres!$B$6)*INDEX(Rôles!$E$5:$E$13,AY10)*INDEX(Rôles!$D$18:$D$22,AZ10),0)} -> 55 | Q10: {=ROUND(Paramètres!$B$20*(Paramètres!$B$5+(1-Paramètres!$B$5)*((K10-Paramètres!$B$7)/(Paramètres!$B$8-Paramètres!$B$7))^Paramètres!$B$6)*INDEX(Rôles!$F$5:$F$13,AY10),0)} -> 5 | R10: =ROUND(Paramètres!$B$64*$AX10*INDEX(Rôles!$N$5:$N$13,$AY10)*INDEX(Rôles!$I$18:$I$22,$AZ10),0) -> 6 | S10: {=MIN(1,ROUND(Paramètres!$B$21*INDEX(Rôles!$G$5:$G$13,AY10),3))} -> 0.765 | T10: {=MIN(Paramètres!$B$28,ROUND(Paramètres!$B$22*INDEX(Rôles!$H$5:$H$13,AY10),3))} -> 0.03 | U10: {=ROUND(Paramètres!$B$23*INDEX(Rôles!$I$5:$I$13,AY10),3)} -> 0.5 | V10: {=MIN(Paramètres!$B$29,ROUND(Paramètres!$B$24*INDEX(Rôles!$J$5:$J$13,AY10),3))} -> 0.04 | W10: {=MIN(Paramètres!$B$27,ROUND((Paramètres!$B$25+(Paramètres!$B$26-Paramètres!$B$25)*(K10-Paramètres!$B$7)/(Paramètres!$B$8-Paramètres!$B$7))*INDEX(Rôles!$K$5:$K$13,AY10)+INDEX(Rôles!$G$18:$G$22,AZ10),3))} -> 0.272 | X10: =ROUND(1-(1-P10/(P10+(Paramètres!$B$19*(Paramètres!$B$5+(1-Paramètres!$B$5)*((K10-Paramètres!$B$7)/(Paramètres!$B$8-Paramètres!$B$7))^Paramètres!$B$6)*(1-Paramètres!$B$30)/Paramètres!$B$30)))*(1-O10/(O10+(Paramètres!$B$18*(Paramètres!$B$5+(1-Paramètres!$B$5)*((K10-Paramètres!$B$7)/(Paramètres!$B$8-Paramètres!$B$7))^Paramètres!$B$6)*(1-Paramètres!$B$31)/Paramètres!$B$31))),3) -> 0.473 | Y10: =ROUND(O10/(O10+(Paramètres!$B$18*(Paramètres!$B$5+(1-Paramètres!$B$5)*((K10-Paramètres!$B$7)/(Paramètres!$B$8-Paramètres!$B$7))^Paramètres!$B$6)*(1-Paramètres!$B$31)/Paramètres!$B$31)),3) -> 0.215 | Z10: {=IF(E10="Neutre",0,MIN(1,INDEX(Rôles!$L$5:$L$13,AY10)+INDEX(Rôles!$F$18:$F$22,AZ10)))} -> 0 | AA10: {=ROUND(INDEX(Rôles!$C$18:$C$22,AZ10)*INDEX(Rôles!$C$5:$C$13,AY10),4)} -> 0.0285 | AB10: {=ROUND(INDEX(Rôles!$B$18:$B$22,AZ10)*INDEX(Rôles!$B$5:$B$13,AY10),2)} -> 18 | AC10: {=INDEX(Rôles!$E$18:$E$22,AZ10)} -> 8 | AD10: {=INDEX(Éléments!$F$5:$F$14,MATCH(E10,Éléments!$A$5:$A$14,0))} -> — | AE10: {=INDEX(Éléments!$G$5:$G$14,MATCH(E10,Éléments!$A$5:$A$14,0))} -> — | AF10: Saignement | AG10: 0.35 | AH10: Assommé | AI10: 0.25 | AJ10: {=ROUND(ROUND(Paramètres!$B$49*K10^Paramètres!$B$50,0)*INDEX(Rôles!$E$18:$E$22,AZ10),0)} -> 360 | AK10: {=ROUND(ROUND(Paramètres!$B$53*K10^Paramètres!$B$54,0)*INDEX(Rôles!$E$18:$E$22,AZ10),0)} -> 208 | AL10: =INDEX(Butin!$B$7:$B$11,AZ10) -> 1 | AM10: =INDEX(Butin!$E$7:$E$11,AZ10) -> 1.4 | AN10: =IF($H10="Boss",INDEX(Butin!$E$28:$K$37,MATCH($B10,Éléments!$C$5:$C$14,1),1),IF($H10="Dragon",INDEX(Butin!$E$41:$K$50,MATCH($B10,Éléments!$C$5:$C$14,1),1),INDEX(Butin!$E$15:$K$24,MATCH($B10,Éléments!$C$5:$C$14,1),1))) -> 0.4 | AO10: =IF($H10="Boss",INDEX(Butin!$E$28:$K$37,MATCH($B10,Éléments!$C$5:$C$14,1),2),IF($H10="Dragon",INDEX(Butin!$E$41:$K$50,MATCH($B10,Éléments!$C$5:$C$14,1),2),INDEX(Butin!$E$15:$K$24,MATCH($B10,Éléments!$C$5:$C$14,1),2))) -> 0.4 | AP10: =IF($H10="Boss",INDEX(Butin!$E$28:$K$37,MATCH($B10,Éléments!$C$5:$C$14,1),3),IF($H10="Dragon",INDEX(Butin!$E$41:$K$50,MATCH($B10,Éléments!$C$5:$C$14,1),3),INDEX(Butin!$E$15:$K$24,MATCH($B10,Éléments!$C$5:$C$14,1),3))) -> 0.15 | AQ10: =IF($H10="Boss",INDEX(Butin!$E$28:$K$37,MATCH($B10,Éléments!$C$5:$C$14,1),4),IF($H10="Dragon",INDEX(Butin!$E$41:$K$50,MATCH($B10,Éléments!$C$5:$C$14,1),4),INDEX(Butin!$E$15:$K$24,MATCH($B10,Éléments!$C$5:$C$14,1),4))) -> 0.04 | AR10: =IF($H10="Boss",INDEX(Butin!$E$28:$K$37,MATCH($B10,Éléments!$C$5:$C$14,1),5),IF($H10="Dragon",INDEX(Butin!$E$41:$K$50,MATCH($B10,Éléments!$C$5:$C$14,1),5),INDEX(Butin!$E$15:$K$24,MATCH($B10,Éléments!$C$5:$C$14,1),5))) -> 0 | AS10: =IF($H10="Boss",INDEX(Butin!$E$28:$K$37,MATCH($B10,Éléments!$C$5:$C$14,1),6),IF($H10="Dragon",INDEX(Butin!$E$41:$K$50,MATCH($B10,Éléments!$C$5:$C$14,1),6),INDEX(Butin!$E$15:$K$24,MATCH($B10,Éléments!$C$5:$C$14,1),6))) -> 0 | AT10: =IF($H10="Boss",INDEX(Butin!$E$28:$K$37,MATCH($B10,Éléments!$C$5:$C$14,1),7),IF($H10="Dragon",INDEX(Butin!$E$41:$K$50,MATCH($B10,Éléments!$C$5:$C$14,1),7),INDEX(Butin!$E$15:$K$24,MATCH($B10,Éléments!$C$5:$C$14,1),7))) -> 0.01 | AU10: =IF(AT10=0,"—",INDEX(Butin!$D$54:$D$63,MATCH($B10,Éléments!$C$5:$C$14,1))&" · "&INDEX(Butin!$F$54:$F$63,MATCH($B10,Éléments!$C$5:$C$14,1))&" · "&INDEX(Butin!$H$54:$H$63,MATCH($B10,Éléments!$C$5:$C$14,1))) -> Heaume du Roi Déchu · Bâton de la Singularité · Bague du Dernier Souffle | AV10: Ours enragé (Boss) | AW10: =B10&IF(G10="Oui","|B","|N") -> 5|B | AX10: =(Paramètres!$B$5+(1-Paramètres!$B$5)*((K10-Paramètres!$B$7)/(Paramètres!$B$8-Paramètres!$B$7))^Paramètres!$B$6) -> 0.070203814 | AY10: =MATCH(I10,Rôles!$A$5:$A$13,0) -> 2 | AZ10: =MATCH(H10,Rôles!$A$18:$A$22,0) -> 4
A11: MON-005 | B11: 9 | C11: {=INDEX(Zones!$B$6:$B$35,MATCH(B11,Zones!$A$6:$A$35,0))} -> Tannière du dragon (9) | D11: {=INDEX(Éléments!$B$5:$B$14,MATCH(B11,Éléments!$C$5:$C$14,1))} -> Forêt | E11: {=INDEX(Éléments!$A$5:$A$14,MATCH(B11,Éléments!$C$5:$C$14,1))} -> Neutre | F11: Dragon (Neutre) | G11: =IF(OR(H11="Boss",H11="Dragon"),"Oui","Non") -> Oui | H11: Dragon | I11: Dragon | J11: Mixte | K11: =IF($F$3="",B11,$F$3) -> 9 | L11: {=ROUND(Paramètres!$B$16*(Paramètres!$B$5+(1-Paramètres!$B$5)*((K11-Paramètres!$B$7)/(Paramètres!$B$8-Paramètres!$B$7))^Paramètres!$B$6)*INDEX(Rôles!$B$18:$B$22,AZ11)*INDEX(Rôles!$B$5:$B$13,AY11),0)} -> 1519 | M11: {=ROUND(IF(J11="Physique",1,IF(J11="Mixte",Paramètres!$B$32,0))*Paramètres!$B$12*(Paramètres!$B$5+(1-Paramètres!$B$5)*((K11-Paramètres!$B$7)/(Paramètres!$B$8-Paramètres!$B$7))^Paramètres!$B$6)*INDEX(Rôles!$C$18:$C$22,AZ11)*INDEX(Rôles!$C$5:$C$13,AY11)/(Paramètres!$B$35*(1-Paramètres!$B$36)),0)} -> 50 | N11: {=ROUND(IF(J11="Magique",1,IF(J11="Mixte",Paramètres!$B$32,0))*Paramètres!$B$12*(Paramètres!$B$5+(1-Paramètres!$B$5)*((K11-Paramètres!$B$7)/(Paramètres!$B$8-Paramètres!$B$7))^Paramètres!$B$6)*INDEX(Rôles!$C$18:$C$22,AZ11)*INDEX(Rôles!$C$5:$C$13,AY11)/(Paramètres!$B$35*(1-Paramètres!$B$36)),0)} -> 50 | O11: {=ROUND(Paramètres!$B$18*(Paramètres!$B$5+(1-Paramètres!$B$5)*((K11-Paramètres!$B$7)/(Paramètres!$B$8-Paramètres!$B$7))^Paramètres!$B$6)*INDEX(Rôles!$D$5:$D$13,AY11)*INDEX(Rôles!$D$18:$D$22,AZ11),0)} -> 73 | P11: {=ROUND(Paramètres!$B$19*(Paramètres!$B$5+(1-Paramètres!$B$5)*((K11-Paramètres!$B$7)/(Paramètres!$B$8-Paramètres!$B$7))^Paramètres!$B$6)*INDEX(Rôles!$E$5:$E$13,AY11)*INDEX(Rôles!$D$18:$D$22,AZ11),0)} -> 70 | Q11: {=ROUND(Paramètres!$B$20*(Paramètres!$B$5+(1-Paramètres!$B$5)*((K11-Paramètres!$B$7)/(Paramètres!$B$8-Paramètres!$B$7))^Paramètres!$B$6)*INDEX(Rôles!$F$5:$F$13,AY11),0)} -> 9 | R11: =ROUND(Paramètres!$B$64*$AX11*INDEX(Rôles!$N$5:$N$13,$AY11)*INDEX(Rôles!$I$18:$I$22,$AZ11),0) -> 8 | S11: {=MIN(1,ROUND(Paramètres!$B$21*INDEX(Rôles!$G$5:$G$13,AY11),3))} -> 0.9 | T11: {=MIN(Paramètres!$B$28,ROUND(Paramètres!$B$22*INDEX(Rôles!$H$5:$H$13,AY11),3))} -> 0.05 | U11: {=ROUND(Paramètres!$B$23*INDEX(Rôles!$I$5:$I$13,AY11),3)} -> 0.5 | V11: {=MIN(Paramètres!$B$29,ROUND(Paramètres!$B$24*INDEX(Rôles!$J$5:$J$13,AY11),3))} -> 0.05 | W11: {=MIN(Paramètres!$B$27,ROUND((Paramètres!$B$25+(Paramètres!$B$26-Paramètres!$B$25)*(K11-Paramètres!$B$7)/(Paramètres!$B$8-Paramètres!$B$7))*INDEX(Rôles!$K$5:$K$13,AY11)+INDEX(Rôles!$G$18:$G$22,AZ11),3))} -> 0.291 | X11: =ROUND(1-(1-P11/(P11+(Paramètres!$B$19*(Paramètres!$B$5+(1-Paramètres!$B$5)*((K11-Paramètres!$B$7)/(Paramètres!$B$8-Paramètres!$B$7))^Paramètres!$B$6)*(1-Paramètres!$B$30)/Paramètres!$B$30)))*(1-O11/(O11+(Paramètres!$B$18*(Paramètres!$B$5+(1-Paramètres!$B$5)*((K11-Paramètres!$B$7)/(Paramètres!$B$8-Paramètres!$B$7))^Paramètres!$B$6)*(1-Paramètres!$B$31)/Paramètres!$B$31))),3) -> 0.47 | Y11: =ROUND(O11/(O11+(Paramètres!$B$18*(Paramètres!$B$5+(1-Paramètres!$B$5)*((K11-Paramètres!$B$7)/(Paramètres!$B$8-Paramètres!$B$7))^Paramètres!$B$6)*(1-Paramètres!$B$31)/Paramètres!$B$31)),3) -> 0.229 | Z11: {=IF(E11="Neutre",0,MIN(1,INDEX(Rôles!$L$5:$L$13,AY11)+INDEX(Rôles!$F$18:$F$22,AZ11)))} -> 0 | AA11: {=ROUND(INDEX(Rôles!$C$18:$C$22,AZ11)*INDEX(Rôles!$C$5:$C$13,AY11),4)} -> 0.03 | AB11: {=ROUND(INDEX(Rôles!$B$18:$B$22,AZ11)*INDEX(Rôles!$B$5:$B$13,AY11),2)} -> 20 | AC11: {=INDEX(Rôles!$E$18:$E$22,AZ11)} -> 12 | AD11: {=INDEX(Éléments!$F$5:$F$14,MATCH(E11,Éléments!$A$5:$A$14,0))} -> — | AE11: {=INDEX(Éléments!$G$5:$G$14,MATCH(E11,Éléments!$A$5:$A$14,0))} -> — | AF11: Assommé | AG11: 0.2 | AH11: Saignement | AI11: 0.2 | AJ11: {=ROUND(ROUND(Paramètres!$B$49*K11^Paramètres!$B$50,0)*INDEX(Rôles!$E$18:$E$22,AZ11),0)} -> 1128 | AK11: {=ROUND(ROUND(Paramètres!$B$53*K11^Paramètres!$B$54,0)*INDEX(Rôles!$E$18:$E$22,AZ11),0)} -> 696 | AL11: =INDEX(Butin!$B$7:$B$11,AZ11) -> 1 | AM11: =INDEX(Butin!$E$7:$E$11,AZ11) -> 2.5 | AN11: =IF($H11="Boss",INDEX(Butin!$E$28:$K$37,MATCH($B11,Éléments!$C$5:$C$14,1),1),IF($H11="Dragon",INDEX(Butin!$E$41:$K$50,MATCH($B11,Éléments!$C$5:$C$14,1),1),INDEX(Butin!$E$15:$K$24,MATCH($B11,Éléments!$C$5:$C$14,1),1))) -> 0.3 | AO11: =IF($H11="Boss",INDEX(Butin!$E$28:$K$37,MATCH($B11,Éléments!$C$5:$C$14,1),2),IF($H11="Dragon",INDEX(Butin!$E$41:$K$50,MATCH($B11,Éléments!$C$5:$C$14,1),2),INDEX(Butin!$E$15:$K$24,MATCH($B11,Éléments!$C$5:$C$14,1),2))) -> 0.4 | AP11: =IF($H11="Boss",INDEX(Butin!$E$28:$K$37,MATCH($B11,Éléments!$C$5:$C$14,1),3),IF($H11="Dragon",INDEX(Butin!$E$41:$K$50,MATCH($B11,Éléments!$C$5:$C$14,1),3),INDEX(Butin!$E$15:$K$24,MATCH($B11,Éléments!$C$5:$C$14,1),3))) -> 0.22 | AQ11: =IF($H11="Boss",INDEX(Butin!$E$28:$K$37,MATCH($B11,Éléments!$C$5:$C$14,1),4),IF($H11="Dragon",INDEX(Butin!$E$41:$K$50,MATCH($B11,Éléments!$C$5:$C$14,1),4),INDEX(Butin!$E$15:$K$24,MATCH($B11,Éléments!$C$5:$C$14,1),4))) -> 0.06 | AR11: =IF($H11="Boss",INDEX(Butin!$E$28:$K$37,MATCH($B11,Éléments!$C$5:$C$14,1),5),IF($H11="Dragon",INDEX(Butin!$E$41:$K$50,MATCH($B11,Éléments!$C$5:$C$14,1),5),INDEX(Butin!$E$15:$K$24,MATCH($B11,Éléments!$C$5:$C$14,1),5))) -> 0 | AS11: =IF($H11="Boss",INDEX(Butin!$E$28:$K$37,MATCH($B11,Éléments!$C$5:$C$14,1),6),IF($H11="Dragon",INDEX(Butin!$E$41:$K$50,MATCH($B11,Éléments!$C$5:$C$14,1),6),INDEX(Butin!$E$15:$K$24,MATCH($B11,Éléments!$C$5:$C$14,1),6))) -> 0 | AT11: =IF($H11="Boss",INDEX(Butin!$E$28:$K$37,MATCH($B11,Éléments!$C$5:$C$14,1),7),IF($H11="Dragon",INDEX(Butin!$E$41:$K$50,MATCH($B11,Éléments!$C$5:$C$14,1),7),INDEX(Butin!$E$15:$K$24,MATCH($B11,Éléments!$C$5:$C$14,1),7))) -> 0.02 | AU11: =IF(AT11=0,"—",INDEX(Butin!$D$54:$D$63,MATCH($B11,Éléments!$C$5:$C$14,1))&" · "&INDEX(Butin!$F$54:$F$63,MATCH($B11,Éléments!$C$5:$C$14,1))&" · "&INDEX(Butin!$H$54:$H$63,MATCH($B11,Éléments!$C$5:$C$14,1))) -> Heaume du Roi Déchu · Bâton de la Singularité · Bague du Dernier Souffle | AV11: Dragon (Neutre) | AW11: =B11&IF(G11="Oui","|B","|N") -> 9|B | AX11: =(Paramètres!$B$5+(1-Paramètres!$B$5)*((K11-Paramètres!$B$7)/(Paramètres!$B$8-Paramètres!$B$7))^Paramètres!$B$6) -> 0.096416176 | AY11: =MATCH(I11,Rôles!$A$5:$A$13,0) -> 9 | AZ11: =MATCH(H11,Rôles!$A$18:$A$22,0) -> 5
A12: MON-006 | B12: 10 | C12: {=INDEX(Zones!$B$6:$B$35,MATCH(B12,Zones!$A$6:$A$35,0))} -> Village gobelin | D12: {=INDEX(Éléments!$B$5:$B$14,MATCH(B12,Éléments!$C$5:$C$14,1))} -> Forêt | E12: {=INDEX(Éléments!$A$5:$A$14,MATCH(B12,Éléments!$C$5:$C$14,1))} -> Neutre | F12: Chef gobelin | G12: =IF(OR(H12="Boss",H12="Dragon"),"Oui","Non") -> Oui | H12: Boss | I12: Guerrier | J12: Physique | K12: =IF($F$3="",B12,$F$3) -> 10 | L12: {=ROUND(Paramètres!$B$16*(Paramètres!$B$5+(1-Paramètres!$B$5)*((K12-Paramètres!$B$7)/(Paramètres!$B$8-Paramètres!$B$7))^Paramètres!$B$6)*INDEX(Rôles!$B$18:$B$22,AZ12)*INDEX(Rôles!$B$5:$B$13,AY12),0)} -> 1124 | M12: {=ROUND(IF(J12="Physique",1,IF(J12="Mixte",Paramètres!$B$32,0))*Paramètres!$B$12*(Paramètres!$B$5+(1-Paramètres!$B$5)*((K12-Paramètres!$B$7)/(Paramètres!$B$8-Paramètres!$B$7))^Paramètres!$B$6)*INDEX(Rôles!$C$18:$C$22,AZ12)*INDEX(Rôles!$C$5:$C$13,AY12)/(Paramètres!$B$35*(1-Paramètres!$B$36)),0)} -> 71 | N12: {=ROUND(IF(J12="Magique",1,IF(J12="Mixte",Paramètres!$B$32,0))*Paramètres!$B$12*(Paramètres!$B$5+(1-Paramètres!$B$5)*((K12-Paramètres!$B$7)/(Paramètres!$B$8-Paramètres!$B$7))^Paramètres!$B$6)*INDEX(Rôles!$C$18:$C$22,AZ12)*INDEX(Rôles!$C$5:$C$13,AY12)/(Paramètres!$B$35*(1-Paramètres!$B$36)),0)} -> 0 | O12: {=ROUND(Paramètres!$B$18*(Paramètres!$B$5+(1-Paramètres!$B$5)*((K12-Paramètres!$B$7)/(Paramètres!$B$8-Paramètres!$B$7))^Paramètres!$B$6)*INDEX(Rôles!$D$5:$D$13,AY12)*INDEX(Rôles!$D$18:$D$22,AZ12),0)} -> 61 | P12: {=ROUND(Paramètres!$B$19*(Paramètres!$B$5+(1-Paramètres!$B$5)*((K12-Paramètres!$B$7)/(Paramètres!$B$8-Paramètres!$B$7))^Paramètres!$B$6)*INDEX(Rôles!$E$5:$E$13,AY12)*INDEX(Rôles!$D$18:$D$22,AZ12),0)} -> 65 | Q12: {=ROUND(Paramètres!$B$20*(Paramètres!$B$5+(1-Paramètres!$B$5)*((K12-Paramètres!$B$7)/(Paramètres!$B$8-Paramètres!$B$7))^Paramètres!$B$6)*INDEX(Rôles!$F$5:$F$13,AY12),0)} -> 11 | R12: =ROUND(Paramètres!$B$64*$AX12*INDEX(Rôles!$N$5:$N$13,$AY12)*INDEX(Rôles!$I$18:$I$22,$AZ12),0) -> 11 | S12: {=MIN(1,ROUND(Paramètres!$B$21*INDEX(Rôles!$G$5:$G$13,AY12),3))} -> 0.9 | T12: {=MIN(Paramètres!$B$28,ROUND(Paramètres!$B$22*INDEX(Rôles!$H$5:$H$13,AY12),3))} -> 0.05 | U12: {=ROUND(Paramètres!$B$23*INDEX(Rôles!$I$5:$I$13,AY12),3)} -> 0.5 | V12: {=MIN(Paramètres!$B$29,ROUND(Paramètres!$B$24*INDEX(Rôles!$J$5:$J$13,AY12),3))} -> 0.05 | W12: {=MIN(Paramètres!$B$27,ROUND((Paramètres!$B$25+(Paramètres!$B$26-Paramètres!$B$25)*(K12-Paramètres!$B$7)/(Paramètres!$B$8-Paramètres!$B$7))*INDEX(Rôles!$K$5:$K$13,AY12)+INDEX(Rôles!$G$18:$G$22,AZ12),3))} -> 0.273 | X12: =ROUND(1-(1-P12/(P12+(Paramètres!$B$19*(Paramètres!$B$5+(1-Paramètres!$B$5)*((K12-Paramètres!$B$7)/(Paramètres!$B$8-Paramètres!$B$7))^Paramètres!$B$6)*(1-Paramètres!$B$30)/Paramètres!$B$30)))*(1-O12/(O12+(Paramètres!$B$18*(Paramètres!$B$5+(1-Paramètres!$B$5)*((K12-Paramètres!$B$7)/(Paramètres!$B$8-Paramètres!$B$7))^Paramètres!$B$6)*(1-Paramètres!$B$31)/Paramètres!$B$31))),3) -> 0.417 | Y12: =ROUND(O12/(O12+(Paramètres!$B$18*(Paramètres!$B$5+(1-Paramètres!$B$5)*((K12-Paramètres!$B$7)/(Paramètres!$B$8-Paramètres!$B$7))^Paramètres!$B$6)*(1-Paramètres!$B$31)/Paramètres!$B$31)),3) -> 0.188 | Z12: {=IF(E12="Neutre",0,MIN(1,INDEX(Rôles!$L$5:$L$13,AY12)+INDEX(Rôles!$F$18:$F$22,AZ12)))} -> 0 | AA12: {=ROUND(INDEX(Rôles!$C$18:$C$22,AZ12)*INDEX(Rôles!$C$5:$C$13,AY12),4)} -> 0.03 | AB12: {=ROUND(INDEX(Rôles!$B$18:$B$22,AZ12)*INDEX(Rôles!$B$5:$B$13,AY12),2)} -> 13.8 | AC12: {=INDEX(Rôles!$E$18:$E$22,AZ12)} -> 8 | AD12: {=INDEX(Éléments!$F$5:$F$14,MATCH(E12,Éléments!$A$5:$A$14,0))} -> — | AE12: {=INDEX(Éléments!$G$5:$G$14,MATCH(E12,Éléments!$A$5:$A$14,0))} -> — | AF12: Assommé | AG12: 0.3 | AH12: Intimidé | AI12: 0.3 | AJ12: {=ROUND(ROUND(Paramètres!$B$49*K12^Paramètres!$B$50,0)*INDEX(Rôles!$E$18:$E$22,AZ12),0)} -> 856 | AK12: {=ROUND(ROUND(Paramètres!$B$53*K12^Paramètres!$B$54,0)*INDEX(Rôles!$E$18:$E$22,AZ12),0)} -> 536 | AL12: =INDEX(Butin!$B$7:$B$11,AZ12) -> 1 | AM12: =INDEX(Butin!$E$7:$E$11,AZ12) -> 1.4 | AN12: =IF($H12="Boss",INDEX(Butin!$E$28:$K$37,MATCH($B12,Éléments!$C$5:$C$14,1),1),IF($H12="Dragon",INDEX(Butin!$E$41:$K$50,MATCH($B12,Éléments!$C$5:$C$14,1),1),INDEX(Butin!$E$15:$K$24,MATCH($B12,Éléments!$C$5:$C$14,1),1))) -> 0.4 | AO12: =IF($H12="Boss",INDEX(Butin!$E$28:$K$37,MATCH($B12,Éléments!$C$5:$C$14,1),2),IF($H12="Dragon",INDEX(Butin!$E$41:$K$50,MATCH($B12,Éléments!$C$5:$C$14,1),2),INDEX(Butin!$E$15:$K$24,MATCH($B12,Éléments!$C$5:$C$14,1),2))) -> 0.4 | AP12: =IF($H12="Boss",INDEX(Butin!$E$28:$K$37,MATCH($B12,Éléments!$C$5:$C$14,1),3),IF($H12="Dragon",INDEX(Butin!$E$41:$K$50,MATCH($B12,Éléments!$C$5:$C$14,1),3),INDEX(Butin!$E$15:$K$24,MATCH($B12,Éléments!$C$5:$C$14,1),3))) -> 0.15 | AQ12: =IF($H12="Boss",INDEX(Butin!$E$28:$K$37,MATCH($B12,Éléments!$C$5:$C$14,1),4),IF($H12="Dragon",INDEX(Butin!$E$41:$K$50,MATCH($B12,Éléments!$C$5:$C$14,1),4),INDEX(Butin!$E$15:$K$24,MATCH($B12,Éléments!$C$5:$C$14,1),4))) -> 0.04 | AR12: =IF($H12="Boss",INDEX(Butin!$E$28:$K$37,MATCH($B12,Éléments!$C$5:$C$14,1),5),IF($H12="Dragon",INDEX(Butin!$E$41:$K$50,MATCH($B12,Éléments!$C$5:$C$14,1),5),INDEX(Butin!$E$15:$K$24,MATCH($B12,Éléments!$C$5:$C$14,1),5))) -> 0 | AS12: =IF($H12="Boss",INDEX(Butin!$E$28:$K$37,MATCH($B12,Éléments!$C$5:$C$14,1),6),IF($H12="Dragon",INDEX(Butin!$E$41:$K$50,MATCH($B12,Éléments!$C$5:$C$14,1),6),INDEX(Butin!$E$15:$K$24,MATCH($B12,Éléments!$C$5:$C$14,1),6))) -> 0 | AT12: =IF($H12="Boss",INDEX(Butin!$E$28:$K$37,MATCH($B12,Éléments!$C$5:$C$14,1),7),IF($H12="Dragon",INDEX(Butin!$E$41:$K$50,MATCH($B12,Éléments!$C$5:$C$14,1),7),INDEX(Butin!$E$15:$K$24,MATCH($B12,Éléments!$C$5:$C$14,1),7))) -> 0.01 | AU12: =IF(AT12=0,"—",INDEX(Butin!$D$54:$D$63,MATCH($B12,Éléments!$C$5:$C$14,1))&" · "&INDEX(Butin!$F$54:$F$63,MATCH($B12,Éléments!$C$5:$C$14,1))&" · "&INDEX(Butin!$H$54:$H$63,MATCH($B12,Éléments!$C$5:$C$14,1))) -> Heaume du Roi Déchu · Bâton de la Singularité · Bague du Dernier Souffle | AV12: Chef Gobbelin (Boss) | AW12: =B12&IF(G12="Oui","|B","|N") -> 10|B | AX12: =(Paramètres!$B$5+(1-Paramètres!$B$5)*((K12-Paramètres!$B$7)/(Paramètres!$B$8-Paramètres!$B$7))^Paramètres!$B$6) -> 0.10346288 | AY12: =MATCH(I12,Rôles!$A$5:$A$13,0) -> 3 | AZ12: =MATCH(H12,Rôles!$A$18:$A$22,0) -> 4
A13: MON-007 | B13: 10 | C13: {=INDEX(Zones!$B$6:$B$35,MATCH(B13,Zones!$A$6:$A$35,0))} -> Village gobelin | D13: {=INDEX(Éléments!$B$5:$B$14,MATCH(B13,Éléments!$C$5:$C$14,1))} -> Forêt | E13: {=INDEX(Éléments!$A$5:$A$14,MATCH(B13,Éléments!$C$5:$C$14,1))} -> Neutre | F13: Gobelin | G13: =IF(OR(H13="Boss",H13="Dragon"),"Oui","Non") -> Non | H13: Faible | I13: Assassin | J13: Physique | K13: =IF($F$3="",B13,$F$3) -> 10 | L13: {=ROUND(Paramètres!$B$16*(Paramètres!$B$5+(1-Paramètres!$B$5)*((K13-Paramètres!$B$7)/(Paramètres!$B$8-Paramètres!$B$7))^Paramètres!$B$6)*INDEX(Rôles!$B$18:$B$22,AZ13)*INDEX(Rôles!$B$5:$B$13,AY13),0)} -> 92 | M13: {=ROUND(IF(J13="Physique",1,IF(J13="Mixte",Paramètres!$B$32,0))*Paramètres!$B$12*(Paramètres!$B$5+(1-Paramètres!$B$5)*((K13-Paramètres!$B$7)/(Paramètres!$B$8-Paramètres!$B$7))^Paramètres!$B$6)*INDEX(Rôles!$C$18:$C$22,AZ13)*INDEX(Rôles!$C$5:$C$13,AY13)/(Paramètres!$B$35*(1-Paramètres!$B$36)),0)} -> 28 | N13: {=ROUND(IF(J13="Magique",1,IF(J13="Mixte",Paramètres!$B$32,0))*Paramètres!$B$12*(Paramètres!$B$5+(1-Paramètres!$B$5)*((K13-Paramètres!$B$7)/(Paramètres!$B$8-Paramètres!$B$7))^Paramètres!$B$6)*INDEX(Rôles!$C$18:$C$22,AZ13)*INDEX(Rôles!$C$5:$C$13,AY13)/(Paramètres!$B$35*(1-Paramètres!$B$36)),0)} -> 0 | O13: {=ROUND(Paramètres!$B$18*(Paramètres!$B$5+(1-Paramètres!$B$5)*((K13-Paramètres!$B$7)/(Paramètres!$B$8-Paramètres!$B$7))^Paramètres!$B$6)*INDEX(Rôles!$D$5:$D$13,AY13)*INDEX(Rôles!$D$18:$D$22,AZ13),0)} -> 22 | P13: {=ROUND(Paramètres!$B$19*(Paramètres!$B$5+(1-Paramètres!$B$5)*((K13-Paramètres!$B$7)/(Paramètres!$B$8-Paramètres!$B$7))^Paramètres!$B$6)*INDEX(Rôles!$E$5:$E$13,AY13)*INDEX(Rôles!$D$18:$D$22,AZ13),0)} -> 17 | Q13: {=ROUND(Paramètres!$B$20*(Paramètres!$B$5+(1-Paramètres!$B$5)*((K13-Paramètres!$B$7)/(Paramètres!$B$8-Paramètres!$B$7))^Paramètres!$B$6)*INDEX(Rôles!$F$5:$F$13,AY13),0)} -> 20 | R13: =ROUND(Paramètres!$B$64*$AX13*INDEX(Rôles!$N$5:$N$13,$AY13)*INDEX(Rôles!$I$18:$I$22,$AZ13),0) -> 14 | S13: {=MIN(1,ROUND(Paramètres!$B$21*INDEX(Rôles!$G$5:$G$13,AY13),3))} -> 1 | T13: {=MIN(Paramètres!$B$28,ROUND(Paramètres!$B$22*INDEX(Rôles!$H$5:$H$13,AY13),3))} -> 0.08 | U13: {=ROUND(Paramètres!$B$23*INDEX(Rôles!$I$5:$I$13,AY13),3)} -> 0.7 | V13: {=MIN(Paramètres!$B$29,ROUND(Paramètres!$B$24*INDEX(Rôles!$J$5:$J$13,AY13),3))} -> 0.06 | W13: {=MIN(Paramètres!$B$27,ROUND((Paramètres!$B$25+(Paramètres!$B$26-Paramètres!$B$25)*(K13-Paramètres!$B$7)/(Paramètres!$B$8-Paramètres!$B$7))*INDEX(Rôles!$K$5:$K$13,AY13)+INDEX(Rôles!$G$18:$G$22,AZ13),3))} -> 0.058 | X13: =ROUND(1-(1-P13/(P13+(Paramètres!$B$19*(Paramètres!$B$5+(1-Paramètres!$B$5)*((K13-Paramètres!$B$7)/(Paramètres!$B$8-Paramètres!$B$7))^Paramètres!$B$6)*(1-Paramètres!$B$30)/Paramètres!$B$30)))*(1-O13/(O13+(Paramètres!$B$18*(Paramètres!$B$5+(1-Paramètres!$B$5)*((K13-Paramètres!$B$7)/(Paramètres!$B$8-Paramètres!$B$7))^Paramètres!$B$6)*(1-Paramètres!$B$31)/Paramètres!$B$31))),3) -> 0.163 | Y13: =ROUND(O13/(O13+(Paramètres!$B$18*(Paramètres!$B$5+(1-Paramètres!$B$5)*((K13-Paramètres!$B$7)/(Paramètres!$B$8-Paramètres!$B$7))^Paramètres!$B$6)*(1-Paramètres!$B$31)/Paramètres!$B$31)),3) -> 0.077 | Z13: {=IF(E13="Neutre",0,MIN(1,INDEX(Rôles!$L$5:$L$13,AY13)+INDEX(Rôles!$F$18:$F$22,AZ13)))} -> 0 | AA13: {=ROUND(INDEX(Rôles!$C$18:$C$22,AZ13)*INDEX(Rôles!$C$5:$C$13,AY13),4)} -> 0.012 | AB13: {=ROUND(INDEX(Rôles!$B$18:$B$22,AZ13)*INDEX(Rôles!$B$5:$B$13,AY13),2)} -> 1.13 | AC13: {=INDEX(Rôles!$E$18:$E$22,AZ13)} -> 0.7 | AD13: {=INDEX(Éléments!$F$5:$F$14,MATCH(E13,Éléments!$A$5:$A$14,0))} -> — | AE13: {=INDEX(Éléments!$G$5:$G$14,MATCH(E13,Éléments!$A$5:$A$14,0))} -> — | AF13: Saignement | AG13: 0.15 | AJ13: {=ROUND(ROUND(Paramètres!$B$49*K13^Paramètres!$B$50,0)*INDEX(Rôles!$E$18:$E$22,AZ13),0)} -> 75 | AK13: {=ROUND(ROUND(Paramètres!$B$53*K13^Paramètres!$B$54,0)*INDEX(Rôles!$E$18:$E$22,AZ13),0)} -> 47 | AL13: =INDEX(Butin!$B$7:$B$11,AZ13) -> 0.03 | AM13: =INDEX(Butin!$E$7:$E$11,AZ13) -> 0.03 | AN13: =IF($H13="Boss",INDEX(Butin!$E$28:$K$37,MATCH($B13,Éléments!$C$5:$C$14,1),1),IF($H13="Dragon",INDEX(Butin!$E$41:$K$50,MATCH($B13,Éléments!$C$5:$C$14,1),1),INDEX(Butin!$E$15:$K$24,MATCH($B13,Éléments!$C$5:$C$14,1),1))) -> 0.8 | AO13: =IF($H13="Boss",INDEX(Butin!$E$28:$K$37,MATCH($B13,Éléments!$C$5:$C$14,1),2),IF($H13="Dragon",INDEX(Butin!$E$41:$K$50,MATCH($B13,Éléments!$C$5:$C$14,1),2),INDEX(Butin!$E$15:$K$24,MATCH($B13,Éléments!$C$5:$C$14,1),2))) -> 0.2 | AP13: =IF($H13="Boss",INDEX(Butin!$E$28:$K$37,MATCH($B13,Éléments!$C$5:$C$14,1),3),IF($H13="Dragon",INDEX(Butin!$E$41:$K$50,MATCH($B13,Éléments!$C$5:$C$14,1),3),INDEX(Butin!$E$15:$K$24,MATCH($B13,Éléments!$C$5:$C$14,1),3))) -> 0 | AQ13: =IF($H13="Boss",INDEX(Butin!$E$28:$K$37,MATCH($B13,Éléments!$C$5:$C$14,1),4),IF($H13="Dragon",INDEX(Butin!$E$41:$K$50,MATCH($B13,Éléments!$C$5:$C$14,1),4),INDEX(Butin!$E$15:$K$24,MATCH($B13,Éléments!$C$5:$C$14,1),4))) -> 0 | AR13: =IF($H13="Boss",INDEX(Butin!$E$28:$K$37,MATCH($B13,Éléments!$C$5:$C$14,1),5),IF($H13="Dragon",INDEX(Butin!$E$41:$K$50,MATCH($B13,Éléments!$C$5:$C$14,1),5),INDEX(Butin!$E$15:$K$24,MATCH($B13,Éléments!$C$5:$C$14,1),5))) -> 0 | AS13: =IF($H13="Boss",INDEX(Butin!$E$28:$K$37,MATCH($B13,Éléments!$C$5:$C$14,1),6),IF($H13="Dragon",INDEX(Butin!$E$41:$K$50,MATCH($B13,Éléments!$C$5:$C$14,1),6),INDEX(Butin!$E$15:$K$24,MATCH($B13,Éléments!$C$5:$C$14,1),6))) -> 0 | AT13: =IF($H13="Boss",INDEX(Butin!$E$28:$K$37,MATCH($B13,Éléments!$C$5:$C$14,1),7),IF($H13="Dragon",INDEX(Butin!$E$41:$K$50,MATCH($B13,Éléments!$C$5:$C$14,1),7),INDEX(Butin!$E$15:$K$24,MATCH($B13,Éléments!$C$5:$C$14,1),7))) -> 0 | AU13: =IF(AT13=0,"—",INDEX(Butin!$D$54:$D$63,MATCH($B13,Éléments!$C$5:$C$14,1))&" · "&INDEX(Butin!$F$54:$F$63,MATCH($B13,Éléments!$C$5:$C$14,1))&" · "&INDEX(Butin!$H$54:$H$63,MATCH($B13,Éléments!$C$5:$C$14,1))) -> — | AV13: Gobbelin | AW13: =B13&IF(G13="Oui","|B","|N") -> 10|N | AX13: =(Paramètres!$B$5+(1-Paramètres!$B$5)*((K13-Paramètres!$B$7)/(Paramètres!$B$8-Paramètres!$B$7))^Paramètres!$B$6) -> 0.10346288 | AY13: =MATCH(I13,Rôles!$A$5:$A$13,0) -> 7 | AZ13: =MATCH(H13,Rôles!$A$18:$A$22,0) -> 1
A14: MON-008 | B14: 10 | C14: {=INDEX(Zones!$B$6:$B$35,MATCH(B14,Zones!$A$6:$A$35,0))} -> Village gobelin | D14: {=INDEX(Éléments!$B$5:$B$14,MATCH(B14,Éléments!$C$5:$C$14,1))} -> Forêt | E14: {=INDEX(Éléments!$A$5:$A$14,MATCH(B14,Éléments!$C$5:$C$14,1))} -> Neutre | F14: Guerrier gobelin | G14: =IF(OR(H14="Boss",H14="Dragon"),"Oui","Non") -> Non | H14: Normal | I14: Guerrier | J14: Physique | K14: =IF($F$3="",B14,$F$3) -> 10 | L14: {=ROUND(Paramètres!$B$16*(Paramètres!$B$5+(1-Paramètres!$B$5)*((K14-Paramètres!$B$7)/(Paramètres!$B$8-Paramètres!$B$7))^Paramètres!$B$6)*INDEX(Rôles!$B$18:$B$22,AZ14)*INDEX(Rôles!$B$5:$B$13,AY14),0)} -> 187 | M14: {=ROUND(IF(J14="Physique",1,IF(J14="Mixte",Paramètres!$B$32,0))*Paramètres!$B$12*(Paramètres!$B$5+(1-Paramètres!$B$5)*((K14-Paramètres!$B$7)/(Paramètres!$B$8-Paramètres!$B$7))^Paramètres!$B$6)*INDEX(Rôles!$C$18:$C$22,AZ14)*INDEX(Rôles!$C$5:$C$13,AY14)/(Paramètres!$B$35*(1-Paramètres!$B$36)),0)} -> 35 | N14: {=ROUND(IF(J14="Magique",1,IF(J14="Mixte",Paramètres!$B$32,0))*Paramètres!$B$12*(Paramètres!$B$5+(1-Paramètres!$B$5)*((K14-Paramètres!$B$7)/(Paramètres!$B$8-Paramètres!$B$7))^Paramètres!$B$6)*INDEX(Rôles!$C$18:$C$22,AZ14)*INDEX(Rôles!$C$5:$C$13,AY14)/(Paramètres!$B$35*(1-Paramètres!$B$36)),0)} -> 0 | O14: {=ROUND(Paramètres!$B$18*(Paramètres!$B$5+(1-Paramètres!$B$5)*((K14-Paramètres!$B$7)/(Paramètres!$B$8-Paramètres!$B$7))^Paramètres!$B$6)*INDEX(Rôles!$D$5:$D$13,AY14)*INDEX(Rôles!$D$18:$D$22,AZ14),0)} -> 47 | P14: {=ROUND(Paramètres!$B$19*(Paramètres!$B$5+(1-Paramètres!$B$5)*((K14-Paramètres!$B$7)/(Paramètres!$B$8-Paramètres!$B$7))^Paramètres!$B$6)*INDEX(Rôles!$E$5:$E$13,AY14)*INDEX(Rôles!$D$18:$D$22,AZ14),0)} -> 50 | Q14: {=ROUND(Paramètres!$B$20*(Paramètres!$B$5+(1-Paramètres!$B$5)*((K14-Paramètres!$B$7)/(Paramètres!$B$8-Paramètres!$B$7))^Paramètres!$B$6)*INDEX(Rôles!$F$5:$F$13,AY14),0)} -> 11 | R14: =ROUND(Paramètres!$B$64*$AX14*INDEX(Rôles!$N$5:$N$13,$AY14)*INDEX(Rôles!$I$18:$I$22,$AZ14),0) -> 10 | S14: {=MIN(1,ROUND(Paramètres!$B$21*INDEX(Rôles!$G$5:$G$13,AY14),3))} -> 0.9 | T14: {=MIN(Paramètres!$B$28,ROUND(Paramètres!$B$22*INDEX(Rôles!$H$5:$H$13,AY14),3))} -> 0.05 | U14: {=ROUND(Paramètres!$B$23*INDEX(Rôles!$I$5:$I$13,AY14),3)} -> 0.5 | V14: {=MIN(Paramètres!$B$29,ROUND(Paramètres!$B$24*INDEX(Rôles!$J$5:$J$13,AY14),3))} -> 0.05 | W14: {=MIN(Paramètres!$B$27,ROUND((Paramètres!$B$25+(Paramètres!$B$26-Paramètres!$B$25)*(K14-Paramètres!$B$7)/(Paramètres!$B$8-Paramètres!$B$7))*INDEX(Rôles!$K$5:$K$13,AY14)+INDEX(Rôles!$G$18:$G$22,AZ14),3))} -> 0.073 | X14: =ROUND(1-(1-P14/(P14+(Paramètres!$B$19*(Paramètres!$B$5+(1-Paramètres!$B$5)*((K14-Paramètres!$B$7)/(Paramètres!$B$8-Paramètres!$B$7))^Paramètres!$B$6)*(1-Paramètres!$B$30)/Paramètres!$B$30)))*(1-O14/(O14+(Paramètres!$B$18*(Paramètres!$B$5+(1-Paramètres!$B$5)*((K14-Paramètres!$B$7)/(Paramètres!$B$8-Paramètres!$B$7))^Paramètres!$B$6)*(1-Paramètres!$B$31)/Paramètres!$B$31))),3) -> 0.348 | Y14: =ROUND(O14/(O14+(Paramètres!$B$18*(Paramètres!$B$5+(1-Paramètres!$B$5)*((K14-Paramètres!$B$7)/(Paramètres!$B$8-Paramètres!$B$7))^Paramètres!$B$6)*(1-Paramètres!$B$31)/Paramètres!$B$31)),3) -> 0.151 | Z14: {=IF(E14="Neutre",0,MIN(1,INDEX(Rôles!$L$5:$L$13,AY14)+INDEX(Rôles!$F$18:$F$22,AZ14)))} -> 0 | AA14: {=ROUND(INDEX(Rôles!$C$18:$C$22,AZ14)*INDEX(Rôles!$C$5:$C$13,AY14),4)} -> 0.015 | AB14: {=ROUND(INDEX(Rôles!$B$18:$B$22,AZ14)*INDEX(Rôles!$B$5:$B$13,AY14),2)} -> 2.3 | AC14: {=INDEX(Rôles!$E$18:$E$22,AZ14)} -> 1 | AD14: {=INDEX(Éléments!$F$5:$F$14,MATCH(E14,Éléments!$A$5:$A$14,0))} -> — | AE14: {=INDEX(Éléments!$G$5:$G$14,MATCH(E14,Éléments!$A$5:$A$14,0))} -> — | AF14: Saignement | AG14: 0.15 | AH14: Assommé | AI14: 0.1 | AJ14: {=ROUND(ROUND(Paramètres!$B$49*K14^Paramètres!$B$50,0)*INDEX(Rôles!$E$18:$E$22,AZ14),0)} -> 107 | AK14: {=ROUND(ROUND(Paramètres!$B$53*K14^Paramètres!$B$54,0)*INDEX(Rôles!$E$18:$E$22,AZ14),0)} -> 67 | AL14: =INDEX(Butin!$B$7:$B$11,AZ14) -> 0.05 | AM14: =INDEX(Butin!$E$7:$E$11,AZ14) -> 0.05 | AN14: =IF($H14="Boss",INDEX(Butin!$E$28:$K$37,MATCH($B14,Éléments!$C$5:$C$14,1),1),IF($H14="Dragon",INDEX(Butin!$E$41:$K$50,MATCH($B14,Éléments!$C$5:$C$14,1),1),INDEX(Butin!$E$15:$K$24,MATCH($B14,Éléments!$C$5:$C$14,1),1))) -> 0.8 | AO14: =IF($H14="Boss",INDEX(Butin!$E$28:$K$37,MATCH($B14,Éléments!$C$5:$C$14,1),2),IF($H14="Dragon",INDEX(Butin!$E$41:$K$50,MATCH($B14,Éléments!$C$5:$C$14,1),2),INDEX(Butin!$E$15:$K$24,MATCH($B14,Éléments!$C$5:$C$14,1),2))) -> 0.2 | AP14: =IF($H14="Boss",INDEX(Butin!$E$28:$K$37,MATCH($B14,Éléments!$C$5:$C$14,1),3),IF($H14="Dragon",INDEX(Butin!$E$41:$K$50,MATCH($B14,Éléments!$C$5:$C$14,1),3),INDEX(Butin!$E$15:$K$24,MATCH($B14,Éléments!$C$5:$C$14,1),3))) -> 0 | AQ14: =IF($H14="Boss",INDEX(Butin!$E$28:$K$37,MATCH($B14,Éléments!$C$5:$C$14,1),4),IF($H14="Dragon",INDEX(Butin!$E$41:$K$50,MATCH($B14,Éléments!$C$5:$C$14,1),4),INDEX(Butin!$E$15:$K$24,MATCH($B14,Éléments!$C$5:$C$14,1),4))) -> 0 | AR14: =IF($H14="Boss",INDEX(Butin!$E$28:$K$37,MATCH($B14,Éléments!$C$5:$C$14,1),5),IF($H14="Dragon",INDEX(Butin!$E$41:$K$50,MATCH($B14,Éléments!$C$5:$C$14,1),5),INDEX(Butin!$E$15:$K$24,MATCH($B14,Éléments!$C$5:$C$14,1),5))) -> 0 | AS14: =IF($H14="Boss",INDEX(Butin!$E$28:$K$37,MATCH($B14,Éléments!$C$5:$C$14,1),6),IF($H14="Dragon",INDEX(Butin!$E$41:$K$50,MATCH($B14,Éléments!$C$5:$C$14,1),6),INDEX(Butin!$E$15:$K$24,MATCH($B14,Éléments!$C$5:$C$14,1),6))) -> 0 | AT14: =IF($H14="Boss",INDEX(Butin!$E$28:$K$37,MATCH($B14,Éléments!$C$5:$C$14,1),7),IF($H14="Dragon",INDEX(Butin!$E$41:$K$50,MATCH($B14,Éléments!$C$5:$C$14,1),7),INDEX(Butin!$E$15:$K$24,MATCH($B14,Éléments!$C$5:$C$14,1),7))) -> 0 | AU14: =IF(AT14=0,"—",INDEX(Butin!$D$54:$D$63,MATCH($B14,Éléments!$C$5:$C$14,1))&" · "&INDEX(Butin!$F$54:$F$63,MATCH($B14,Éléments!$C$5:$C$14,1))&" · "&INDEX(Butin!$H$54:$H$63,MATCH($B14,Éléments!$C$5:$C$14,1))) -> — | AV14: Guerrier Gobbelin | AW14: =B14&IF(G14="Oui","|B","|N") -> 10|N | AX14: =(Paramètres!$B$5+(1-Paramètres!$B$5)*((K14-Paramètres!$B$7)/(Paramètres!$B$8-Paramètres!$B$7))^Paramètres!$B$6) -> 0.10346288 | AY14: =MATCH(I14,Rôles!$A$5:$A$13,0) -> 3 | AZ14: =MATCH(H14,Rôles!$A$18:$A$22,0) -> 2
