Workbook

Sheet Guide
A1: RPG tour par tour : compétences
A2: Familles de compétences par classe, variantes élémentaires, fusions, déblocages et rotation.
A4: PRINCIPE
A5: 3 familles par classe | B5: Attaque (liée à l'arme 1 : épée, bâton, arc), Soutien (liée à l'arme 2 : bouclier, orbe, carquois : buff, soin, bouclier, debuff) et Passif.
A6: Équipement | B6: 3 compétences actives + 2 passives. Une seule ultime parmi les actives (réglable dans Paramètres).
A7: Recharge | B7: Calculée (Bases, col. H). Les actives du kit de départ (niveau 1) n'ont aucune recharge : utilisables à chaque action. Les autres : score = puissance × 2 si attaque de zone + valeur d'effet ; score ≤ 1,0 → recharge 1 (chaque manche), ≤ 2,4 → recharge 2 (1 manche de pause), au-delà ou ultime → recharge 3 (2 manches de pause).
A8: Éléments | B8: Chaque compétence active existe en 10 éléments. Neutre = version de départ. L'élément ajoute une altération ou un bonus (Feu : Brûlure, Glace : Froid puis Gel, Eau : Mouillé…).
A9: Déblocage | B9: Les compétences de base se débloquent par niveau (1 à 60). Un élément se débloque en terminant le dernier étage de son biome : Terre (20), Feu (30), Vent (40), Acide (50), Eau (60), Glace (70), Électricité (80), Lumière (90), Ombre (100).
A10: Fusions | B10: Deux éléments sur une même compétence (55 fusions, noms du fichier Éléments/Fusions) : puissance ×1,10 et effet propre. Disponibles à la Tour d'alchimie (étage 85 du diagramme).
A11: Départ | B11: Chaque classe commence avec 2 actives sans recharge et 1 passif, en Neutre (ex. Guerrier : Frappe rapide, Coup d'estoc, Peau dure). Coup d'estoc, Lance arcanique et Tir précis passent à 0,90 de puissance (avec leur effet) pour rester un choix face à l'attaque à 1,00.
A12: ONGLETS
A13: Catalogue | B13: Les 484 compétences : 45 de base × 10 éléments, 24 passifs de classe et 10 affinités élémentaires. Filtres sur chaque colonne.
A14: Bases | B14: Les 79 compétences de base (cellules jaunes) : nom, racine des variantes, cible, recharge, puissance, effet, niveau requis. Tout le reste en découle.
A15: Éléments | B15: Étage de déblocage, effet ajouté aux attaques, effet ajouté aux soutiens, passif d'affinité, matrice des avantages.
A16: Fusions | B16: Les 55 fusions avec leur effet en combat au tour par tour et l'étage où elles deviennent possibles.
A17: Constructeur | B17: Une compétence + 1 ou 2 éléments → nom, effets, puissance, dégâts estimés contre un ennemi d'un élément donné.
A18: Rotation | B18: 3 actives + 2 passives : contrôles (classe, ultimes, déblocage) et simulation de 12 tours avec puissance moyenne par tour.
A19: Déblocages | B19: Combien de compétences chaque classe a à chaque étape de la tour, et le kit de départ.
A20: Paramètres | B20: Nombre d'emplacements, ultimes, ennemis par vague, repère de puissance, bonus de fusion, étage de la Tour d'alchimie.
A21: ÉQUILIBRAGE
A22: Repère | B22: Le bestiaire calibre les PV des monstres sur 1,5 × la stat d'attaque par tour. Une rotation ultime + compétence à 2 tours + compétence à 1 tour donne ~1,9 ; avec un soutien à la place, ~1,6.
A23: Puissances | B23: Sans recharge (départ) : ~0,9 à 1,0 ; recharge 1 : ~1,0 ; recharge 2 : ~1,5 à 1,8 (mono) ou ~0,8 à 0,95 sur toute la vague ; ultime : 2,8 à 3,0 (mono) ou ~1,5 à 1,6 (zone).
A24: Altérations | B24: Mêmes règles que le bestiaire : cumul max, durée, contrôles divisés par 2 sur les boss, jamais d'immunité totale.
A25: HYPOTHÈSES À VALIDER
A26: Stat du Tireur | B26: Le Tireur utilise la Force pour ses dégâts (et l'Agilité, la Précision et les critiques via l'équipement). À changer si tu préfères l'Agilité.
A27: Actions et mana | B27: Pas de mana : seules les recharges limitent les compétences. Solo : 3 actions par manche pour toute l'équipe (1 à 3 personnages). Multi : 3 actions par joueur. Une compétence à recharge ne peut être lancée qu'une fois par manche ; celles du kit de départ, sans recharge, autant de fois que voulu.
A28: Fusions tardives | B28: Le diagramme place la Tour d'alchimie à l'étage 85 : les fusions arrivent donc en fin de tour. Mettre 0 dans Paramètres pour les autoriser plus tôt.
A29: Ombre | B29: L'Ombre se débloque en finissant la tour (étage 100) : c'est une récompense de fin de jeu.
A30: LÉGENDE
A31: Cellule jaune, texte bleu | B31: Valeur modifiable. Les autres cellules sont des formules : ne pas les écraser. Fond orange = ultime.

Sheet Catalogue
A1: Catalogue des compétences et de leurs variantes élémentaires
A2: Chaque compétence active existe en 10 éléments (Neutre = version de départ). Passifs de classe et affinités élémentaires en fin de liste. Filtres sur chaque colonne.
A4: ID | B4: Classe | C4: Famille | D4: Type | E4: Compétence de base | F4: Élément | G4: Nom | H4: Cible | I4: Recharge (tours) | J4: Ultime | K4: Puissance (× stat) | L4: Stat | M4: Effet de base | N4: Effet de l’élément | O4: Déclenchement | P4: Niveau requis | Q4: Étage à terminer | R4: Disponible | S4: Puissance par tour (vague) | T4: (aide) N° base | U4: (aide) N° élément
A5: GUE-A01-NEU | B5: =INDEX(Bases!$B$5:$B$83,$T5) -> Guerrier | C5: =INDEX(Bases!$E$5:$E$83,$T5) -> Attaque (arme 1) | D5: =INDEX(Bases!$F$5:$F$83,$T5) -> Attaque | E5: =INDEX(Bases!$C$5:$C$83,$T5) -> Frappe rapide | F5: =INDEX(Éléments!$A$5:$A$14,$U5) -> Neutre | G5: =IF(OR($F5="Neutre",$C5="Passif"),$E5,INDEX(Bases!$D$5:$D$83,$T5)&" "&INDEX(Éléments!$D$5:$D$14,$U5)) -> Frappe rapide | H5: =INDEX(Bases!$G$5:$G$83,$T5) -> Mono | I5: =INDEX(Bases!$H$5:$H$83,$T5) -> 0 | J5: =INDEX(Bases!$I$5:$I$83,$T5) -> Non | K5: =INDEX(Bases!$J$5:$J$83,$T5) -> 1 | L5: =INDEX(Bases!$K$5:$K$83,$T5) -> Force | M5: =INDEX(Bases!$L$5:$L$83,$T5) -> Coup d'épée simple et fiable. | N5: =IF($C5="Passif","—",IF($C5="Attaque (arme 1)",INDEX(Éléments!$F$5:$F$14,$U5),INDEX(Éléments!$G$5:$G$14,$U5))) -> Aucune altération ; ignore 10 % de la Résistance de la cible. Fiable contre tous les biomes. | O5: =INDEX(Bases!$M$5:$M$83,$T5) -> Active | P5: =INDEX(Bases!$N$5:$N$83,$T5) -> 1 | Q5: =INDEX(Éléments!$C$5:$C$14,$U5) -> 0 | R5: ="Niv. "&$P5&IF($Q5>0," · étage "&$Q5&" terminé","") -> Niv. 1 | S5: =IF(ISNUMBER($I5),$K5*IF($H5="Zone",Paramètres!$B$8,1)/MAX(1,$I5),0) -> 1 | T5: 1 | U5: 1
A6: GUE-A01-TER | B6: =INDEX(Bases!$B$5:$B$83,$T6) -> Guerrier | C6: =INDEX(Bases!$E$5:$E$83,$T6) -> Attaque (arme 1) | D6: =INDEX(Bases!$F$5:$F$83,$T6) -> Attaque | E6: =INDEX(Bases!$C$5:$C$83,$T6) -> Frappe rapide | F6: =INDEX(Éléments!$A$5:$A$14,$U6) -> Terre | G6: =IF(OR($F6="Neutre",$C6="Passif"),$E6,INDEX(Bases!$D$5:$D$83,$T6)&" "&INDEX(Éléments!$D$5:$D$14,$U6)) -> Frappe rapide de pierre | H6: =INDEX(Bases!$G$5:$G$83,$T6) -> Mono | I6: =INDEX(Bases!$H$5:$H$83,$T6) -> 0 | J6: =INDEX(Bases!$I$5:$I$83,$T6) -> Non | K6: =INDEX(Bases!$J$5:$J$83,$T6) -> 1 | L6: =INDEX(Bases!$K$5:$K$83,$T6) -> Force | M6: =INDEX(Bases!$L$5:$L$83,$T6) -> Coup d'épée simple et fiable. | N6: =IF($C6="Passif","—",IF($C6="Attaque (arme 1)",INDEX(Éléments!$F$5:$F$14,$U6),INDEX(Éléments!$G$5:$G$14,$U6))) -> 30 % : Garde brisée (−15 % Résistance, 2 tours). | O6: =INDEX(Bases!$M$5:$M$83,$T6) -> Active | P6: =INDEX(Bases!$N$5:$N$83,$T6) -> 1 | Q6: =INDEX(Éléments!$C$5:$C$14,$U6) -> 20 | R6: ="Niv. "&$P6&IF($Q6>0," · étage "&$Q6&" terminé","") -> Niv. 1 · étage 20 terminé | S6: =IF(ISNUMBER($I6),$K6*IF($H6="Zone",Paramètres!$B$8,1)/MAX(1,$I6),0) -> 1 | T6: 1 | U6: 2
A7: GUE-A01-FEU | B7: =INDEX(Bases!$B$5:$B$83,$T7) -> Guerrier | C7: =INDEX(Bases!$E$5:$E$83,$T7) -> Attaque (arme 1) | D7: =INDEX(Bases!$F$5:$F$83,$T7) -> Attaque | E7: =INDEX(Bases!$C$5:$C$83,$T7) -> Frappe rapide | F7: =INDEX(Éléments!$A$5:$A$14,$U7) -> Feu | G7: =IF(OR($F7="Neutre",$C7="Passif"),$E7,INDEX(Bases!$D$5:$D$83,$T7)&" "&INDEX(Éléments!$D$5:$D$14,$U7)) -> Frappe rapide de feu | H7: =INDEX(Bases!$G$5:$G$83,$T7) -> Mono | I7: =INDEX(Bases!$H$5:$H$83,$T7) -> 0 | J7: =INDEX(Bases!$I$5:$I$83,$T7) -> Non | K7: =INDEX(Bases!$J$5:$J$83,$T7) -> 1 | L7: =INDEX(Bases!$K$5:$K$83,$T7) -> Force | M7: =INDEX(Bases!$L$5:$L$83,$T7) -> Coup d'épée simple et fiable. | N7: =IF($C7="Passif","—",IF($C7="Attaque (arme 1)",INDEX(Éléments!$F$5:$F$14,$U7),INDEX(Éléments!$G$5:$G$14,$U7))) -> 35 % : Brûlure (8 % de la stat d'attaque par tour, 3 tours, non cumulable). | O7: =INDEX(Bases!$M$5:$M$83,$T7) -> Active | P7: =INDEX(Bases!$N$5:$N$83,$T7) -> 1 | Q7: =INDEX(Éléments!$C$5:$C$14,$U7) -> 30 | R7: ="Niv. "&$P7&IF($Q7>0," · étage "&$Q7&" terminé","") -> Niv. 1 · étage 30 terminé | S7: =IF(ISNUMBER($I7),$K7*IF($H7="Zone",Paramètres!$B$8,1)/MAX(1,$I7),0) -> 1 | T7: 1 | U7: 3
A8: GUE-A01-VEN | B8: =INDEX(Bases!$B$5:$B$83,$T8) -> Guerrier | C8: =INDEX(Bases!$E$5:$E$83,$T8) -> Attaque (arme 1) | D8: =INDEX(Bases!$F$5:$F$83,$T8) -> Attaque | E8: =INDEX(Bases!$C$5:$C$83,$T8) -> Frappe rapide | F8: =INDEX(Éléments!$A$5:$A$14,$U8) -> Vent | G8: =IF(OR($F8="Neutre",$C8="Passif"),$E8,INDEX(Bases!$D$5:$D$83,$T8)&" "&INDEX(Éléments!$D$5:$D$14,$U8)) -> Frappe rapide de vent | H8: =INDEX(Bases!$G$5:$G$83,$T8) -> Mono | I8: =INDEX(Bases!$H$5:$H$83,$T8) -> 0 | J8: =INDEX(Bases!$I$5:$I$83,$T8) -> Non | K8: =INDEX(Bases!$J$5:$J$83,$T8) -> 1 | L8: =INDEX(Bases!$K$5:$K$83,$T8) -> Force | M8: =INDEX(Bases!$L$5:$L$83,$T8) -> Coup d'épée simple et fiable. | N8: =IF($C8="Passif","—",IF($C8="Attaque (arme 1)",INDEX(Éléments!$F$5:$F$14,$U8),INDEX(Éléments!$G$5:$G$14,$U8))) -> +10 % de chance de critique ; 30 % : Désorienté (−15 % Précision, 2 tours). | O8: =INDEX(Bases!$M$5:$M$83,$T8) -> Active | P8: =INDEX(Bases!$N$5:$N$83,$T8) -> 1 | Q8: =INDEX(Éléments!$C$5:$C$14,$U8) -> 40 | R8: ="Niv. "&$P8&IF($Q8>0," · étage "&$Q8&" terminé","") -> Niv. 1 · étage 40 terminé | S8: =IF(ISNUMBER($I8),$K8*IF($H8="Zone",Paramètres!$B$8,1)/MAX(1,$I8),0) -> 1 | T8: 1 | U8: 4
A9: GUE-A01-ACI | B9: =INDEX(Bases!$B$5:$B$83,$T9) -> Guerrier | C9: =INDEX(Bases!$E$5:$E$83,$T9) -> Attaque (arme 1) | D9: =INDEX(Bases!$F$5:$F$83,$T9) -> Attaque | E9: =INDEX(Bases!$C$5:$C$83,$T9) -> Frappe rapide | F9: =INDEX(Éléments!$A$5:$A$14,$U9) -> Acide | G9: =IF(OR($F9="Neutre",$C9="Passif"),$E9,INDEX(Bases!$D$5:$D$83,$T9)&" "&INDEX(Éléments!$D$5:$D$14,$U9)) -> Frappe rapide d'acide | H9: =INDEX(Bases!$G$5:$G$83,$T9) -> Mono | I9: =INDEX(Bases!$H$5:$H$83,$T9) -> 0 | J9: =INDEX(Bases!$I$5:$I$83,$T9) -> Non | K9: =INDEX(Bases!$J$5:$J$83,$T9) -> 1 | L9: =INDEX(Bases!$K$5:$K$83,$T9) -> Force | M9: =INDEX(Bases!$L$5:$L$83,$T9) -> Coup d'épée simple et fiable. | N9: =IF($C9="Passif","—",IF($C9="Attaque (arme 1)",INDEX(Éléments!$F$5:$F$14,$U9),INDEX(Éléments!$G$5:$G$14,$U9))) -> 50 % : 1 pile de Corrosion (−5 % Armure par pile, 4 piles max, 3 tours). | O9: =INDEX(Bases!$M$5:$M$83,$T9) -> Active | P9: =INDEX(Bases!$N$5:$N$83,$T9) -> 1 | Q9: =INDEX(Éléments!$C$5:$C$14,$U9) -> 50 | R9: ="Niv. "&$P9&IF($Q9>0," · étage "&$Q9&" terminé","") -> Niv. 1 · étage 50 terminé | S9: =IF(ISNUMBER($I9),$K9*IF($H9="Zone",Paramètres!$B$8,1)/MAX(1,$I9),0) -> 1 | T9: 1 | U9: 5
A10: GUE-A01-EAU | B10: =INDEX(Bases!$B$5:$B$83,$T10) -> Guerrier | C10: =INDEX(Bases!$E$5:$E$83,$T10) -> Attaque (arme 1) | D10: =INDEX(Bases!$F$5:$F$83,$T10) -> Attaque | E10: =INDEX(Bases!$C$5:$C$83,$T10) -> Frappe rapide | F10: =INDEX(Éléments!$A$5:$A$14,$U10) -> Eau | G10: =IF(OR($F10="Neutre",$C10="Passif"),$E10,INDEX(Bases!$D$5:$D$83,$T10)&" "&INDEX(Éléments!$D$5:$D$14,$U10)) -> Frappe rapide d'eau | H10: =INDEX(Bases!$G$5:$G$83,$T10) -> Mono | I10: =INDEX(Bases!$H$5:$H$83,$T10) -> 0 | J10: =INDEX(Bases!$I$5:$I$83,$T10) -> Non | K10: =INDEX(Bases!$J$5:$J$83,$T10) -> 1 | L10: =INDEX(Bases!$K$5:$K$83,$T10) -> Force | M10: =INDEX(Bases!$L$5:$L$83,$T10) -> Coup d'épée simple et fiable. | N10: =IF($C10="Passif","—",IF($C10="Attaque (arme 1)",INDEX(Éléments!$F$5:$F$14,$U10),INDEX(Éléments!$G$5:$G$14,$U10))) -> 50 % : Mouillé (+25 % de dégâts d'Électricité subis, retire Brûlure, 3 tours). | O10: =INDEX(Bases!$M$5:$M$83,$T10) -> Active | P10: =INDEX(Bases!$N$5:$N$83,$T10) -> 1 | Q10: =INDEX(Éléments!$C$5:$C$14,$U10) -> 60 | R10: ="Niv. "&$P10&IF($Q10>0," · étage "&$Q10&" terminé","") -> Niv. 1 · étage 60 terminé | S10: =IF(ISNUMBER($I10),$K10*IF($H10="Zone",Paramètres!$B$8,1)/MAX(1,$I10),0) -> 1 | T10: 1 | U10: 6
A11: GUE-A01-GLA | B11: =INDEX(Bases!$B$5:$B$83,$T11) -> Guerrier | C11: =INDEX(Bases!$E$5:$E$83,$T11) -> Attaque (arme 1) | D11: =INDEX(Bases!$F$5:$F$83,$T11) -> Attaque | E11: =INDEX(Bases!$C$5:$C$83,$T11) -> Frappe rapide | F11: =INDEX(Éléments!$A$5:$A$14,$U11) -> Glace | G11: =IF(OR($F11="Neutre",$C11="Passif"),$E11,INDEX(Bases!$D$5:$D$83,$T11)&" "&INDEX(Éléments!$D$5:$D$14,$U11)) -> Frappe rapide de glace | H11: =INDEX(Bases!$G$5:$G$83,$T11) -> Mono | I11: =INDEX(Bases!$H$5:$H$83,$T11) -> 0 | J11: =INDEX(Bases!$I$5:$I$83,$T11) -> Non | K11: =INDEX(Bases!$J$5:$J$83,$T11) -> 1 | L11: =INDEX(Bases!$K$5:$K$83,$T11) -> Force | M11: =INDEX(Bases!$L$5:$L$83,$T11) -> Coup d'épée simple et fiable. | N11: =IF($C11="Passif","—",IF($C11="Attaque (arme 1)",INDEX(Éléments!$F$5:$F$14,$U11),INDEX(Éléments!$G$5:$G$14,$U11))) -> 40 % : 1 pile de Froid (−8 % Agilité ; à 3 piles : Gel, la cible perd 1 tour). | O11: =INDEX(Bases!$M$5:$M$83,$T11) -> Active | P11: =INDEX(Bases!$N$5:$N$83,$T11) -> 1 | Q11: =INDEX(Éléments!$C$5:$C$14,$U11) -> 70 | R11: ="Niv. "&$P11&IF($Q11>0," · étage "&$Q11&" terminé","") -> Niv. 1 · étage 70 terminé | S11: =IF(ISNUMBER($I11),$K11*IF($H11="Zone",Paramètres!$B$8,1)/MAX(1,$I11),0) -> 1 | T11: 1 | U11: 7
A12: GUE-A01-ELE | B12: =INDEX(Bases!$B$5:$B$83,$T12) -> Guerrier | C12: =INDEX(Bases!$E$5:$E$83,$T12) -> Attaque (arme 1) | D12: =INDEX(Bases!$F$5:$F$83,$T12) -> Attaque | E12: =INDEX(Bases!$C$5:$C$83,$T12) -> Frappe rapide | F12: =INDEX(Éléments!$A$5:$A$14,$U12) -> Électricité | G12: =IF(OR($F12="Neutre",$C12="Passif"),$E12,INDEX(Bases!$D$5:$D$83,$T12)&" "&INDEX(Éléments!$D$5:$D$14,$U12)) -> Frappe rapide de foudre | H12: =INDEX(Bases!$G$5:$G$83,$T12) -> Mono | I12: =INDEX(Bases!$H$5:$H$83,$T12) -> 0 | J12: =INDEX(Bases!$I$5:$I$83,$T12) -> Non | K12: =INDEX(Bases!$J$5:$J$83,$T12) -> 1 | L12: =INDEX(Bases!$K$5:$K$83,$T12) -> Force | M12: =INDEX(Bases!$L$5:$L$83,$T12) -> Coup d'épée simple et fiable. | N12: =IF($C12="Passif","—",IF($C12="Attaque (arme 1)",INDEX(Éléments!$F$5:$F$14,$U12),INDEX(Éléments!$G$5:$G$14,$U12))) -> Rebondit sur 1 autre ennemi (40 % des dégâts) ; 10 % : Étourdissement (1 tour). | O12: =INDEX(Bases!$M$5:$M$83,$T12) -> Active | P12: =INDEX(Bases!$N$5:$N$83,$T12) -> 1 | Q12: =INDEX(Éléments!$C$5:$C$14,$U12) -> 80 | R12: ="Niv. "&$P12&IF($Q12>0," · étage "&$Q12&" terminé","") -> Niv. 1 · étage 80 terminé | S12: =IF(ISNUMBER($I12),$K12*IF($H12="Zone",Paramètres!$B$8,1)/MAX(1,$I12),0) -> 1 | T12: 1 | U12: 8
A13: GUE-A01-LUM | B13: =INDEX(Bases!$B$5:$B$83,$T13) -> Guerrier | C13: =INDEX(Bases!$E$5:$E$83,$T13) -> Attaque (arme 1) | D13: =INDEX(Bases!$F$5:$F$83,$T13) -> Attaque | E13: =INDEX(Bases!$C$5:$C$83,$T13) -> Frappe rapide | F13: =INDEX(Éléments!$A$5:$A$14,$U13) -> Lumière | G13: =IF(OR($F13="Neutre",$C13="Passif"),$E13,INDEX(Bases!$D$5:$D$83,$T13)&" "&INDEX(Éléments!$D$5:$D$14,$U13)) -> Frappe rapide de lumière | H13: =INDEX(Bases!$G$5:$G$83,$T13) -> Mono | I13: =INDEX(Bases!$H$5:$H$83,$T13) -> 0 | J13: =INDEX(Bases!$I$5:$I$83,$T13) -> Non | K13: =INDEX(Bases!$J$5:$J$83,$T13) -> 1 | L13: =INDEX(Bases!$K$5:$K$83,$T13) -> Force | M13: =INDEX(Bases!$L$5:$L$83,$T13) -> Coup d'épée simple et fiable. | N13: =IF($C13="Passif","—",IF($C13="Attaque (arme 1)",INDEX(Éléments!$F$5:$F$14,$U13),INDEX(Éléments!$G$5:$G$14,$U13))) -> Soigne le lanceur de 5 % des dégâts infligés ; 25 % : Éblouissement (−20 % chance de critique, 2 tours). | O13: =INDEX(Bases!$M$5:$M$83,$T13) -> Active | P13: =INDEX(Bases!$N$5:$N$83,$T13) -> 1 | Q13: =INDEX(Éléments!$C$5:$C$14,$U13) -> 90 | R13: ="Niv. "&$P13&IF($Q13>0," · étage "&$Q13&" terminé","") -> Niv. 1 · étage 90 terminé | S13: =IF(ISNUMBER($I13),$K13*IF($H13="Zone",Paramètres!$B$8,1)/MAX(1,$I13),0) -> 1 | T13: 1 | U13: 9
A14: GUE-A01-OMB | B14: =INDEX(Bases!$B$5:$B$83,$T14) -> Guerrier | C14: =INDEX(Bases!$E$5:$E$83,$T14) -> Attaque (arme 1) | D14: =INDEX(Bases!$F$5:$F$83,$T14) -> Attaque | E14: =INDEX(Bases!$C$5:$C$83,$T14) -> Frappe rapide | F14: =INDEX(Éléments!$A$5:$A$14,$U14) -> Ombre | G14: =IF(OR($F14="Neutre",$C14="Passif"),$E14,INDEX(Bases!$D$5:$D$83,$T14)&" "&INDEX(Éléments!$D$5:$D$14,$U14)) -> Frappe rapide d'ombre | H14: =INDEX(Bases!$G$5:$G$83,$T14) -> Mono | I14: =INDEX(Bases!$H$5:$H$83,$T14) -> 0 | J14: =INDEX(Bases!$I$5:$I$83,$T14) -> Non | K14: =INDEX(Bases!$J$5:$J$83,$T14) -> 1 | L14: =INDEX(Bases!$K$5:$K$83,$T14) -> Force | M14: =INDEX(Bases!$L$5:$L$83,$T14) -> Coup d'épée simple et fiable. | N14: =IF($C14="Passif","—",IF($C14="Attaque (arme 1)",INDEX(Éléments!$F$5:$F$14,$U14),INDEX(Éléments!$G$5:$G$14,$U14))) -> Vol de vie 5 % ; 30 % : Corruption (+10 % de dégâts subis, 2 tours). | O14: =INDEX(Bases!$M$5:$M$83,$T14) -> Active | P14: =INDEX(Bases!$N$5:$N$83,$T14) -> 1 | Q14: =INDEX(Éléments!$C$5:$C$14,$U14) -> 100 | R14: ="Niv. "&$P14&IF($Q14>0," · étage "&$Q14&" terminé","") -> Niv. 1 · étage 100 terminé | S14: =IF(ISNUMBER($I14),$K14*IF($H14="Zone",Paramètres!$B$8,1)/MAX(1,$I14),0) -> 1 | T14: 1 | U14: 10
A15: GUE-A02-NEU | B15: =INDEX(Bases!$B$5:$B$83,$T15) -> Guerrier | C15: =INDEX(Bases!$E$5:$E$83,$T15) -> Attaque (arme 1) | D15: =INDEX(Bases!$F$5:$F$83,$T15) -> Attaque | E15: =INDEX(Bases!$C$5:$C$83,$T15) -> Coup d'estoc | F15: =INDEX(Éléments!$A$5:$A$14,$U15) -> Neutre | G15: =IF(OR($F15="Neutre",$C15="Passif"),$E15,INDEX(Bases!$D$5:$D$83,$T15)&" "&INDEX(Éléments!$D$5:$D$14,$U15)) -> Coup d'estoc | H15: =INDEX(Bases!$G$5:$G$83,$T15) -> Mono | I15: =INDEX(Bases!$H$5:$H$83,$T15) -> 0 | J15: =INDEX(Bases!$I$5:$I$83,$T15) -> Non | K15: =INDEX(Bases!$J$5:$J$83,$T15) -> 0.9 | L15: =INDEX(Bases!$K$5:$K$83,$T15) -> Force | M15: =INDEX(Bases!$L$5:$L$83,$T15) -> Perce la garde : ignore 20 % de l'Armure. | N15: =IF($C15="Passif","—",IF($C15="Attaque (arme 1)",INDEX(Éléments!$F$5:$F$14,$U15),INDEX(Éléments!$G$5:$G$14,$U15))) -> Aucune altération ; ignore 10 % de la Résistance de la cible. Fiable contre tous les biomes. | O15: =INDEX(Bases!$M$5:$M$83,$T15) -> Active | P15: =INDEX(Bases!$N$5:$N$83,$T15) -> 1 | Q15: =INDEX(Éléments!$C$5:$C$14,$U15) -> 0 | R15: ="Niv. "&$P15&IF($Q15>0," · étage "&$Q15&" terminé","") -> Niv. 1 | S15: =IF(ISNUMBER($I15),$K15*IF($H15="Zone",Paramètres!$B$8,1)/MAX(1,$I15),0) -> 0.9 | T15: 2 | U15: 1
A16: GUE-A02-TER | B16: =INDEX(Bases!$B$5:$B$83,$T16) -> Guerrier | C16: =INDEX(Bases!$E$5:$E$83,$T16) -> Attaque (arme 1) | D16: =INDEX(Bases!$F$5:$F$83,$T16) -> Attaque | E16: =INDEX(Bases!$C$5:$C$83,$T16) -> Coup d'estoc | F16: =INDEX(Éléments!$A$5:$A$14,$U16) -> Terre | G16: =IF(OR($F16="Neutre",$C16="Passif"),$E16,INDEX(Bases!$D$5:$D$83,$T16)&" "&INDEX(Éléments!$D$5:$D$14,$U16)) -> Estoc de pierre | H16: =INDEX(Bases!$G$5:$G$83,$T16) -> Mono | I16: =INDEX(Bases!$H$5:$H$83,$T16) -> 0 | J16: =INDEX(Bases!$I$5:$I$83,$T16) -> Non | K16: =INDEX(Bases!$J$5:$J$83,$T16) -> 0.9 | L16: =INDEX(Bases!$K$5:$K$83,$T16) -> Force | M16: =INDEX(Bases!$L$5:$L$83,$T16) -> Perce la garde : ignore 20 % de l'Armure. | N16: =IF($C16="Passif","—",IF($C16="Attaque (arme 1)",INDEX(Éléments!$F$5:$F$14,$U16),INDEX(Éléments!$G$5:$G$14,$U16))) -> 30 % : Garde brisée (−15 % Résistance, 2 tours). | O16: =INDEX(Bases!$M$5:$M$83,$T16) -> Active | P16: =INDEX(Bases!$N$5:$N$83,$T16) -> 1 | Q16: =INDEX(Éléments!$C$5:$C$14,$U16) -> 20 | R16: ="Niv. "&$P16&IF($Q16>0," · étage "&$Q16&" terminé","") -> Niv. 1 · étage 20 terminé | S16: =IF(ISNUMBER($I16),$K16*IF($H16="Zone",Paramètres!$B$8,1)/MAX(1,$I16),0) -> 0.9 | T16: 2 | U16: 2
... A488: TOU-AFF-OMB | B488: =INDEX(Bases!$B$5:$B$83,$T488) -> Toutes | C488: =INDEX(Bases!$E$5:$E$83,$T488) -> Passif | D488: =INDEX(Bases!$F$5:$F$83,$T488) -> Passif | E488: =INDEX(Bases!$C$5:$C$83,$T488) -> Affinité ténébreuse | F488: =INDEX(Éléments!$A$5:$A$14,$U488) -> Ombre | G488: =IF(OR($F488="Neutre",$C488="Passif"),$E488,INDEX(Bases!$D$5:$D$83,$T488)&" "&INDEX(Éléments!$D$5:$D$14,$U488)) -> Affinité ténébreuse | H488: =INDEX(Bases!$G$5:$G$83,$T488) -> Soi | I488: =INDEX(Bases!$H$5:$H$83,$T488) -> — | J488: =INDEX(Bases!$I$5:$I$83,$T488) -> Non | K488: =INDEX(Bases!$J$5:$J$83,$T488) -> 0 | L488: =INDEX(Bases!$K$5:$K$83,$T488) -> — | M488: =INDEX(Bases!$L$5:$L$83,$T488) -> +10 % de dégâts d'Ombre ; +3 % de vol de vie. | N488: =IF($C488="Passif","—",IF($C488="Attaque (arme 1)",INDEX(Éléments!$F$5:$F$14,$U488),INDEX(Éléments!$G$5:$G$14,$U488))) -> — | O488: =INDEX(Bases!$M$5:$M$83,$T488) -> Permanent | P488: =INDEX(Bases!$N$5:$N$83,$T488) -> 1 | Q488: =INDEX(Éléments!$C$5:$C$14,$U488) -> 100 | R488: ="Niv. "&$P488&IF($Q488>0," · étage "&$Q488&" terminé","") -> Niv. 1 · étage 100 terminé | S488: =IF(ISNUMBER($I488),$K488*IF($H488="Zone",Paramètres!$B$8,1)/MAX(1,$I488),0) -> 0 | T488: 79 | U488: 10
A490: « Puissance par tour (vague) » = puissance × ennemis touchés (3 pour une zone) ÷ recharge : sert à comparer une compétence à 1 tour et une ultime à 3 tours.

Sheet Bases
A1: Compétences de base (version Neutre)
A2: La version de départ de chaque compétence. Le Catalogue en tire les 10 variantes élémentaires. Modifiez ici : tout le classeur suit.
A4: ID | B4: Classe | C4: Nom (Neutre) | D4: Racine des variantes | E4: Famille | F4: Type | G4: Cible | H4: Recharge (tours) | I4: Ultime | J4: Puissance (× stat) | K4: Stat | L4: Effet de base | M4: Déclenchement | N4: Niveau requis | O4: Valeur d'effet (équiv. puissance) | P4: Score de recharge
A5: GUE-A01 | B5: Guerrier | C5: Frappe rapide | D5: Frappe rapide | E5: Attaque (arme 1) | F5: Attaque | G5: Mono | H5: =IF($F5="Passif","—",IF($N5<=Paramètres!$B$19,0,IF($I5="Oui",3,IF($P5<=Paramètres!$B$14,1,IF($P5<=Paramètres!$B$15,2,3))))) -> 0 | I5: Non | J5: 1 | K5: Force | L5: Coup d'épée simple et fiable. | M5: Active | N5: 1 | O5: 0 | P5: =ROUND($J5*IF($G5="Zone",Paramètres!$B$13,1)+$O5,2) -> 1
A6: GUE-A02 | B6: Guerrier | C6: Coup d'estoc | D6: Estoc | E6: Attaque (arme 1) | F6: Attaque | G6: Mono | H6: =IF($F6="Passif","—",IF($N6<=Paramètres!$B$19,0,IF($I6="Oui",3,IF($P6<=Paramètres!$B$14,1,IF($P6<=Paramètres!$B$15,2,3))))) -> 0 | I6: Non | J6: 0.9 | K6: Force | L6: Perce la garde : ignore 20 % de l'Armure. | M6: Active | N6: 1 | O6: 0.2 | P6: =ROUND($J6*IF($G6="Zone",Paramètres!$B$13,1)+$O6,2) -> 1.1
A7: GUE-A03 | B7: Guerrier | C7: Coup vertical | D7: Coup vertical | E7: Attaque (arme 1) | F7: Attaque | G7: Mono | H7: =IF($F7="Passif","—",IF($N7<=Paramètres!$B$19,0,IF($I7="Oui",3,IF($P7<=Paramètres!$B$14,1,IF($P7<=Paramètres!$B$15,2,3))))) -> 2 | I7: Non | J7: 1.6 | K7: Force | L7: 15 % : Assommé (la cible perd 1 tour). | M7: Active | N7: 8 | O7: 0.3 | P7: =ROUND($J7*IF($G7="Zone",Paramètres!$B$13,1)+$O7,2) -> 1.9
A8: GUE-A04 | B8: Guerrier | C8: Tourbillon | D8: Tourbillon | E8: Attaque (arme 1) | F8: Attaque | G8: Zone | H8: =IF($F8="Passif","—",IF($N8<=Paramètres!$B$19,0,IF($I8="Oui",3,IF($P8<=Paramètres!$B$14,1,IF($P8<=Paramètres!$B$15,2,3))))) -> 2 | I8: Non | J8: 0.85 | K8: Force | L8: Frappe tous les ennemis de la vague. | M8: Active | N8: 12 | O8: 0 | P8: =ROUND($J8*IF($G8="Zone",Paramètres!$B$13,1)+$O8,2) -> 1.7
A9: GUE-A05 | B9: Guerrier | C9: Entaille | D9: Entaille | E9: Attaque (arme 1) | F9: Attaque | G9: Mono | H9: =IF($F9="Passif","—",IF($N9<=Paramètres!$B$19,0,IF($I9="Oui",3,IF($P9<=Paramètres!$B$14,1,IF($P9<=Paramètres!$B$15,2,3))))) -> 1 | I9: Non | J9: 0.85 | K9: Force | L9: 35 % : Saignement (5 % de la Force par tour, 3 tours). | M9: Active | N9: 18 | O9: 0.15 | P9: =ROUND($J9*IF($G9="Zone",Paramètres!$B$13,1)+$O9,2) -> 1
A10: GUE-A06 | B10: Guerrier | C10: Charge | D10: Charge | E10: Attaque (arme 1) | F10: Attaque | G10: Mono | H10: =IF($F10="Passif","—",IF($N10<=Paramètres!$B$19,0,IF($I10="Oui",3,IF($P10<=Paramètres!$B$14,1,IF($P10<=Paramètres!$B$15,2,3))))) -> 2 | I10: Non | J10: 1.5 | K10: Force | L10: Intimide la cible (−10 % de dégâts infligés, 2 tours). | M10: Active | N10: 25 | O10: 0.3 | P10: =ROUND($J10*IF($G10="Zone",Paramètres!$B$13,1)+$O10,2) -> 1.8
A11: GUE-A07 | B11: Guerrier | C11: Exécution | D11: Exécution | E11: Attaque (arme 1) | F11: Attaque | G11: Mono | H11: =IF($F11="Passif","—",IF($N11<=Paramètres!$B$19,0,IF($I11="Oui",3,IF($P11<=Paramètres!$B$14,1,IF($P11<=Paramètres!$B$15,2,3))))) -> 3 | I11: Oui | J11: 3 | K11: Force | L11: +50 % de dégâts si la cible a moins de 30 % de ses PV. | M11: Active | N11: 30 | O11: 0.3 | P11: =ROUND($J11*IF($G11="Zone",Paramètres!$B$13,1)+$O11,2) -> 3.3
A12: GUE-A08 | B12: Guerrier | C12: Onde de choc | D12: Onde de choc | E12: Attaque (arme 1) | F12: Attaque | G12: Zone | H12: =IF($F12="Passif","—",IF($N12<=Paramètres!$B$19,0,IF($I12="Oui",3,IF($P12<=Paramètres!$B$14,1,IF($P12<=Paramètres!$B$15,2,3))))) -> 3 | I12: Oui | J12: 1.6 | K12: Force | L12: Frappe toute la vague ; 20 % : Assommé. | M12: Active | N12: 60 | O12: 0.4 | P12: =ROUND($J12*IF($G12="Zone",Paramètres!$B$13,1)+$O12,2) -> 3.6
A13: GUE-S01 | B13: Guerrier | C13: Garde | D13: Garde | E13: Soutien (arme 2) | F13: Buff | G13: Soi | H13: =IF($F13="Passif","—",IF($N13<=Paramètres!$B$19,0,IF($I13="Oui",3,IF($P13<=Paramètres!$B$14,1,IF($P13<=Paramètres!$B$15,2,3))))) -> 2 | I13: Non | J13: 0 | K13: Force | L13: +30 % de Résistance pendant 2 tours. | M13: Active | N13: 5 | O13: 1.5 | P13: =ROUND($J13*IF($G13="Zone",Paramètres!$B$13,1)+$O13,2) -> 1.5
A14: GUE-S02 | B14: Guerrier | C14: Coup de bouclier | D14: Coup de bouclier | E14: Soutien (arme 2) | F14: Debuff | G14: Mono | H14: =IF($F14="Passif","—",IF($N14<=Paramètres!$B$19,0,IF($I14="Oui",3,IF($P14<=Paramètres!$B$14,1,IF($P14<=Paramètres!$B$15,2,3))))) -> 2 | I14: Non | J14: 0.6 | K14: Force | L14: 25 % : Assommé (1 tour). | M14: Active | N14: 10 | O14: 0.6 | P14: =ROUND($J14*IF($G14="Zone",Paramètres!$B$13,1)+$O14,2) -> 1.2
A15: GUE-S03 | B15: Guerrier | C15: Cri de guerre | D15: Cri | E15: Soutien (arme 2) | F15: Buff | G15: Soi | H15: =IF($F15="Passif","—",IF($N15<=Paramètres!$B$19,0,IF($I15="Oui",3,IF($P15<=Paramètres!$B$14,1,IF($P15<=Paramètres!$B$15,2,3))))) -> 2 | I15: Non | J15: 0 | K15: Force | L15: +20 % de Force pendant 2 tours. | M15: Active | N15: 15 | O15: 1.5 | P15: =ROUND($J15*IF($G15="Zone",Paramètres!$B$13,1)+$O15,2) -> 1.5
A16: GUE-S04 | B16: Guerrier | C16: Mur de boucliers | D16: Rempart | E16: Soutien (arme 2) | F16: Bouclier | G16: Soi | H16: =IF($F16="Passif","—",IF($N16<=Paramètres!$B$19,0,IF($I16="Oui",3,IF($P16<=Paramètres!$B$14,1,IF($P16<=Paramètres!$B$15,2,3))))) -> 2 | I16: Non | J16: 0 | K16: Force | L16: Bouclier = 15 % des PV max pendant 2 tours, en plus des PV (Vitalité). | M16: Active | N16: 20 | O16: 1.6 | P16: =ROUND($J16*IF($G16="Zone",Paramètres!$B$13,1)+$O16,2) -> 1.6
... A19: GUE-S07 | B19: Guerrier | C19: Forteresse | D19: Forteresse | E19: Soutien (arme 2) | F19: Bouclier | G19: Soi | H19: =IF($F19="Passif","—",IF($N19<=Paramètres!$B$19,0,IF($I19="Oui",3,IF($P19<=Paramètres!$B$14,1,IF($P19<=Paramètres!$B$15,2,3))))) -> 3 | I19: Oui | J19: 0 | K19: Force | L19: Bouclier = 30 % des PV max + immunité aux contrôles pendant 2 tours. | M19: Active | N19: 50 | O19: 2.5 | P19: =ROUND($J19*IF($G19="Zone",Paramètres!$B$13,1)+$O19,2) -> 2.5
A20: GUE-P01 | B20: Guerrier | C20: Peau dure | D20: — | E20: Passif | F20: Passif | G20: Soi | H20: — | I20: Non | J20: 0 | K20: — | L20: +8 % de Résistance. | M20: Permanent | N20: 1 | O20: — | P20: —
A21: GUE-P02 | B21: Guerrier | C21: Soif de sang | D21: — | E21: Passif | F21: Passif | G21: Soi | H21: — | I21: Non | J21: 0 | K21: — | L21: Vol de vie : 5 % des dégâts infligés. | M21: Permanent | N21: 10 | O21: — | P21: —
A22: GUE-P03 | B22: Guerrier | C22: Contre-attaque | D22: — | E22: Passif | F22: Passif | G22: Soi | H22: — | I22: Non | J22: 0 | K22: — | L22: 15 % de riposter quand il est touché (50 % de la Force). | M22: Quand il est touché | N22: 20 | O22: — | P22: —
A23: GUE-P04 | B23: Guerrier | C23: Rage | D23: — | E23: Passif | F23: Passif | G23: Soi | H23: — | I23: Non | J23: 0 | K23: — | L23: +2 % de dégâts par tranche de 10 % de PV perdus (max +15 %). | M23: Permanent | N23: 30 | O23: — | P23: —
A24: GUE-P05 | B24: Guerrier | C24: Briseur de garde | D24: — | E24: Passif | F24: Passif | G24: Soi | H24: — | I24: Non | J24: 0 | K24: — | L24: Chaque coup vole 2 % de la Résistance de la cible (5 piles max). | M24: À chaque coup | N24: 40 | O24: — | P24: —
A25: GUE-P06 | B25: Guerrier | C25: Bouclier réflexe | D25: — | E25: Passif | F25: Passif | G25: Soi | H25: — | I25: Non | J25: 0 | K25: — | L25: Bouclier de 8 % des PV max. | M25: Tous les 3 tours | N25: 50 | O25: — | P25: —
A26: GUE-P07 | B26: Guerrier | C26: Maître d'armes | D26: — | E26: Passif | F26: Passif | G26: Soi | H26: — | I26: Non | J26: 0 | K26: — | L26: +5 % de Pénétration et +5 % de dégâts critiques. | M26: Permanent | N26: 60 | O26: — | P26: —
A27: GUE-P08 | B27: Guerrier | C27: Endurance du vétéran | D27: — | E27: Passif | F27: Passif | G27: Soi | H27: — | I27: Non | J27: 0 | K27: — | L27: Rend 3 % des PV max. | M27: Chaque tour | N27: 70 | O27: — | P27: —
A28: MAG-A01 | B28: Mage | C28: Boule arcanique | D28: Boule | E28: Attaque (arme 1) | F28: Attaque | G28: Mono | H28: =IF($F28="Passif","—",IF($N28<=Paramètres!$B$19,0,IF($I28="Oui",3,IF($P28<=Paramètres!$B$14,1,IF($P28<=Paramètres!$B$15,2,3))))) -> 0 | I28: Non | J28: 1 | K28: Magie | L28: Projectile magique fiable. | M28: Active | N28: 1 | O28: 0 | P28: =ROUND($J28*IF($G28="Zone",Paramètres!$B$13,1)+$O28,2) -> 1
A29: MAG-A02 | B29: Mage | C29: Lance arcanique | D29: Lance | E29: Attaque (arme 1) | F29: Attaque | G29: Mono | H29: =IF($F29="Passif","—",IF($N29<=Paramètres!$B$19,0,IF($I29="Oui",3,IF($P29<=Paramètres!$B$14,1,IF($P29<=Paramètres!$B$15,2,3))))) -> 0 | I29: Non | J29: 0.9 | K29: Magie | L29: Ignore 15 % de la Résistance. | M29: Active | N29: 1 | O29: 0.15 | P29: =ROUND($J29*IF($G29="Zone",Paramètres!$B$13,1)+$O29,2) -> 1.05
A30: MAG-A03 | B30: Mage | C30: Tornade arcanique | D30: Tornade | E30: Attaque (arme 1) | F30: Attaque | G30: Zone | H30: =IF($F30="Passif","—",IF($N30<=Paramètres!$B$19,0,IF($I30="Oui",3,IF($P30<=Paramètres!$B$14,1,IF($P30<=Paramètres!$B$15,2,3))))) -> 2 | I30: Non | J30: 0.85 | K30: Magie | L30: Frappe tous les ennemis de la vague. | M30: Active | N30: 8 | O30: 0 | P30: =ROUND($J30*IF($G30="Zone",Paramètres!$B$13,1)+$O30,2) -> 1.7
A31: MAG-A04 | B31: Mage | C31: Rayon arcanique | D31: Rayon | E31: Attaque (arme 1) | F31: Attaque | G31: Mono | H31: =IF($F31="Passif","—",IF($N31<=Paramètres!$B$19,0,IF($I31="Oui",3,IF($P31<=Paramètres!$B$14,1,IF($P31<=Paramètres!$B$15,2,3))))) -> 1 | I31: Non | J31: 0.8 | K31: Magie | L31: Deux impacts (2 × 40 %) : deux chances d'appliquer l'effet élémentaire. | M31: Active | N31: 12 | O31: 0.2 | P31: =ROUND($J31*IF($G31="Zone",Paramètres!$B$13,1)+$O31,2) -> 1
A32: MAG-A05 | B32: Mage | C32: Pluie arcanique | D32: Pluie | E32: Attaque (arme 1) | F32: Attaque | G32: Zone | H32: =IF($F32="Passif","—",IF($N32<=Paramètres!$B$19,0,IF($I32="Oui",3,IF($P32<=Paramètres!$B$14,1,IF($P32<=Paramètres!$B$15,2,3))))) -> 2 | I32: Non | J32: 0.7 | K32: Magie | L32: Frappe toute la vague ; +50 % de chance d'appliquer l'effet élémentaire. | M32: Active | N32: 18 | O32: 0.3 | P32: =ROUND($J32*IF($G32="Zone",Paramètres!$B$13,1)+$O32,2) -> 1.7
A33: MAG-A06 | B33: Mage | C33: Nova arcanique | D33: Nova | E33: Attaque (arme 1) | F33: Attaque | G33: Zone | H33: =IF($F33="Passif","—",IF($N33<=Paramètres!$B$19,0,IF($I33="Oui",3,IF($P33<=Paramètres!$B$14,1,IF($P33<=Paramètres!$B$15,2,3))))) -> 2 | I33: Non | J33: 0.95 | K33: Magie | L33: Frappe toute la vague ; les ennemis touchés infligent −10 % de dégâts (1 tour). | M33: Active | N33: 25 | O33: 0.3 | P33: =ROUND($J33*IF($G33="Zone",Paramètres!$B$13,1)+$O33,2) -> 2.2
A34: MAG-A07 | B34: Mage | C34: Météore | D34: Météore | E34: Attaque (arme 1) | F34: Attaque | G34: Zone | H34: =IF($F34="Passif","—",IF($N34<=Paramètres!$B$19,0,IF($I34="Oui",3,IF($P34<=Paramètres!$B$14,1,IF($P34<=Paramètres!$B$15,2,3))))) -> 3 | I34: Oui | J34: 1.6 | K34: Magie | L34: Frappe toute la vague ; l'effet élémentaire est garanti sur la cible principale. | M34: Active | N34: 30 | O34: 0.3 | P34: =ROUND($J34*IF($G34="Zone",Paramètres!$B$13,1)+$O34,2) -> 3.5
A35: MAG-A08 | B35: Mage | C35: Explosion arcanique | D35: Explosion | E35: Attaque (arme 1) | F35: Attaque | G35: Mono | H35: =IF($F35="Passif","—",IF($N35<=Paramètres!$B$19,0,IF($I35="Oui",3,IF($P35<=Paramètres!$B$14,1,IF($P35<=Paramètres!$B$15,2,3))))) -> 3 | I35: Oui | J35: 3 | K35: Magie | L35: +25 % de dégâts si la cible porte une altération. | M35: Active | N35: 60 | O35: 0.2 | P35: =ROUND($J35*IF($G35="Zone",Paramètres!$B$13,1)+$O35,2) -> 3.2
A36: MAG-S01 | B36: Mage | C36: Barrière | D36: Barrière | E36: Soutien (arme 2) | F36: Bouclier | G36: Soi | H36: =IF($F36="Passif","—",IF($N36<=Paramètres!$B$19,0,IF($I36="Oui",3,IF($P36<=Paramètres!$B$14,1,IF($P36<=Paramètres!$B$15,2,3))))) -> 2 | I36: Non | J36: 0 | K36: Magie | L36: Bouclier = 12 % des PV max pendant 2 tours. | M36: Active | N36: 5 | O36: 1.4 | P36: =ROUND($J36*IF($G36="Zone",Paramètres!$B$13,1)+$O36,2) -> 1.4
A37: MAG-S02 | B37: Mage | C37: Soin | D37: Soin | E37: Soutien (arme 2) | F37: Soin | G37: Soi | H37: =IF($F37="Passif","—",IF($N37<=Paramètres!$B$19,0,IF($I37="Oui",3,IF($P37<=Paramètres!$B$14,1,IF($P37<=Paramètres!$B$15,2,3))))) -> 2 | I37: Non | J37: 0 | K37: Magie | L37: Soigne 18 % des PV max (augmenté par le Bonus de soins). | M37: Active | N37: 10 | O37: 1.8 | P37: =ROUND($J37*IF($G37="Zone",Paramètres!$B$13,1)+$O37,2) -> 1.8
A38: MAG-S03 | B38: Mage | C38: Amplification | D38: Amplification | E38: Soutien (arme 2) | F38: Buff | G38: Soi | H38: =IF($F38="Passif","—",IF($N38<=Paramètres!$B$19,0,IF($I38="Oui",3,IF($P38<=Paramètres!$B$14,1,IF($P38<=Paramètres!$B$15,2,3))))) -> 2 | I38: Non | J38: 0 | K38: Magie | L38: +25 % de Magie pendant 2 tours. | M38: Active | N38: 15 | O38: 1.6 | P38: =ROUND($J38*IF($G38="Zone",Paramètres!$B$13,1)+$O38,2) -> 1.6
A39: MAG-S04 | B39: Mage | C39: Malédiction | D39: Malédiction | E39: Soutien (arme 2) | F39: Debuff | G39: Mono | H39: =IF($F39="Passif","—",IF($N39<=Paramètres!$B$19,0,IF($I39="Oui",3,IF($P39<=Paramètres!$B$14,1,IF($P39<=Paramètres!$B$15,2,3))))) -> 2 | I39: Non | J39: 0 | K39: Magie | L39: La cible inflige −15 % de dégâts pendant 2 tours. | M39: Active | N39: 20 | O39: 1.5 | P39: =ROUND($J39*IF($G39="Zone",Paramètres!$B$13,1)+$O39,2) -> 1.5
... A42: MAG-S07 | B42: Mage | C42: Sanctuaire | D42: Sanctuaire | E42: Soutien (arme 2) | F42: Soin | G42: Soi | H42: =IF($F42="Passif","—",IF($N42<=Paramètres!$B$19,0,IF($I42="Oui",3,IF($P42<=Paramètres!$B$14,1,IF($P42<=Paramètres!$B$15,2,3))))) -> 3 | I42: Oui | J42: 0 | K42: Magie | L42: Soigne 30 % des PV max + bouclier de 15 % des PV max. | M42: Active | N42: 50 | O42: 2.5 | P42: =ROUND($J42*IF($G42="Zone",Paramètres!$B$13,1)+$O42,2) -> 2.5
A43: MAG-P01 | B43: Mage | C43: Concentration arcanique | D43: — | E43: Passif | F43: Passif | G43: Soi | H43: — | I43: Non | J43: 0 | K43: — | L43: +8 % de Magie. | M43: Permanent | N43: 1 | O43: — | P43: —
A44: MAG-P02 | B44: Mage | C44: Siphon | D44: — | E44: Passif | F44: Passif | G44: Soi | H44: — | I44: Non | J44: 0 | K44: — | L44: Vol de vie : 4 % des dégâts magiques. | M44: Permanent | N44: 10 | O44: — | P44: —
A45: MAG-P03 | B45: Mage | C45: Écho | D45: — | E45: Passif | F45: Passif | G45: Soi | H45: — | I45: Non | J45: 0 | K45: — | L45: 15 % qu'un sort à recharge 1 frappe une seconde fois (50 %). | M45: À chaque sort | N45: 20 | O45: — | P45: —
...

Sheet Éléments
A1: Éléments : déblocage et effets ajoutés aux compétences
A2: Chaque compétence active existe dans les 10 éléments. L'élément se débloque quand on termine le dernier étage de son biome (Feu : étage 30 terminé).
A4: Élément | B4: Biome | C4: Étage à terminer | D4: Nom des variantes | E4: Altération | F4: Effet ajouté aux attaques | G4: Effet ajouté aux soutiens (buff, soin, bouclier, debuff) | H4: Passif d’affinité | K4: Liste (aide)
A5: Neutre | B5: Forêt | C5: 0 | D5: (nom de base) | E5: Aucune | F5: Aucune altération ; ignore 10 % de la Résistance de la cible. Fiable contre tous les biomes. | G5: Aucun bonus élémentaire : effet de base seul. | H5: Maîtrise arcanique | K5: —
A6: Terre | B6: Montagne | C6: 20 | D6: de pierre | E6: Garde brisée | F6: 30 % : Garde brisée (−15 % Résistance, 2 tours). | G6: +15 % d'Armure pendant la durée de l'effet. | H6: Affinité tellurique | K6: Neutre
A7: Feu | B7: Volcan | C7: 30 | D7: de feu | E7: Brûlure | F7: 35 % : Brûlure (8 % de la stat d'attaque par tour, 3 tours, non cumulable). | G7: Les ennemis qui frappent le lanceur ont 40 % de subir Brûlure (pendant la durée). | H7: Affinité ardente | K7: Terre
A8: Vent | B8: Désert | C8: 40 | D8: de vent | E8: Désorienté | F8: +10 % de chance de critique ; 30 % : Désorienté (−15 % Précision, 2 tours). | G8: +10 % d'Agilité (esquive) pendant la durée de l'effet. | H8: Affinité des vents | K8: Feu
A9: Acide | B9: Marais | C9: 50 | D9: d'acide | E9: Corrosion | F9: 50 % : 1 pile de Corrosion (−5 % Armure par pile, 4 piles max, 3 tours). | G9: Les ennemis qui frappent le lanceur prennent 1 pile de Corrosion (40 %). | H9: Affinité corrosive | K9: Vent
A10: Eau | B10: Océan / Île | C10: 60 | D10: d'eau | E10: Mouillé | F10: 50 % : Mouillé (+25 % de dégâts d'Électricité subis, retire Brûlure, 3 tours). | G10: Soin supplémentaire de 4 % des PV max ; retire Brûlure du lanceur. | H10: Affinité des marées | K10: Acide
A11: Glace | B11: Iceberg | C11: 70 | D11: de glace | E11: Froid / Gel | F11: 40 % : 1 pile de Froid (−8 % Agilité ; à 3 piles : Gel, la cible perd 1 tour). | G11: Les ennemis qui frappent le lanceur prennent 1 pile de Froid (40 %). | H11: Affinité glaciale | K11: Eau
A12: Électricité | B12: Haute montagne | C12: 80 | D12: de foudre | E12: Étourdissement | F12: Rebondit sur 1 autre ennemi (40 % des dégâts) ; 10 % : Étourdissement (1 tour). | G12: La prochaine attaque du lanceur inflige +15 % de dégâts. | H12: Affinité orageuse | K12: Glace
A13: Lumière | B13: Palais céleste | C13: 90 | D13: de lumière | E13: Éblouissement | F13: Soigne le lanceur de 5 % des dégâts infligés ; 25 % : Éblouissement (−20 % chance de critique, 2 tours). | G13: +20 % sur les soins et boucliers de la compétence. | H13: Affinité solaire | K13: Électricité
A14: Ombre | B14: Palais démoniaque | C14: 100 | D14: d'ombre | E14: Corruption | F14: Vol de vie 5 % ; 30 % : Corruption (+10 % de dégâts subis, 2 tours). | G14: Les ennemis qui frappent le lanceur subissent Corruption (25 %). | H14: Affinité ténébreuse | K14: Lumière
A15: Neutre = compétences de départ (nom de base). Étage à terminer : 20 = battre l'étage 20 (fin de la Montagne). Ombre se débloque en finissant la tour (étage 100). | K15: Ombre
A17: Multiplicateurs élémentaires (défenseur en ligne, attaquant en colonne) — copie du fichier Éléments/Fusions
A18: Défenseur ↓ / Attaquant → | B18: Feu | C18: Électricité | D18: Acide | E18: Glace | F18: Eau | G18: Vent | H18: Terre | I18: Ombre | J18: Lumière | K18: Neutre
A19: Feu | B19: 1 | C19: 1 | D19: 1 | E19: 0.75 | F19: 1.5 | G19: 1 | H19: 1 | I19: 1 | J19: 1 | K19: 1
A20: Électricité | B20: 1 | C20: 1 | D20: 1 | E20: 1 | F20: 0.75 | G20: 1 | H20: 1.5 | I20: 1 | J20: 1 | K20: 1
A21: Acide | B21: 1 | C21: 1 | D21: 1 | E21: 1 | F21: 1 | G21: 1 | H21: 0.75 | I21: 1 | J21: 0.75 | K21: 1
A22: Glace | B22: 1.5 | C22: 1 | D22: 1 | E22: 1 | F22: 1 | G22: 0.75 | H22: 1 | I22: 1 | J22: 1 | K22: 1
A23: Eau | B23: 0.75 | C23: 1.5 | D23: 1 | E23: 1 | F23: 1 | G23: 1 | H23: 1 | I23: 1 | J23: 1 | K23: 1
A24: Vent | B24: 1 | C24: 1 | D24: 1 | E24: 1.5 | F24: 1 | G24: 1 | H24: 0.75 | I24: 1 | J24: 1 | K24: 1
A25: Terre | B25: 1 | C25: 0.75 | D25: 1.5 | E25: 1 | F25: 1 | G25: 1.5 | H25: 1 | I25: 1 | J25: 1 | K25: 1
A26: Ombre | B26: 1 | C26: 1 | D26: 1 | E26: 1 | F26: 1 | G26: 1 | H26: 1 | I26: 1 | J26: 1.5 | K26: 1
A27: Lumière | B27: 1 | C27: 1 | D27: 0.75 | E27: 1 | F27: 1 | G27: 1 | H27: 1 | I27: 1.5 | J27: 1 | K27: 1
A28: Neutre | B28: 1 | C28: 1 | D28: 1 | E28: 1 | F28: 1 | G28: 1 | H28: 1 | I28: 1 | J28: 1 | K28: 1
A29: ×1,5 : l'attaquant a l'avantage ; ×0,75 : le défenseur résiste. Pour une fusion, c'est l'élément principal (le 1er) qui compte (règle du fichier Éléments/Fusions).

Sheet Fusions
A1: Fusions : compétences infusées de deux éléments
A2: N'importe quelle compétence active peut porter une fusion (ex. Boule + Feu + Électricité = Boule de plasma). L'élément 1 compte pour l'avantage, la fusion remplace les effets simples.
A4: Élément 1 | B4: Élément 2 | C4: Fusion | D4: Effet en combat (tour par tour) | E4: Idée d’origine (fichier Éléments/Fusions) | F4: Rôle | G4: Disponible après l’étage | H4: Exemple Guerrier | I4: Exemple Mage | J4: Exemple Tireur | K4: (aide) clé 1 | L4: (aide) clé 2
A5: Feu | B5: Feu | C5: Brasier | D5: Brûlure renforcée (12 % / tour au lieu de 8 %) ; si la cible meurt en brûlant, la Brûlure passe à un autre ennemi. | E5: Brûlure renforcée ; peut se propager aux ennemis proches. | F5: Dégâts / propagation | G5: =MAX(INDEX(Éléments!$C$5:$C$14,MATCH(A5,Éléments!$A$5:$A$14,0)),INDEX(Éléments!$C$5:$C$14,MATCH(B5,Éléments!$A$5:$A$14,0)),Paramètres!$B$11) -> 85 | H5: Estoc de brasier | I5: Boule de brasier | J5: Tir précis de brasier | K5: =A5&"|"&B5 -> Feu|Feu | L5: =B5&"|"&A5 -> Feu|Feu
A6: Feu | B6: Électricité | C6: Plasma | D6: Rebondit sur 1 ennemi (50 % des dégâts) ; chaque cible touchée a 35 % de subir Brûlure. | E6: Éclairs surchauffés qui rebondissent et appliquent une brûlure. | F6: Dégâts / chaîne | G6: =MAX(INDEX(Éléments!$C$5:$C$14,MATCH(A6,Éléments!$A$5:$A$14,0)),INDEX(Éléments!$C$5:$C$14,MATCH(B6,Éléments!$A$5:$A$14,0)),Paramètres!$B$11) -> 85 | H6: Estoc de plasma | I6: Boule de plasma | J6: Tir précis de plasma | K6: =A6&"|"&B6 -> Feu|Électricité | L6: =B6&"|"&A6 -> Électricité|Feu
A7: Feu | B7: Acide | C7: Brimstone | D7: Si la cible a 2 piles de Corrosion ou plus : explosion de 40 % des dégâts sur les autres ennemis (les piles sont consommées). | E7: Les cibles corrodées explosent et infligent des dégâts de zone. | F7: Explosion / anti-armure | G7: =MAX(INDEX(Éléments!$C$5:$C$14,MATCH(A7,Éléments!$A$5:$A$14,0)),INDEX(Éléments!$C$5:$C$14,MATCH(B7,Éléments!$A$5:$A$14,0)),Paramètres!$B$11) -> 85 | H7: Estoc de brimstone | I7: Boule de brimstone | J7: Tir précis de brimstone | K7: =A7&"|"&B7 -> Feu|Acide | L7: =B7&"|"&A7 -> Acide|Feu
A8: Feu | B8: Glace | C8: Cryopyre | D8: Contre une cible avec Froid ou Gel : consomme les piles, +20 % de dégâts par pile consommée. | E8: Choc thermique ; consomme une partie du gel pour infliger un burst. | F8: Burst / anti-contrôle | G8: =MAX(INDEX(Éléments!$C$5:$C$14,MATCH(A8,Éléments!$A$5:$A$14,0)),INDEX(Éléments!$C$5:$C$14,MATCH(B8,Éléments!$A$5:$A$14,0)),Paramètres!$B$11) -> 85 | H8: Estoc de cryopyre | I8: Boule de cryopyre | J8: Tir précis de cryopyre | K8: =A8&"|"&B8 -> Feu|Glace | L8: =B8&"|"&A8 -> Glace|Feu
A9: Feu | B9: Eau | C9: Vapeur | D9: Nuage de vapeur 2 tours : tous les ennemis subissent 5 % de la stat d'attaque par tour et −10 % de Précision. | E9: Nuage brûlant qui inflige des dégâts et gêne la visibilité. | F9: Zone persistante | G9: =MAX(INDEX(Éléments!$C$5:$C$14,MATCH(A9,Éléments!$A$5:$A$14,0)),INDEX(Éléments!$C$5:$C$14,MATCH(B9,Éléments!$A$5:$A$14,0)),Paramètres!$B$11) -> 85 | H9: Estoc de vapeur | I9: Boule de vapeur | J9: Tir précis de vapeur | K9: =A9&"|"&B9 -> Feu|Eau | L9: =B9&"|"&A9 -> Eau|Feu
A10: Feu | B10: Vent | C10: Feu follet | D10: La Brûlure est aussi appliquée à 1 ennemi supplémentaire au hasard. | E10: Les flammes sont poussées dans une direction et se propagent plus loin. | F10: Propagation / zone | G10: =MAX(INDEX(Éléments!$C$5:$C$14,MATCH(A10,Éléments!$A$5:$A$14,0)),INDEX(Éléments!$C$5:$C$14,MATCH(B10,Éléments!$A$5:$A$14,0)),Paramètres!$B$11) -> 85 | H10: Estoc de feu follet | I10: Boule de feu follet | J10: Tir précis de feu follet | K10: =A10&"|"&B10 -> Feu|Vent | L10: =B10&"|"&A10 -> Vent|Feu
A11: Feu | B11: Terre | C11: Magma | D11: Lave 2 tours : chaque ennemi qui attaque subit 6 % de la stat d'attaque ; 25 % : Garde brisée. | E11: Crée des flaques de lave qui infligent des dégâts au passage. | F11: Zone persistante | G11: =MAX(INDEX(Éléments!$C$5:$C$14,MATCH(A11,Éléments!$A$5:$A$14,0)),INDEX(Éléments!$C$5:$C$14,MATCH(B11,Éléments!$A$5:$A$14,0)),Paramètres!$B$11) -> 85 | H11: Estoc de magma | I11: Boule de magma | J11: Tir précis de magma | K11: =A11&"|"&B11 -> Feu|Terre | L11: =B11&"|"&A11 -> Terre|Feu
A12: Feu | B12: Ombre | C12: Feu maudit | D12: Brûlure + Corruption ; un ennemi brûlé qui meurt transmet la Corruption à un autre ennemi. | E12: Les ennemis brûlés transmettent une malédiction à leur mort. | F12: Propagation / malédiction | G12: =MAX(INDEX(Éléments!$C$5:$C$14,MATCH(A12,Éléments!$A$5:$A$14,0)),INDEX(Éléments!$C$5:$C$14,MATCH(B12,Éléments!$A$5:$A$14,0)),Paramètres!$B$11) -> 100 | H12: Estoc de feu maudit | I12: Boule de feu maudit | J12: Tir précis de feu maudit | K12: =A12&"|"&B12 -> Feu|Ombre | L12: =B12&"|"&A12 -> Ombre|Feu
A13: Feu | B13: Lumière | C13: Feu solaire | D13: +15 % de dégâts ; dissipe 1 effet positif de la cible. | E13: Explosion lumineuse qui brûle et dissipe les effets d’ombre. | F13: Burst / purification | G13: =MAX(INDEX(Éléments!$C$5:$C$14,MATCH(A13,Éléments!$A$5:$A$14,0)),INDEX(Éléments!$C$5:$C$14,MATCH(B13,Éléments!$A$5:$A$14,0)),Paramètres!$B$11) -> 90 | H13: Estoc de feu solaire | I13: Boule de feu solaire | J13: Tir précis de feu solaire | K13: =A13&"|"&B13 -> Feu|Lumière | L13: =B13&"|"&A13 -> Lumière|Feu
A14: Feu | B14: Neutre | C14: Flamme arcanique | D14: 35 % : Brûlure ; ignore 15 % de la Résistance. | E14: Flamme concentrée qui ignore une petite partie des résistances. | F14: Dégâts fiables | G14: =MAX(INDEX(Éléments!$C$5:$C$14,MATCH(A14,Éléments!$A$5:$A$14,0)),INDEX(Éléments!$C$5:$C$14,MATCH(B14,Éléments!$A$5:$A$14,0)),Paramètres!$B$11) -> 85 | H14: Estoc de flamme arcanique | I14: Boule de flamme arcanique | J14: Tir précis de flamme arcanique | K14: =A14&"|"&B14 -> Feu|Neutre | L14: =B14&"|"&A14 -> Neutre|Feu
A15: Électricité | B15: Électricité | C15: Foudre | D15: Étourdissement 20 % (au lieu de 10 %) ; +10 % de chance de critique. | E15: Impact électrique puissant avec chance d’étourdissement. | F15: Burst / contrôle | G15: =MAX(INDEX(Éléments!$C$5:$C$14,MATCH(A15,Éléments!$A$5:$A$14,0)),INDEX(Éléments!$C$5:$C$14,MATCH(B15,Éléments!$A$5:$A$14,0)),Paramètres!$B$11) -> 85 | H15: Estoc de foudre | I15: Boule de foudre | J15: Tir précis de foudre | K15: =A15&"|"&B15 -> Électricité|Électricité | L15: =B15&"|"&A15 -> Électricité|Électricité
A16: Électricité | B16: Acide | C16: Flux corrosif | D16: Rebondit sur 1 ennemi ; chaque cible touchée prend 1 pile de Corrosion. | E16: Les arcs électriques rebondissent et appliquent la corrosion. | F16: Chaîne / anti-armure | G16: =MAX(INDEX(Éléments!$C$5:$C$14,MATCH(A16,Éléments!$A$5:$A$14,0)),INDEX(Éléments!$C$5:$C$14,MATCH(B16,Éléments!$A$5:$A$14,0)),Paramètres!$B$11) -> 85 | H16: Estoc de flux corrosif | I16: Boule de flux corrosif | J16: Tir précis de flux corrosif | K16: =A16&"|"&B16 -> Électricité|Acide | L16: =B16&"|"&A16 -> Acide|Électricité
... A59: Neutre | B59: Neutre | C59: Singularité | D59: +25 % de dégâts ; ignore l'avantage et la résistance élémentaires de la cible (toujours ×1). | E59: Concentre la magie avant une explosion arcanique. | F59: Burst / dégâts fiables | G59: =MAX(INDEX(Éléments!$C$5:$C$14,MATCH(A59,Éléments!$A$5:$A$14,0)),INDEX(Éléments!$C$5:$C$14,MATCH(B59,Éléments!$A$5:$A$14,0)),Paramètres!$B$11) -> 85 | H59: Estoc de singularité | I59: Boule de singularité | J59: Tir précis de singularité | K59: =A59&"|"&B59 -> Neutre|Neutre | L59: =B59&"|"&A59 -> Neutre|Neutre
A61: Sur une compétence de soutien (buff, soin, bouclier), la fusion ajoute les effets « soutien » des deux éléments à 70 % chacun, en plus de l'effet de fusion s'il concerne le lanceur.
A62: Plafonds : les règles d'altération du bestiaire s'appliquent (cumul max, durée, contrôles divisés par 2 sur les boss, jamais d'immunité totale).

Sheet Constructeur
A1: Constructeur : une compétence, 1 ou 2 éléments
A2: Choisissez une compétence de base et ses éléments (cellules jaunes). Avec un 2e élément, la compétence devient une fusion.
A3: Compétence de base | B3: Boule arcanique
A4: Élément 1 (principal) | B4: Feu
A5: Élément 2 (fusion, ou —) | B5: Électricité
A6: Élément de l'ennemi visé | B6: Eau
A7: Stat d'attaque du joueur (Force ou Magie) | B7: 700
A8: Réduction des dégâts par l'ennemi | B8: 0.25
A10: (aide) N° de la compétence | B10: =MATCH($B$3,Bases!$C$5:$C$83,0) -> 24
A11: Classe · famille · type | B11: =INDEX(Bases!$B$5:$B$83,$B$10)&" · "&INDEX(Bases!$E$5:$E$83,$B$10)&" · "&INDEX(Bases!$F$5:$F$83,$B$10) -> Mage · Attaque (arme 1) · Attaque
A12: Fusion ? | B12: =IF(OR($B$5="",$B$5="—"),"Non","Oui") -> Oui
A13: (aide) ligne de fusion | B13: =IF($B$12="Non",0,IFERROR(MATCH($B$4&"|"&$B$5,Fusions!$K$5:$K$59,0),MATCH($B$4&"|"&$B$5,Fusions!$L$5:$L$59,0))) -> 2
A14: Nom de la fusion | B14: =IF($B$12="Non","—",INDEX(Fusions!$C$5:$C$59,$B$13)) -> Plasma
A15: Nom | B15: =IF(INDEX(Bases!$E$5:$E$83,$B$10)="Passif",$B$3,IF($B$12="Oui",INDEX(Bases!$D$5:$D$83,$B$10)&" "&IF(ISNUMBER(SEARCH(LEFT($B$14,1),"aeiouyéèêâîôh")),"d'","de ")&LOWER(LEFT($B$14,1))&MID($B$14,2,40),IF($B$4="Neutre",$B$3,INDEX(Bases!$D$5:$D$83,$B$10)&" "&INDEX(Éléments!$D$5:$D$14,MATCH($B$4,Éléments!$A$5:$A$14,0))))) -> Boule de plasma
A16: Cible · recharge · ultime | B16: =INDEX(Bases!$G$5:$G$83,$B$10)&" · recharge "&INDEX(Bases!$H$5:$H$83,$B$10)&" · ultime : "&INDEX(Bases!$I$5:$I$83,$B$10) -> Mono · recharge 0 · ultime : Non
A17: Puissance (× stat) | B17: =INDEX(Bases!$J$5:$J$83,$B$10)*IF($B$12="Oui",Paramètres!$B$10,1) -> 1.1
A18: Effet de base | B18: =INDEX(Bases!$L$5:$L$83,$B$10) -> Projectile magique fiable.
A19: Effet de l'élément 1 | B19: =IF($B$12="Oui","(remplacé par la fusion)",IF(INDEX(Bases!$E$5:$E$83,$B$10)="Attaque (arme 1)",INDEX(Éléments!$F$5:$F$14,MATCH($B$4,Éléments!$A$5:$A$14,0)),INDEX(Éléments!$G$5:$G$14,MATCH($B$4,Éléments!$A$5:$A$14,0)))) -> (remplacé par la fusion)
A20: Effet de la fusion | B20: =IF($B$12="Non","—",INDEX(Fusions!$D$5:$D$59,$B$13)) -> Rebondit sur 1 ennemi (50 % des dégâts) ; chaque cible touchée a 35 % de subir Brûlure.
A21: Multiplicateur élémentaire | B21: =INDEX(Éléments!$B$19:$K$28,MATCH($B$6,Éléments!$A$19:$A$28,0),MATCH($B$4,Éléments!$B$18:$K$18,0)) -> 0.75
A22: Dégâts par cible (estim.) | B22: =ROUND($B$7*$B$17*$B$21*(1-$B$8),0) -> 433
A23: Dégâts sur une vague (estim.) | B23: =$B$22*IF(INDEX(Bases!$G$5:$G$83,$B$10)="Zone",Paramètres!$B$8,IF(INDEX(Bases!$G$5:$G$83,$B$10)="Mono",1,0)) -> 433
A24: Disponible | B24: ="Niveau "&INDEX(Bases!$N$5:$N$83,$B$10)&" · étage "&MAX(INDEX(Éléments!$C$5:$C$14,MATCH($B$4,Éléments!$A$5:$A$14,0)),IF($B$12="Oui",MAX(INDEX(Éléments!$C$5:$C$14,MATCH($B$5,Éléments!$A$5:$A$14,0)),Paramètres!$B$11),0))&" terminé"&IF($B$12="Oui"," (Tour d'alchimie)","") -> Niveau 1 · étage 85 terminé (Tour d'alchimie)
A26: Dégâts = stat × puissance × multiplicateur élémentaire × (1 − réduction), avant critique. Pour une fusion, l'avantage se calcule avec l'élément 1 seulement.
A27: Exemple de combo : Boule d'eau (Mouillé) puis Lance de foudre (+25 % sur une cible Mouillée) ; ou Tir précis + Pointes barbelées pour du Saignement sur critique.

Sheet Rotation
A1: Rotation : 3 actives + 2 passives
A2: Choisissez vos compétences (noms du Catalogue). La simulation joue chaque tour la 1re compétence prête dans l'ordre des emplacements : mettez l'ultime en 1.
A3: Étage atteint (pour vérifier les déblocages) | B3: 65
A5: Emplacement | B5: Compétence | C5: Classe | D5: Famille | E5: Cible | F5: Recharge | G5: Ultime | H5: Puissance | I5: Disponible ? | J5: Effets
A6: Active 1 | B6: Explosion de feu | C6: =IFERROR(INDEX(Catalogue!$B$5:$B$488,MATCH($B6,Catalogue!$G$5:$G$488,0)),"?") -> Mage | D6: =IFERROR(INDEX(Catalogue!$C$5:$C$488,MATCH($B6,Catalogue!$G$5:$G$488,0)),"?") -> Attaque (arme 1) | E6: =IFERROR(INDEX(Catalogue!$H$5:$H$488,MATCH($B6,Catalogue!$G$5:$G$488,0)),"?") -> Mono | F6: =IFERROR(INDEX(Catalogue!$I$5:$I$488,MATCH($B6,Catalogue!$G$5:$G$488,0)),"?") -> 3 | G6: =IFERROR(INDEX(Catalogue!$J$5:$J$488,MATCH($B6,Catalogue!$G$5:$G$488,0)),"?") -> Oui | H6: =IFERROR(INDEX(Catalogue!$K$5:$K$488,MATCH($B6,Catalogue!$G$5:$G$488,0)),"?") -> 3 | I6: =IFERROR(IF(AND(INDEX(Catalogue!$P$5:$P$488,MATCH($B6,Catalogue!$G$5:$G$488,0))<=$B$3,INDEX(Catalogue!$Q$5:$Q$488,MATCH($B6,Catalogue!$G$5:$G$488,0))<$B$3),"Oui","Non : "&INDEX(Catalogue!$R$5:$R$488,MATCH($B6,Catalogue!$G$5:$G$488,0))),"?") -> Oui | J6: =IFERROR(INDEX(Catalogue!$M$5:$M$488,MATCH($B6,Catalogue!$G$5:$G$488,0))&IF(INDEX(Catalogue!$N$5:$N$488,MATCH($B6,Catalogue!$G$5:$G$488,0))="—",""," + "&INDEX(Catalogue!$N$5:$N$488,MATCH($B6,Catalogue!$G$5:$G$488,0))),"Nom introuvable dans le Catalogue") -> +25 % de dégâts si la cible porte une altération. + 35 % : Brûlure (8 % de la stat d'attaque par tour, 3 tours, non cumulable).
A7: Active 2 | B7: Lance de feu | C7: =IFERROR(INDEX(Catalogue!$B$5:$B$488,MATCH($B7,Catalogue!$G$5:$G$488,0)),"?") -> Mage | D7: =IFERROR(INDEX(Catalogue!$C$5:$C$488,MATCH($B7,Catalogue!$G$5:$G$488,0)),"?") -> Attaque (arme 1) | E7: =IFERROR(INDEX(Catalogue!$H$5:$H$488,MATCH($B7,Catalogue!$G$5:$G$488,0)),"?") -> Mono | F7: =IFERROR(INDEX(Catalogue!$I$5:$I$488,MATCH($B7,Catalogue!$G$5:$G$488,0)),"?") -> 0 | G7: =IFERROR(INDEX(Catalogue!$J$5:$J$488,MATCH($B7,Catalogue!$G$5:$G$488,0)),"?") -> Non | H7: =IFERROR(INDEX(Catalogue!$K$5:$K$488,MATCH($B7,Catalogue!$G$5:$G$488,0)),"?") -> 0.9 | I7: =IFERROR(IF(AND(INDEX(Catalogue!$P$5:$P$488,MATCH($B7,Catalogue!$G$5:$G$488,0))<=$B$3,INDEX(Catalogue!$Q$5:$Q$488,MATCH($B7,Catalogue!$G$5:$G$488,0))<$B$3),"Oui","Non : "&INDEX(Catalogue!$R$5:$R$488,MATCH($B7,Catalogue!$G$5:$G$488,0))),"?") -> Oui | J7: =IFERROR(INDEX(Catalogue!$M$5:$M$488,MATCH($B7,Catalogue!$G$5:$G$488,0))&IF(INDEX(Catalogue!$N$5:$N$488,MATCH($B7,Catalogue!$G$5:$G$488,0))="—",""," + "&INDEX(Catalogue!$N$5:$N$488,MATCH($B7,Catalogue!$G$5:$G$488,0))),"Nom introuvable dans le Catalogue") -> Ignore 15 % de la Résistance. + 35 % : Brûlure (8 % de la stat d'attaque par tour, 3 tours, non cumulable).
A8: Active 3 | B8: Boule de feu | C8: =IFERROR(INDEX(Catalogue!$B$5:$B$488,MATCH($B8,Catalogue!$G$5:$G$488,0)),"?") -> Mage | D8: =IFERROR(INDEX(Catalogue!$C$5:$C$488,MATCH($B8,Catalogue!$G$5:$G$488,0)),"?") -> Attaque (arme 1) | E8: =IFERROR(INDEX(Catalogue!$H$5:$H$488,MATCH($B8,Catalogue!$G$5:$G$488,0)),"?") -> Mono | F8: =IFERROR(INDEX(Catalogue!$I$5:$I$488,MATCH($B8,Catalogue!$G$5:$G$488,0)),"?") -> 0 | G8: =IFERROR(INDEX(Catalogue!$J$5:$J$488,MATCH($B8,Catalogue!$G$5:$G$488,0)),"?") -> Non | H8: =IFERROR(INDEX(Catalogue!$K$5:$K$488,MATCH($B8,Catalogue!$G$5:$G$488,0)),"?") -> 1 | I8: =IFERROR(IF(AND(INDEX(Catalogue!$P$5:$P$488,MATCH($B8,Catalogue!$G$5:$G$488,0))<=$B$3,INDEX(Catalogue!$Q$5:$Q$488,MATCH($B8,Catalogue!$G$5:$G$488,0))<$B$3),"Oui","Non : "&INDEX(Catalogue!$R$5:$R$488,MATCH($B8,Catalogue!$G$5:$G$488,0))),"?") -> Oui | J8: =IFERROR(INDEX(Catalogue!$M$5:$M$488,MATCH($B8,Catalogue!$G$5:$G$488,0))&IF(INDEX(Catalogue!$N$5:$N$488,MATCH($B8,Catalogue!$G$5:$G$488,0))="—",""," + "&INDEX(Catalogue!$N$5:$N$488,MATCH($B8,Catalogue!$G$5:$G$488,0))),"Nom introuvable dans le Catalogue") -> Projectile magique fiable. + 35 % : Brûlure (8 % de la stat d'attaque par tour, 3 tours, non cumulable).
A9: Passif 1 | B9: Persistance | C9: =IFERROR(INDEX(Catalogue!$B$5:$B$488,MATCH($B9,Catalogue!$G$5:$G$488,0)),"?") -> Mage | D9: =IFERROR(INDEX(Catalogue!$C$5:$C$488,MATCH($B9,Catalogue!$G$5:$G$488,0)),"?") -> Passif | E9: =IFERROR(INDEX(Catalogue!$H$5:$H$488,MATCH($B9,Catalogue!$G$5:$G$488,0)),"?") -> Soi | F9: =IFERROR(INDEX(Catalogue!$I$5:$I$488,MATCH($B9,Catalogue!$G$5:$G$488,0)),"?") -> — | G9: =IFERROR(INDEX(Catalogue!$J$5:$J$488,MATCH($B9,Catalogue!$G$5:$G$488,0)),"?") -> Non | H9: =IFERROR(INDEX(Catalogue!$K$5:$K$488,MATCH($B9,Catalogue!$G$5:$G$488,0)),"?") -> 0 | I9: =IFERROR(IF(AND(INDEX(Catalogue!$P$5:$P$488,MATCH($B9,Catalogue!$G$5:$G$488,0))<=$B$3,INDEX(Catalogue!$Q$5:$Q$488,MATCH($B9,Catalogue!$G$5:$G$488,0))<$B$3),"Oui","Non : "&INDEX(Catalogue!$R$5:$R$488,MATCH($B9,Catalogue!$G$5:$G$488,0))),"?") -> Oui | J9: =IFERROR(INDEX(Catalogue!$M$5:$M$488,MATCH($B9,Catalogue!$G$5:$G$488,0))&IF(INDEX(Catalogue!$N$5:$N$488,MATCH($B9,Catalogue!$G$5:$G$488,0))="—",""," + "&INDEX(Catalogue!$N$5:$N$488,MATCH($B9,Catalogue!$G$5:$G$488,0))),"Nom introuvable dans le Catalogue") -> Les altérations infligées durent 1 tour de plus.
A10: Passif 2 | B10: Affinité ardente | C10: =IFERROR(INDEX(Catalogue!$B$5:$B$488,MATCH($B10,Catalogue!$G$5:$G$488,0)),"?") -> Toutes | D10: =IFERROR(INDEX(Catalogue!$C$5:$C$488,MATCH($B10,Catalogue!$G$5:$G$488,0)),"?") -> Passif | E10: =IFERROR(INDEX(Catalogue!$H$5:$H$488,MATCH($B10,Catalogue!$G$5:$G$488,0)),"?") -> Soi | F10: =IFERROR(INDEX(Catalogue!$I$5:$I$488,MATCH($B10,Catalogue!$G$5:$G$488,0)),"?") -> — | G10: =IFERROR(INDEX(Catalogue!$J$5:$J$488,MATCH($B10,Catalogue!$G$5:$G$488,0)),"?") -> Non | H10: =IFERROR(INDEX(Catalogue!$K$5:$K$488,MATCH($B10,Catalogue!$G$5:$G$488,0)),"?") -> 0 | I10: =IFERROR(IF(AND(INDEX(Catalogue!$P$5:$P$488,MATCH($B10,Catalogue!$G$5:$G$488,0))<=$B$3,INDEX(Catalogue!$Q$5:$Q$488,MATCH($B10,Catalogue!$G$5:$G$488,0))<$B$3),"Oui","Non : "&INDEX(Catalogue!$R$5:$R$488,MATCH($B10,Catalogue!$G$5:$G$488,0))),"?") -> Oui | J10: =IFERROR(INDEX(Catalogue!$M$5:$M$488,MATCH($B10,Catalogue!$G$5:$G$488,0))&IF(INDEX(Catalogue!$N$5:$N$488,MATCH($B10,Catalogue!$G$5:$G$488,0))="—",""," + "&INDEX(Catalogue!$N$5:$N$488,MATCH($B10,Catalogue!$G$5:$G$488,0))),"Nom introuvable dans le Catalogue") -> +10 % de dégâts de Feu ; la Brûlure dure 1 tour de plus.
A12: Contrôles
A13: Une seule classe (ou affinités) | B13: =IF(SUMPRODUCT((C6:C10<>C6)*(C6:C10<>"Toutes"))=0,"OK","Mélange de classes") -> OK
A14: Actives = compétences actives | B14: =IF(COUNTIF(D6:D8,"Passif")=0,"OK","Un passif est en emplacement actif") -> OK
A15: Passives = compétences passives | B15: =IF(COUNTIF(D9:D10,"Passif")=2,"OK","Une active est en emplacement passif") -> OK
A16: Ultimes | B16: =IF(COUNTIF(G6:G8,"Oui")<=Paramètres!$B$7,"OK","Trop d'ultimes : "&COUNTIF(G6:G8,"Oui")) -> OK
A17: Toutes débloquées | B17: =IF(COUNTIF(I6:I10,"Oui")=5,"OK","Certaines ne sont pas encore disponibles") -> OK
A18: Pas de doublon | B18: =IF(SUMPRODUCT((B6:B10<>"")/COUNTIF(B6:B10,B6:B10&""))=5,"OK","Compétence en double") -> OK
A20: Résultat de la simulation
A21: Puissance moyenne par tour sur une cible | B21: =ROUND(AVERAGE(G27:G38),2) -> 1.6
A22: Puissance moyenne par tour sur une vague | B22: =ROUND(AVERAGE(H27:H38),2) -> 1.6
A23: Repère du bestiaire | B23: =Paramètres!$B$9 -> 1.5
A24: Lecture | B24: =IF(B21>=Paramètres!$B$9*1.2,"Rotation offensive : au-dessus du repère",IF(B21>=Paramètres!$B$9*0.9,"Rotation équilibrée","Rotation défensive : combats plus longs, à compenser par les soins / boucliers")) -> Rotation équilibrée
A26: Tour | B26: Active 1 prête | C26: Active 2 prête | D26: Active 3 prête | E26: Emplacement utilisé | F26: Compétence | G26: Puissance (1 cible) | H26: Puissance (vague) | I26: Dernier usage 1 | J26: Dernier usage 2 | K26: Dernier usage 3
A27: 1 | B27: =IF(AND($A27<=Paramètres!$B$12,$D$6<>"Passif",$A27--99>=IF(ISNUMBER($F$6),$F$6,99)),"Oui","Non") -> Oui | C27: =IF(AND($A27<=Paramètres!$B$12,$D$7<>"Passif",$A27--99>=IF(ISNUMBER($F$7),$F$7,99)),"Oui","Non") -> Oui | D27: =IF(AND($A27<=Paramètres!$B$12,$D$8<>"Passif",$A27--99>=IF(ISNUMBER($F$8),$F$8,99)),"Oui","Non") -> Oui | E27: =IF(B27="Oui",1,IF(C27="Oui",2,IF(D27="Oui",3,0))) -> 1 | F27: =IF(E27=0,"(rien de prêt)",INDEX($B$6:$B$8,E27)) -> Explosion de feu | G27: =IF(OR($A27>Paramètres!$B$12,E27=0),0,N(INDEX($H$6:$H$8,E27))) -> 3 | H27: =IF(OR($A27>Paramètres!$B$12,E27=0),0,N(INDEX($H$6:$H$8,E27))*IF(INDEX($E$6:$E$8,E27)="Zone",Paramètres!$B$8,1)) -> 3 | I27: =IF($E27=1,$A27,-99) -> 1 | J27: =IF($E27=2,$A27,-99) -> -99 | K27: =IF($E27=3,$A27,-99) -> -99
