Workbook

Sheet Guide
A1: RPG tour par tour : équipements
A2: Classeur de conception : tous les équipements, pour les 3 classes, les 10 slots, les 5 matériaux et les 7 raretés.
A4: OBJECTIF
A5: Contenu | B5: 930 équipements : 3 classes × 10 slots × 5 matériaux × 6 raretés (Commun → Légendaire), plus 30 Uniques. Chaque objet a ses stats selon slot, classe, matériau, rareté et amélioration.
A6: Slots | B6: Chapeau, Armure, Pantalon, Botte, Collier, Anneau 1, Anneau 2, Ceinture, Arme 1, Arme 2. Arme 1 / Arme 2 dépendent de la classe.
A7: ONGLETS
A8: Catalogue | B8: Les 930 objets. Cellule jaune du haut : niveau d'amélioration affiché (0, un nombre ou « max »). Filtres sur chaque colonne.
A9: Calculateur | B9: Un seul objet : classe, slot, rareté, palier, amélioration → nom, stats, passif, ressource et coût du niveau suivant.
A10: Progression | B10: L'objet du Calculateur, de +0 au maximum de son palier : stats, coût de chaque niveau et coût cumulé.
A11: Set complet | B11: 10 slots de même rareté pour une classe, un palier et une amélioration. Cases rouges = plafond conseillé dépassé.
A12: Uniques | B12: Les 30 Uniques : nom, élément, passif, biome de butin, boss qui les lâchent, niveau de base.
A13: Amélioration | B13: Ressource à dépenser pour chaque niveau d'amélioration (1 à 99), par rareté, et total cumulé.
A14: Profils | B14: Le cœur de l'équilibrage : poids de chaque stat pour chacun des 30 couples classe/slot.
A15: Matériaux | B15: Les 5 matériaux de chaque famille, les paliers (niveau de base, amélioration max) et où trouver chaque ressource.
A16: Paramètres | B16: Raretés (multiplicateur, lignes, coût d'amélioration), courbe de niveau, valeur de référence des stats, plafonds, courbe de coût.
A17: CLASSES
A18: Guerrier | B18: Épée + Bouclier. Armure lourde (cuir, fer, acier, mithril, adamantite). Stats : Vitalité, Force, Résistance, Armure. Initiative : bottes, chevalière, ceinturon.
A19: Mage | B19: Bâton + Orbe. Tissu (lin, laine, soie, velours enchanté, étoffe astrale). Stats : Magie, Vitalité, soins, résistances élémentaires. Initiative : bottines, sceau, amulette.
A20: Tireur | B20: Arc + Carquois. Cuir (toile, cuir, cuir clouté, écailles, peau de dragon). Stats : Agilité, Précision, critiques, Pénétration. Initiative : bottes, bague, capuche, carquois (le plus rapide).
A21: VARIANTES ET RARETÉS
A22: Matériau = variante | B22: Chaque type existe en 5 matériaux : Épée en bois, en fer, en acier, en mithril, en adamantite. Un matériau plus haut part d'un niveau plus élevé (1, 15, 30, 50, 70).
A23: Rareté | B23: Chaque variante existe en Commun, Rare, Super rare, Épique, Mythique et Légendaire : Épée en bois Commune … Épée en bois Légendaire, puis Épée en fer Commune … Légendaire, etc.
A24: Unique | B24: Stats (toutes les lignes, ×2,50) + passif, nom unique (ex. Épée de la Mort). Pas de matériau : il part du niveau de son biome et s'améliore jusqu'au niveau 100.
A25: AMÉLIORATION
A26: Principe | B26: Le niveau d'un objet = son amélioration (+0 quand il tombe). Améliorer coûte le matériau de l'objet : une Épée en bois demande un peu de bois au niveau 1, puis un peu plus à chaque niveau.
A27: Plafond | B27: Bois +19 (niv. 1→20), fer +20 (15→35), acier +25 (30→55), mithril +25 (50→75), adamantite +30 (70→100). Pour aller plus loin, il faut passer au matériau suivant.
A28: Coût | B28: Ressource pour le niveau L = arrondi(3 × L^1,25 × multiplicateur de rareté). Une Légendaire coûte 2,5 fois plus qu'une Commune. Pas de temps de fabrication.
A29: FORMULE
A30: Valeur d'une stat | B30: poids du slot × K × multiplicateur de rareté × facteur(niveau effectif), arrondi. Niveau effectif = niveau de base du matériau + amélioration. Facteur : 5 % au niveau 1, 100 % au niveau 100.
A31: Stats par rareté | B31: Une rareté ne débloque que les N stats les mieux classées du profil : 2 (Commun), 3, 4, 5, 6 (Mythique), 7 (Légendaire et Unique).
A32: HYPOTHÈSES À VALIDER
A33: Ressources | B33: Bois, fer, acier, mithril, adamantite, cuir, cuir clouté, écailles, peau de dragon, lin, laine, soie, velours, étoffe astrale viennent du diagramme. Les autres (chêne, quartz, cuivre…) ont une source proposée dans Matériaux.
A34: Butin | B34: Un objet tombe à +0, dans le matériau du palier de l'étage (bois étages 1–14, fer 15–29, acier 30–49, mithril 50–69, adamantite 70+).
A35: Armes | B35: Mage = Bâton + Orbe, Tireur = Arc + Carquois (tu n'avais donné que l'exemple du guerrier).
A36: Anneaux | B36: Anneau 1 (offensif) et Anneau 2 (défensif/utilitaire) sont deux objets distincts.
A37: Valeurs d'équilibrage | B37: Tous les chiffres (K, multiplicateurs, plafonds, coûts) sont des points de départ à ajuster après tests (production des bâtiments notamment).
A38: LÉGENDE
A39: Cellule jaune, texte bleu | B39: Valeur modifiable. Les cellules sans fond jaune sont des formules : ne pas écraser.
A41: MISE À JOUR
A42: Initiative | B42: Nouvelle stat (Paramètres, Profils, Catalogue, Calculateur, Progression, Set complet). Le mana est retiré : les 3 passifs Uniques qui l'utilisaient agissent désormais sur les recharges ou les PV.

Sheet Catalogue
A1: Catalogue des équipements
A2: 930 objets = 3 classes × 10 slots × (5 matériaux × 6 raretés + 1 Unique). Filtres sur chaque colonne.
A3: Niveau d'amélioration affiché | C3: 0 | D3: 0 = objet tel qu'il tombe. Un nombre = même amélioration pour tous (plafonnée par palier). « max » = chaque objet au maximum de son palier.
A5: ID | B5: Classe | C5: Slot | D5: Palier | E5: Matériau | F5: Rareté | G5: Nom | H5: Niveau de base | I5: Amélioration | J5: Niveau effectif | K5: Élément | L5: Vitalité | M5: Force | N5: Résistance | O5: Magie | P5: Agilité | Q5: Initiative | R5: Précision | S5: Chance de critique | T5: Dégâts critiques | U5: Armure | V5: Pénétration | W5: Résistance élémentaire | X5: Bonus de soins | Y5: Résistance aux altérations | Z5: Puissance (pts) | AA5: Passif | AB5: Effet du passif | AC5: Ressource d'amélioration | AD5: Coût du niveau suivant | AE5: (aide) N° profil | AF5: (aide) N° rareté | AG5: (aide) Multipl. | AH5: (aide) Lignes | AI5: (aide) Amélioration max | AJ5: (aide) Facteur
A6: GUE-CHA-P1-COM | B6: Guerrier | C6: Chapeau | D6: 1 | E6: {=INDEX(Matériaux!$B$5:$F$12,MATCH(INDEX(Profils!$E$5:$E$34,$AE6),Matériaux!$A$5:$A$12,0),$D6)} -> cuir | F6: Commun | G6: {=INDEX(Profils!$D$5:$D$34,$AE6)&" en "&$E6} -> Casque en cuir | H6: {=INDEX(Matériaux!$B$16:$B$20,$D6)} -> 1 | I6: =IF(ISNUMBER($C$3),MIN(MAX(0,ROUND($C$3,0)),$AI6),$AI6) -> 0 | J6: =$H6+$I6 -> 1 | K6: — | L6: {=IF(AND(INDEX(Profils!$F$5:$F$34,$AE6)>0,INDEX(Profils!$U$5:$U$34,$AE6)<=$AH6),ROUND(INDEX(Profils!$F$5:$F$34,$AE6)*Paramètres!$E$22*$AG6*$AJ6,Paramètres!$F$22),0)} -> 2 | M6: {=IF(AND(INDEX(Profils!$G$5:$G$34,$AE6)>0,INDEX(Profils!$V$5:$V$34,$AE6)<=$AH6),ROUND(INDEX(Profils!$G$5:$G$34,$AE6)*Paramètres!$E$23*$AG6*$AJ6,Paramètres!$F$23),0)} -> 0 | N6: {=IF(AND(INDEX(Profils!$H$5:$H$34,$AE6)>0,INDEX(Profils!$W$5:$W$34,$AE6)<=$AH6),ROUND(INDEX(Profils!$H$5:$H$34,$AE6)*Paramètres!$E$24*$AG6*$AJ6,Paramètres!$F$24),0)} -> 1 | O6: {=IF(AND(INDEX(Profils!$I$5:$I$34,$AE6)>0,INDEX(Profils!$X$5:$X$34,$AE6)<=$AH6),ROUND(INDEX(Profils!$I$5:$I$34,$AE6)*Paramètres!$E$25*$AG6*$AJ6,Paramètres!$F$25),0)} -> 0 | P6: {=IF(AND(INDEX(Profils!$J$5:$J$34,$AE6)>0,INDEX(Profils!$Y$5:$Y$34,$AE6)<=$AH6),ROUND(INDEX(Profils!$J$5:$J$34,$AE6)*Paramètres!$E$26*$AG6*$AJ6,Paramètres!$F$26),0)} -> 0 | Q6: {=IF(AND(INDEX(Profils!$K$5:$K$34,$AE6)>0,INDEX(Profils!$Z$5:$Z$34,$AE6)<=$AH6),ROUND(INDEX(Profils!$K$5:$K$34,$AE6)*Paramètres!$E$27*$AG6*$AJ6,Paramètres!$F$27),0)} -> 0 | R6: {=IF(AND(INDEX(Profils!$L$5:$L$34,$AE6)>0,INDEX(Profils!$AA$5:$AA$34,$AE6)<=$AH6),ROUND(INDEX(Profils!$L$5:$L$34,$AE6)*Paramètres!$E$28*$AG6*$AJ6,Paramètres!$F$28),0)} -> 0 | S6: {=IF(AND(INDEX(Profils!$M$5:$M$34,$AE6)>0,INDEX(Profils!$AB$5:$AB$34,$AE6)<=$AH6),ROUND(INDEX(Profils!$M$5:$M$34,$AE6)*Paramètres!$E$29*$AG6*$AJ6,Paramètres!$F$29),0)} -> 0 | T6: {=IF(AND(INDEX(Profils!$N$5:$N$34,$AE6)>0,INDEX(Profils!$AC$5:$AC$34,$AE6)<=$AH6),ROUND(INDEX(Profils!$N$5:$N$34,$AE6)*Paramètres!$E$30*$AG6*$AJ6,Paramètres!$F$30),0)} -> 0 | U6: {=IF(AND(INDEX(Profils!$O$5:$O$34,$AE6)>0,INDEX(Profils!$AD$5:$AD$34,$AE6)<=$AH6),ROUND(INDEX(Profils!$O$5:$O$34,$AE6)*Paramètres!$E$31*$AG6*$AJ6,Paramètres!$F$31),0)} -> 0 | V6: {=IF(AND(INDEX(Profils!$P$5:$P$34,$AE6)>0,INDEX(Profils!$AE$5:$AE$34,$AE6)<=$AH6),ROUND(INDEX(Profils!$P$5:$P$34,$AE6)*Paramètres!$E$32*$AG6*$AJ6,Paramètres!$F$32),0)} -> 0 | W6: {=IF(AND(INDEX(Profils!$Q$5:$Q$34,$AE6)>0,INDEX(Profils!$AF$5:$AF$34,$AE6)<=$AH6),ROUND(INDEX(Profils!$Q$5:$Q$34,$AE6)*Paramètres!$E$33*$AG6*$AJ6,Paramètres!$F$33),0)} -> 0 | X6: {=IF(AND(INDEX(Profils!$R$5:$R$34,$AE6)>0,INDEX(Profils!$AG$5:$AG$34,$AE6)<=$AH6),ROUND(INDEX(Profils!$R$5:$R$34,$AE6)*Paramètres!$E$34*$AG6*$AJ6,Paramètres!$F$34),0)} -> 0 | Y6: {=IF(AND(INDEX(Profils!$S$5:$S$34,$AE6)>0,INDEX(Profils!$AH$5:$AH$34,$AE6)<=$AH6),ROUND(INDEX(Profils!$S$5:$S$34,$AE6)*Paramètres!$E$35*$AG6*$AJ6,Paramètres!$F$35),0)} -> 0 | Z6: =ROUND(L6/Paramètres!$E$22+M6/Paramètres!$E$23+N6/Paramètres!$E$24+O6/Paramètres!$E$25+P6/Paramètres!$E$26+Q6/Paramètres!$E$27+R6/Paramètres!$E$28+S6/Paramètres!$E$29+T6/Paramètres!$E$30+U6/Paramètres!$E$31+V6/Paramètres!$E$32+W6/Paramètres!$E$33+X6/Paramètres!$E$34+Y6/Paramètres!$E$35,1) -> 0.1 | AA6: — | AB6: — | AC6: =$E6 -> cuir | AD6: {=IF($I6>=$AI6,"Max",ROUND(Paramètres!$B$40*($I6+1)^Paramètres!$B$41*INDEX(Paramètres!$H$6:$H$12,$AF6),0))} -> 3 | AE6: =MATCH($B6&"|"&$C6,Profils!$A$5:$A$34,0) -> 1 | AF6: 1 | AG6: {=INDEX(Paramètres!$C$6:$C$12,$AF6)} -> 1 | AH6: {=INDEX(Paramètres!$D$6:$D$12,$AF6)} -> 2 | AI6: {=INDEX(Matériaux!$C$16:$C$20,$D6)} -> 19 | AJ6: =Paramètres!$B$16+(1-Paramètres!$B$16)*(($J6-Paramètres!$B$14)/(Paramètres!$B$15-Paramètres!$B$14))^Paramètres!$B$17 -> 0.05
A7: GUE-CHA-P1-RAR | B7: Guerrier | C7: Chapeau | D7: 1 | E7: {=INDEX(Matériaux!$B$5:$F$12,MATCH(INDEX(Profils!$E$5:$E$34,$AE7),Matériaux!$A$5:$A$12,0),$D7)} -> cuir | F7: Rare | G7: {=INDEX(Profils!$D$5:$D$34,$AE7)&" en "&$E7} -> Casque en cuir | H7: {=INDEX(Matériaux!$B$16:$B$20,$D7)} -> 1 | I7: =IF(ISNUMBER($C$3),MIN(MAX(0,ROUND($C$3,0)),$AI7),$AI7) -> 0 | J7: =$H7+$I7 -> 1 | K7: — | L7: {=IF(AND(INDEX(Profils!$F$5:$F$34,$AE7)>0,INDEX(Profils!$U$5:$U$34,$AE7)<=$AH7),ROUND(INDEX(Profils!$F$5:$F$34,$AE7)*Paramètres!$E$22*$AG7*$AJ7,Paramètres!$F$22),0)} -> 2 | M7: {=IF(AND(INDEX(Profils!$G$5:$G$34,$AE7)>0,INDEX(Profils!$V$5:$V$34,$AE7)<=$AH7),ROUND(INDEX(Profils!$G$5:$G$34,$AE7)*Paramètres!$E$23*$AG7*$AJ7,Paramètres!$F$23),0)} -> 0 | N7: {=IF(AND(INDEX(Profils!$H$5:$H$34,$AE7)>0,INDEX(Profils!$W$5:$W$34,$AE7)<=$AH7),ROUND(INDEX(Profils!$H$5:$H$34,$AE7)*Paramètres!$E$24*$AG7*$AJ7,Paramètres!$F$24),0)} -> 1 | O7: {=IF(AND(INDEX(Profils!$I$5:$I$34,$AE7)>0,INDEX(Profils!$X$5:$X$34,$AE7)<=$AH7),ROUND(INDEX(Profils!$I$5:$I$34,$AE7)*Paramètres!$E$25*$AG7*$AJ7,Paramètres!$F$25),0)} -> 0 | P7: {=IF(AND(INDEX(Profils!$J$5:$J$34,$AE7)>0,INDEX(Profils!$Y$5:$Y$34,$AE7)<=$AH7),ROUND(INDEX(Profils!$J$5:$J$34,$AE7)*Paramètres!$E$26*$AG7*$AJ7,Paramètres!$F$26),0)} -> 0 | Q7: {=IF(AND(INDEX(Profils!$K$5:$K$34,$AE7)>0,INDEX(Profils!$Z$5:$Z$34,$AE7)<=$AH7),ROUND(INDEX(Profils!$K$5:$K$34,$AE7)*Paramètres!$E$27*$AG7*$AJ7,Paramètres!$F$27),0)} -> 0 | R7: {=IF(AND(INDEX(Profils!$L$5:$L$34,$AE7)>0,INDEX(Profils!$AA$5:$AA$34,$AE7)<=$AH7),ROUND(INDEX(Profils!$L$5:$L$34,$AE7)*Paramètres!$E$28*$AG7*$AJ7,Paramètres!$F$28),0)} -> 0 | S7: {=IF(AND(INDEX(Profils!$M$5:$M$34,$AE7)>0,INDEX(Profils!$AB$5:$AB$34,$AE7)<=$AH7),ROUND(INDEX(Profils!$M$5:$M$34,$AE7)*Paramètres!$E$29*$AG7*$AJ7,Paramètres!$F$29),0)} -> 0 | T7: {=IF(AND(INDEX(Profils!$N$5:$N$34,$AE7)>0,INDEX(Profils!$AC$5:$AC$34,$AE7)<=$AH7),ROUND(INDEX(Profils!$N$5:$N$34,$AE7)*Paramètres!$E$30*$AG7*$AJ7,Paramètres!$F$30),0)} -> 0 | U7: {=IF(AND(INDEX(Profils!$O$5:$O$34,$AE7)>0,INDEX(Profils!$AD$5:$AD$34,$AE7)<=$AH7),ROUND(INDEX(Profils!$O$5:$O$34,$AE7)*Paramètres!$E$31*$AG7*$AJ7,Paramètres!$F$31),0)} -> 1 | V7: {=IF(AND(INDEX(Profils!$P$5:$P$34,$AE7)>0,INDEX(Profils!$AE$5:$AE$34,$AE7)<=$AH7),ROUND(INDEX(Profils!$P$5:$P$34,$AE7)*Paramètres!$E$32*$AG7*$AJ7,Paramètres!$F$32),0)} -> 0 | W7: {=IF(AND(INDEX(Profils!$Q$5:$Q$34,$AE7)>0,INDEX(Profils!$AF$5:$AF$34,$AE7)<=$AH7),ROUND(INDEX(Profils!$Q$5:$Q$34,$AE7)*Paramètres!$E$33*$AG7*$AJ7,Paramètres!$F$33),0)} -> 0 | X7: {=IF(AND(INDEX(Profils!$R$5:$R$34,$AE7)>0,INDEX(Profils!$AG$5:$AG$34,$AE7)<=$AH7),ROUND(INDEX(Profils!$R$5:$R$34,$AE7)*Paramètres!$E$34*$AG7*$AJ7,Paramètres!$F$34),0)} -> 0 | Y7: {=IF(AND(INDEX(Profils!$S$5:$S$34,$AE7)>0,INDEX(Profils!$AH$5:$AH$34,$AE7)<=$AH7),ROUND(INDEX(Profils!$S$5:$S$34,$AE7)*Paramètres!$E$35*$AG7*$AJ7,Paramètres!$F$35),0)} -> 0 | Z7: =ROUND(L7/Paramètres!$E$22+M7/Paramètres!$E$23+N7/Paramètres!$E$24+O7/Paramètres!$E$25+P7/Paramètres!$E$26+Q7/Paramètres!$E$27+R7/Paramètres!$E$28+S7/Paramètres!$E$29+T7/Paramètres!$E$30+U7/Paramètres!$E$31+V7/Paramètres!$E$32+W7/Paramètres!$E$33+X7/Paramètres!$E$34+Y7/Paramètres!$E$35,1) -> 0.2 | AA7: — | AB7: — | AC7: =$E7 -> cuir | AD7: {=IF($I7>=$AI7,"Max",ROUND(Paramètres!$B$40*($I7+1)^Paramètres!$B$41*INDEX(Paramètres!$H$6:$H$12,$AF7),0))} -> 4 | AE7: =MATCH($B7&"|"&$C7,Profils!$A$5:$A$34,0) -> 1 | AF7: 2 | AG7: {=INDEX(Paramètres!$C$6:$C$12,$AF7)} -> 1.2 | AH7: {=INDEX(Paramètres!$D$6:$D$12,$AF7)} -> 3 | AI7: {=INDEX(Matériaux!$C$16:$C$20,$D7)} -> 19 | AJ7: =Paramètres!$B$16+(1-Paramètres!$B$16)*(($J7-Paramètres!$B$14)/(Paramètres!$B$15-Paramètres!$B$14))^Paramètres!$B$17 -> 0.05
A8: GUE-CHA-P1-SRA | B8: Guerrier | C8: Chapeau | D8: 1 | E8: {=INDEX(Matériaux!$B$5:$F$12,MATCH(INDEX(Profils!$E$5:$E$34,$AE8),Matériaux!$A$5:$A$12,0),$D8)} -> cuir | F8: Super rare | G8: {=INDEX(Profils!$D$5:$D$34,$AE8)&" en "&$E8} -> Casque en cuir | H8: {=INDEX(Matériaux!$B$16:$B$20,$D8)} -> 1 | I8: =IF(ISNUMBER($C$3),MIN(MAX(0,ROUND($C$3,0)),$AI8),$AI8) -> 0 | J8: =$H8+$I8 -> 1 | K8: — | L8: {=IF(AND(INDEX(Profils!$F$5:$F$34,$AE8)>0,INDEX(Profils!$U$5:$U$34,$AE8)<=$AH8),ROUND(INDEX(Profils!$F$5:$F$34,$AE8)*Paramètres!$E$22*$AG8*$AJ8,Paramètres!$F$22),0)} -> 3 | M8: {=IF(AND(INDEX(Profils!$G$5:$G$34,$AE8)>0,INDEX(Profils!$V$5:$V$34,$AE8)<=$AH8),ROUND(INDEX(Profils!$G$5:$G$34,$AE8)*Paramètres!$E$23*$AG8*$AJ8,Paramètres!$F$23),0)} -> 0 | N8: {=IF(AND(INDEX(Profils!$H$5:$H$34,$AE8)>0,INDEX(Profils!$W$5:$W$34,$AE8)<=$AH8),ROUND(INDEX(Profils!$H$5:$H$34,$AE8)*Paramètres!$E$24*$AG8*$AJ8,Paramètres!$F$24),0)} -> 1 | O8: {=IF(AND(INDEX(Profils!$I$5:$I$34,$AE8)>0,INDEX(Profils!$X$5:$X$34,$AE8)<=$AH8),ROUND(INDEX(Profils!$I$5:$I$34,$AE8)*Paramètres!$E$25*$AG8*$AJ8,Paramètres!$F$25),0)} -> 0 | P8: {=IF(AND(INDEX(Profils!$J$5:$J$34,$AE8)>0,INDEX(Profils!$Y$5:$Y$34,$AE8)<=$AH8),ROUND(INDEX(Profils!$J$5:$J$34,$AE8)*Paramètres!$E$26*$AG8*$AJ8,Paramètres!$F$26),0)} -> 0 | Q8: {=IF(AND(INDEX(Profils!$K$5:$K$34,$AE8)>0,INDEX(Profils!$Z$5:$Z$34,$AE8)<=$AH8),ROUND(INDEX(Profils!$K$5:$K$34,$AE8)*Paramètres!$E$27*$AG8*$AJ8,Paramètres!$F$27),0)} -> 0 | R8: {=IF(AND(INDEX(Profils!$L$5:$L$34,$AE8)>0,INDEX(Profils!$AA$5:$AA$34,$AE8)<=$AH8),ROUND(INDEX(Profils!$L$5:$L$34,$AE8)*Paramètres!$E$28*$AG8*$AJ8,Paramètres!$F$28),0)} -> 0 | S8: {=IF(AND(INDEX(Profils!$M$5:$M$34,$AE8)>0,INDEX(Profils!$AB$5:$AB$34,$AE8)<=$AH8),ROUND(INDEX(Profils!$M$5:$M$34,$AE8)*Paramètres!$E$29*$AG8*$AJ8,Paramètres!$F$29),0)} -> 0 | T8: {=IF(AND(INDEX(Profils!$N$5:$N$34,$AE8)>0,INDEX(Profils!$AC$5:$AC$34,$AE8)<=$AH8),ROUND(INDEX(Profils!$N$5:$N$34,$AE8)*Paramètres!$E$30*$AG8*$AJ8,Paramètres!$F$30),0)} -> 0 | U8: {=IF(AND(INDEX(Profils!$O$5:$O$34,$AE8)>0,INDEX(Profils!$AD$5:$AD$34,$AE8)<=$AH8),ROUND(INDEX(Profils!$O$5:$O$34,$AE8)*Paramètres!$E$31*$AG8*$AJ8,Paramètres!$F$31),0)} -> 2 | V8: {=IF(AND(INDEX(Profils!$P$5:$P$34,$AE8)>0,INDEX(Profils!$AE$5:$AE$34,$AE8)<=$AH8),ROUND(INDEX(Profils!$P$5:$P$34,$AE8)*Paramètres!$E$32*$AG8*$AJ8,Paramètres!$F$32),0)} -> 0 | W8: {=IF(AND(INDEX(Profils!$Q$5:$Q$34,$AE8)>0,INDEX(Profils!$AF$5:$AF$34,$AE8)<=$AH8),ROUND(INDEX(Profils!$Q$5:$Q$34,$AE8)*Paramètres!$E$33*$AG8*$AJ8,Paramètres!$F$33),0)} -> 0 | X8: {=IF(AND(INDEX(Profils!$R$5:$R$34,$AE8)>0,INDEX(Profils!$AG$5:$AG$34,$AE8)<=$AH8),ROUND(INDEX(Profils!$R$5:$R$34,$AE8)*Paramètres!$E$34*$AG8*$AJ8,Paramètres!$F$34),0)} -> 0 | Y8: {=IF(AND(INDEX(Profils!$S$5:$S$34,$AE8)>0,INDEX(Profils!$AH$5:$AH$34,$AE8)<=$AH8),ROUND(INDEX(Profils!$S$5:$S$34,$AE8)*Paramètres!$E$35*$AG8*$AJ8,Paramètres!$F$35),0)} -> 0.001 | Z8: =ROUND(L8/Paramètres!$E$22+M8/Paramètres!$E$23+N8/Paramètres!$E$24+O8/Paramètres!$E$25+P8/Paramètres!$E$26+Q8/Paramètres!$E$27+R8/Paramètres!$E$28+S8/Paramètres!$E$29+T8/Paramètres!$E$30+U8/Paramètres!$E$31+V8/Paramètres!$E$32+W8/Paramètres!$E$33+X8/Paramètres!$E$34+Y8/Paramètres!$E$35,1) -> 0.4 | AA8: — | AB8: — | AC8: =$E8 -> cuir | AD8: {=IF($I8>=$AI8,"Max",ROUND(Paramètres!$B$40*($I8+1)^Paramètres!$B$41*INDEX(Paramètres!$H$6:$H$12,$AF8),0))} -> 4 | AE8: =MATCH($B8&"|"&$C8,Profils!$A$5:$A$34,0) -> 1 | AF8: 3 | AG8: {=INDEX(Paramètres!$C$6:$C$12,$AF8)} -> 1.45 | AH8: {=INDEX(Paramètres!$D$6:$D$12,$AF8)} -> 4 | AI8: {=INDEX(Matériaux!$C$16:$C$20,$D8)} -> 19 | AJ8: =Paramètres!$B$16+(1-Paramètres!$B$16)*(($J8-Paramètres!$B$14)/(Paramètres!$B$15-Paramètres!$B$14))^Paramètres!$B$17 -> 0.05
A9: GUE-CHA-P1-EPI | B9: Guerrier | C9: Chapeau | D9: 1 | E9: {=INDEX(Matériaux!$B$5:$F$12,MATCH(INDEX(Profils!$E$5:$E$34,$AE9),Matériaux!$A$5:$A$12,0),$D9)} -> cuir | F9: Épique | G9: {=INDEX(Profils!$D$5:$D$34,$AE9)&" en "&$E9} -> Casque en cuir | H9: {=INDEX(Matériaux!$B$16:$B$20,$D9)} -> 1 | I9: =IF(ISNUMBER($C$3),MIN(MAX(0,ROUND($C$3,0)),$AI9),$AI9) -> 0 | J9: =$H9+$I9 -> 1 | K9: — | L9: {=IF(AND(INDEX(Profils!$F$5:$F$34,$AE9)>0,INDEX(Profils!$U$5:$U$34,$AE9)<=$AH9),ROUND(INDEX(Profils!$F$5:$F$34,$AE9)*Paramètres!$E$22*$AG9*$AJ9,Paramètres!$F$22),0)} -> 4 | M9: {=IF(AND(INDEX(Profils!$G$5:$G$34,$AE9)>0,INDEX(Profils!$V$5:$V$34,$AE9)<=$AH9),ROUND(INDEX(Profils!$G$5:$G$34,$AE9)*Paramètres!$E$23*$AG9*$AJ9,Paramètres!$F$23),0)} -> 0 | N9: {=IF(AND(INDEX(Profils!$H$5:$H$34,$AE9)>0,INDEX(Profils!$W$5:$W$34,$AE9)<=$AH9),ROUND(INDEX(Profils!$H$5:$H$34,$AE9)*Paramètres!$E$24*$AG9*$AJ9,Paramètres!$F$24),0)} -> 2 | O9: {=IF(AND(INDEX(Profils!$I$5:$I$34,$AE9)>0,INDEX(Profils!$X$5:$X$34,$AE9)<=$AH9),ROUND(INDEX(Profils!$I$5:$I$34,$AE9)*Paramètres!$E$25*$AG9*$AJ9,Paramètres!$F$25),0)} -> 0 | P9: {=IF(AND(INDEX(Profils!$J$5:$J$34,$AE9)>0,INDEX(Profils!$Y$5:$Y$34,$AE9)<=$AH9),ROUND(INDEX(Profils!$J$5:$J$34,$AE9)*Paramètres!$E$26*$AG9*$AJ9,Paramètres!$F$26),0)} -> 0 | Q9: {=IF(AND(INDEX(Profils!$K$5:$K$34,$AE9)>0,INDEX(Profils!$Z$5:$Z$34,$AE9)<=$AH9),ROUND(INDEX(Profils!$K$5:$K$34,$AE9)*Paramètres!$E$27*$AG9*$AJ9,Paramètres!$F$27),0)} -> 0 | R9: {=IF(AND(INDEX(Profils!$L$5:$L$34,$AE9)>0,INDEX(Profils!$AA$5:$AA$34,$AE9)<=$AH9),ROUND(INDEX(Profils!$L$5:$L$34,$AE9)*Paramètres!$E$28*$AG9*$AJ9,Paramètres!$F$28),0)} -> 0 | S9: {=IF(AND(INDEX(Profils!$M$5:$M$34,$AE9)>0,INDEX(Profils!$AB$5:$AB$34,$AE9)<=$AH9),ROUND(INDEX(Profils!$M$5:$M$34,$AE9)*Paramètres!$E$29*$AG9*$AJ9,Paramètres!$F$29),0)} -> 0 | T9: {=IF(AND(INDEX(Profils!$N$5:$N$34,$AE9)>0,INDEX(Profils!$AC$5:$AC$34,$AE9)<=$AH9),ROUND(INDEX(Profils!$N$5:$N$34,$AE9)*Paramètres!$E$30*$AG9*$AJ9,Paramètres!$F$30),0)} -> 0 | U9: {=IF(AND(INDEX(Profils!$O$5:$O$34,$AE9)>0,INDEX(Profils!$AD$5:$AD$34,$AE9)<=$AH9),ROUND(INDEX(Profils!$O$5:$O$34,$AE9)*Paramètres!$E$31*$AG9*$AJ9,Paramètres!$F$31),0)} -> 2 | V9: {=IF(AND(INDEX(Profils!$P$5:$P$34,$AE9)>0,INDEX(Profils!$AE$5:$AE$34,$AE9)<=$AH9),ROUND(INDEX(Profils!$P$5:$P$34,$AE9)*Paramètres!$E$32*$AG9*$AJ9,Paramètres!$F$32),0)} -> 0 | W9: {=IF(AND(INDEX(Profils!$Q$5:$Q$34,$AE9)>0,INDEX(Profils!$AF$5:$AF$34,$AE9)<=$AH9),ROUND(INDEX(Profils!$Q$5:$Q$34,$AE9)*Paramètres!$E$33*$AG9*$AJ9,Paramètres!$F$33),0)} -> 0.001 | X9: {=IF(AND(INDEX(Profils!$R$5:$R$34,$AE9)>0,INDEX(Profils!$AG$5:$AG$34,$AE9)<=$AH9),ROUND(INDEX(Profils!$R$5:$R$34,$AE9)*Paramètres!$E$34*$AG9*$AJ9,Paramètres!$F$34),0)} -> 0 | Y9: {=IF(AND(INDEX(Profils!$S$5:$S$34,$AE9)>0,INDEX(Profils!$AH$5:$AH$34,$AE9)<=$AH9),ROUND(INDEX(Profils!$S$5:$S$34,$AE9)*Paramètres!$E$35*$AG9*$AJ9,Paramètres!$F$35),0)} -> 0.001 | Z9: =ROUND(L9/Paramètres!$E$22+M9/Paramètres!$E$23+N9/Paramètres!$E$24+O9/Paramètres!$E$25+P9/Paramètres!$E$26+Q9/Paramètres!$E$27+R9/Paramètres!$E$28+S9/Paramètres!$E$29+T9/Paramètres!$E$30+U9/Paramètres!$E$31+V9/Paramètres!$E$32+W9/Paramètres!$E$33+X9/Paramètres!$E$34+Y9/Paramètres!$E$35,1) -> 0.5 | AA9: — | AB9: — | AC9: =$E9 -> cuir | AD9: {=IF($I9>=$AI9,"Max",ROUND(Paramètres!$B$40*($I9+1)^Paramètres!$B$41*INDEX(Paramètres!$H$6:$H$12,$AF9),0))} -> 5 | AE9: =MATCH($B9&"|"&$C9,Profils!$A$5:$A$34,0) -> 1 | AF9: 4 | AG9: {=INDEX(Paramètres!$C$6:$C$12,$AF9)} -> 1.75 | AH9: {=INDEX(Paramètres!$D$6:$D$12,$AF9)} -> 5 | AI9: {=INDEX(Matériaux!$C$16:$C$20,$D9)} -> 19 | AJ9: =Paramètres!$B$16+(1-Paramètres!$B$16)*(($J9-Paramètres!$B$14)/(Paramètres!$B$15-Paramètres!$B$14))^Paramètres!$B$17 -> 0.05
A10: GUE-CHA-P1-MYT | B10: Guerrier | C10: Chapeau | D10: 1 | E10: {=INDEX(Matériaux!$B$5:$F$12,MATCH(INDEX(Profils!$E$5:$E$34,$AE10),Matériaux!$A$5:$A$12,0),$D10)} -> cuir | F10: Mythique | G10: {=INDEX(Profils!$D$5:$D$34,$AE10)&" en "&$E10} -> Casque en cuir | H10: {=INDEX(Matériaux!$B$16:$B$20,$D10)} -> 1 | I10: =IF(ISNUMBER($C$3),MIN(MAX(0,ROUND($C$3,0)),$AI10),$AI10) -> 0 | J10: =$H10+$I10 -> 1 | K10: — | L10: {=IF(AND(INDEX(Profils!$F$5:$F$34,$AE10)>0,INDEX(Profils!$U$5:$U$34,$AE10)<=$AH10),ROUND(INDEX(Profils!$F$5:$F$34,$AE10)*Paramètres!$E$22*$AG10*$AJ10,Paramètres!$F$22),0)} -> 4 | M10: {=IF(AND(INDEX(Profils!$G$5:$G$34,$AE10)>0,INDEX(Profils!$V$5:$V$34,$AE10)<=$AH10),ROUND(INDEX(Profils!$G$5:$G$34,$AE10)*Paramètres!$E$23*$AG10*$AJ10,Paramètres!$F$23),0)} -> 1 | N10: {=IF(AND(INDEX(Profils!$H$5:$H$34,$AE10)>0,INDEX(Profils!$W$5:$W$34,$AE10)<=$AH10),ROUND(INDEX(Profils!$H$5:$H$34,$AE10)*Paramètres!$E$24*$AG10*$AJ10,Paramètres!$F$24),0)} -> 2 | O10: {=IF(AND(INDEX(Profils!$I$5:$I$34,$AE10)>0,INDEX(Profils!$X$5:$X$34,$AE10)<=$AH10),ROUND(INDEX(Profils!$I$5:$I$34,$AE10)*Paramètres!$E$25*$AG10*$AJ10,Paramètres!$F$25),0)} -> 0 | P10: {=IF(AND(INDEX(Profils!$J$5:$J$34,$AE10)>0,INDEX(Profils!$Y$5:$Y$34,$AE10)<=$AH10),ROUND(INDEX(Profils!$J$5:$J$34,$AE10)*Paramètres!$E$26*$AG10*$AJ10,Paramètres!$F$26),0)} -> 0 | Q10: {=IF(AND(INDEX(Profils!$K$5:$K$34,$AE10)>0,INDEX(Profils!$Z$5:$Z$34,$AE10)<=$AH10),ROUND(INDEX(Profils!$K$5:$K$34,$AE10)*Paramètres!$E$27*$AG10*$AJ10,Paramètres!$F$27),0)} -> 0 | R10: {=IF(AND(INDEX(Profils!$L$5:$L$34,$AE10)>0,INDEX(Profils!$AA$5:$AA$34,$AE10)<=$AH10),ROUND(INDEX(Profils!$L$5:$L$34,$AE10)*Paramètres!$E$28*$AG10*$AJ10,Paramètres!$F$28),0)} -> 0 | S10: {=IF(AND(INDEX(Profils!$M$5:$M$34,$AE10)>0,INDEX(Profils!$AB$5:$AB$34,$AE10)<=$AH10),ROUND(INDEX(Profils!$M$5:$M$34,$AE10)*Paramètres!$E$29*$AG10*$AJ10,Paramètres!$F$29),0)} -> 0 | T10: {=IF(AND(INDEX(Profils!$N$5:$N$34,$AE10)>0,INDEX(Profils!$AC$5:$AC$34,$AE10)<=$AH10),ROUND(INDEX(Profils!$N$5:$N$34,$AE10)*Paramètres!$E$30*$AG10*$AJ10,Paramètres!$F$30),0)} -> 0 | U10: {=IF(AND(INDEX(Profils!$O$5:$O$34,$AE10)>0,INDEX(Profils!$AD$5:$AD$34,$AE10)<=$AH10),ROUND(INDEX(Profils!$O$5:$O$34,$AE10)*Paramètres!$E$31*$AG10*$AJ10,Paramètres!$F$31),0)} -> 3 | V10: {=IF(AND(INDEX(Profils!$P$5:$P$34,$AE10)>0,INDEX(Profils!$AE$5:$AE$34,$AE10)<=$AH10),ROUND(INDEX(Profils!$P$5:$P$34,$AE10)*Paramètres!$E$32*$AG10*$AJ10,Paramètres!$F$32),0)} -> 0 | W10: {=IF(AND(INDEX(Profils!$Q$5:$Q$34,$AE10)>0,INDEX(Profils!$AF$5:$AF$34,$AE10)<=$AH10),ROUND(INDEX(Profils!$Q$5:$Q$34,$AE10)*Paramètres!$E$33*$AG10*$AJ10,Paramètres!$F$33),0)} -> 0.001 | X10: {=IF(AND(INDEX(Profils!$R$5:$R$34,$AE10)>0,INDEX(Profils!$AG$5:$AG$34,$AE10)<=$AH10),ROUND(INDEX(Profils!$R$5:$R$34,$AE10)*Paramètres!$E$34*$AG10*$AJ10,Paramètres!$F$34),0)} -> 0 | Y10: {=IF(AND(INDEX(Profils!$S$5:$S$34,$AE10)>0,INDEX(Profils!$AH$5:$AH$34,$AE10)<=$AH10),ROUND(INDEX(Profils!$S$5:$S$34,$AE10)*Paramètres!$E$35*$AG10*$AJ10,Paramètres!$F$35),0)} -> 0.002 | Z10: =ROUND(L10/Paramètres!$E$22+M10/Paramètres!$E$23+N10/Paramètres!$E$24+O10/Paramètres!$E$25+P10/Paramètres!$E$26+Q10/Paramètres!$E$27+R10/Paramètres!$E$28+S10/Paramètres!$E$29+T10/Paramètres!$E$30+U10/Paramètres!$E$31+V10/Paramètres!$E$32+W10/Paramètres!$E$33+X10/Paramètres!$E$34+Y10/Paramètres!$E$35,1) -> 0.7 | AA10: — | AB10: — | AC10: =$E10 -> cuir | AD10: {=IF($I10>=$AI10,"Max",ROUND(Paramètres!$B$40*($I10+1)^Paramètres!$B$41*INDEX(Paramètres!$H$6:$H$12,$AF10),0))} -> 6 | AE10: =MATCH($B10&"|"&$C10,Profils!$A$5:$A$34,0) -> 1 | AF10: 5 | AG10: {=INDEX(Paramètres!$C$6:$C$12,$AF10)} -> 2.1 | AH10: {=INDEX(Paramètres!$D$6:$D$12,$AF10)} -> 6 | AI10: {=INDEX(Matériaux!$C$16:$C$20,$D10)} -> 19 | AJ10: =Paramètres!$B$16+(1-Paramètres!$B$16)*(($J10-Paramètres!$B$14)/(Paramètres!$B$15-Paramètres!$B$14))^Paramètres!$B$17 -> 0.05
A11: GUE-CHA-P1-LEG | B11: Guerrier | C11: Chapeau | D11: 1 | E11: {=INDEX(Matériaux!$B$5:$F$12,MATCH(INDEX(Profils!$E$5:$E$34,$AE11),Matériaux!$A$5:$A$12,0),$D11)} -> cuir | F11: Légendaire | G11: {=INDEX(Profils!$D$5:$D$34,$AE11)&" en "&$E11} -> Casque en cuir | H11: {=INDEX(Matériaux!$B$16:$B$20,$D11)} -> 1 | I11: =IF(ISNUMBER($C$3),MIN(MAX(0,ROUND($C$3,0)),$AI11),$AI11) -> 0 | J11: =$H11+$I11 -> 1 | K11: — | L11: {=IF(AND(INDEX(Profils!$F$5:$F$34,$AE11)>0,INDEX(Profils!$U$5:$U$34,$AE11)<=$AH11),ROUND(INDEX(Profils!$F$5:$F$34,$AE11)*Paramètres!$E$22*$AG11*$AJ11,Paramètres!$F$22),0)} -> 5 | M11: {=IF(AND(INDEX(Profils!$G$5:$G$34,$AE11)>0,INDEX(Profils!$V$5:$V$34,$AE11)<=$AH11),ROUND(INDEX(Profils!$G$5:$G$34,$AE11)*Paramètres!$E$23*$AG11*$AJ11,Paramètres!$F$23),0)} -> 1 | N11: {=IF(AND(INDEX(Profils!$H$5:$H$34,$AE11)>0,INDEX(Profils!$W$5:$W$34,$AE11)<=$AH11),ROUND(INDEX(Profils!$H$5:$H$34,$AE11)*Paramètres!$E$24*$AG11*$AJ11,Paramètres!$F$24),0)} -> 2 | O11: {=IF(AND(INDEX(Profils!$I$5:$I$34,$AE11)>0,INDEX(Profils!$X$5:$X$34,$AE11)<=$AH11),ROUND(INDEX(Profils!$I$5:$I$34,$AE11)*Paramètres!$E$25*$AG11*$AJ11,Paramètres!$F$25),0)} -> 0 | P11: {=IF(AND(INDEX(Profils!$J$5:$J$34,$AE11)>0,INDEX(Profils!$Y$5:$Y$34,$AE11)<=$AH11),ROUND(INDEX(Profils!$J$5:$J$34,$AE11)*Paramètres!$E$26*$AG11*$AJ11,Paramètres!$F$26),0)} -> 0 | Q11: {=IF(AND(INDEX(Profils!$K$5:$K$34,$AE11)>0,INDEX(Profils!$Z$5:$Z$34,$AE11)<=$AH11),ROUND(INDEX(Profils!$K$5:$K$34,$AE11)*Paramètres!$E$27*$AG11*$AJ11,Paramètres!$F$27),0)} -> 0 | R11: {=IF(AND(INDEX(Profils!$L$5:$L$34,$AE11)>0,INDEX(Profils!$AA$5:$AA$34,$AE11)<=$AH11),ROUND(INDEX(Profils!$L$5:$L$34,$AE11)*Paramètres!$E$28*$AG11*$AJ11,Paramètres!$F$28),0)} -> 0.001 | S11: {=IF(AND(INDEX(Profils!$M$5:$M$34,$AE11)>0,INDEX(Profils!$AB$5:$AB$34,$AE11)<=$AH11),ROUND(INDEX(Profils!$M$5:$M$34,$AE11)*Paramètres!$E$29*$AG11*$AJ11,Paramètres!$F$29),0)} -> 0 | T11: {=IF(AND(INDEX(Profils!$N$5:$N$34,$AE11)>0,INDEX(Profils!$AC$5:$AC$34,$AE11)<=$AH11),ROUND(INDEX(Profils!$N$5:$N$34,$AE11)*Paramètres!$E$30*$AG11*$AJ11,Paramètres!$F$30),0)} -> 0 | U11: {=IF(AND(INDEX(Profils!$O$5:$O$34,$AE11)>0,INDEX(Profils!$AD$5:$AD$34,$AE11)<=$AH11),ROUND(INDEX(Profils!$O$5:$O$34,$AE11)*Paramètres!$E$31*$AG11*$AJ11,Paramètres!$F$31),0)} -> 3 | V11: {=IF(AND(INDEX(Profils!$P$5:$P$34,$AE11)>0,INDEX(Profils!$AE$5:$AE$34,$AE11)<=$AH11),ROUND(INDEX(Profils!$P$5:$P$34,$AE11)*Paramètres!$E$32*$AG11*$AJ11,Paramètres!$F$32),0)} -> 0 | W11: {=IF(AND(INDEX(Profils!$Q$5:$Q$34,$AE11)>0,INDEX(Profils!$AF$5:$AF$34,$AE11)<=$AH11),ROUND(INDEX(Profils!$Q$5:$Q$34,$AE11)*Paramètres!$E$33*$AG11*$AJ11,Paramètres!$F$33),0)} -> 0.001 | X11: {=IF(AND(INDEX(Profils!$R$5:$R$34,$AE11)>0,INDEX(Profils!$AG$5:$AG$34,$AE11)<=$AH11),ROUND(INDEX(Profils!$R$5:$R$34,$AE11)*Paramètres!$E$34*$AG11*$AJ11,Paramètres!$F$34),0)} -> 0 | Y11: {=IF(AND(INDEX(Profils!$S$5:$S$34,$AE11)>0,INDEX(Profils!$AH$5:$AH$34,$AE11)<=$AH11),ROUND(INDEX(Profils!$S$5:$S$34,$AE11)*Paramètres!$E$35*$AG11*$AJ11,Paramètres!$F$35),0)} -> 0.002 | Z11: =ROUND(L11/Paramètres!$E$22+M11/Paramètres!$E$23+N11/Paramètres!$E$24+O11/Paramètres!$E$25+P11/Paramètres!$E$26+Q11/Paramètres!$E$27+R11/Paramètres!$E$28+S11/Paramètres!$E$29+T11/Paramètres!$E$30+U11/Paramètres!$E$31+V11/Paramètres!$E$32+W11/Paramètres!$E$33+X11/Paramètres!$E$34+Y11/Paramètres!$E$35,1) -> 0.8 | AA11: — | AB11: — | AC11: =$E11 -> cuir | AD11: {=IF($I11>=$AI11,"Max",ROUND(Paramètres!$B$40*($I11+1)^Paramètres!$B$41*INDEX(Paramètres!$H$6:$H$12,$AF11),0))} -> 8 | AE11: =MATCH($B11&"|"&$C11,Profils!$A$5:$A$34,0) -> 1 | AF11: 6 | AG11: {=INDEX(Paramètres!$C$6:$C$12,$AF11)} -> 2.4 | AH11: {=INDEX(Paramètres!$D$6:$D$12,$AF11)} -> 7 | AI11: {=INDEX(Matériaux!$C$16:$C$20,$D11)} -> 19 | AJ11: =Paramètres!$B$16+(1-Paramètres!$B$16)*(($J11-Paramètres!$B$14)/(Paramètres!$B$15-Paramètres!$B$14))^Paramètres!$B$17 -> 0.05
A12: GUE-CHA-P2-COM | B12: Guerrier | C12: Chapeau | D12: 2 | E12: {=INDEX(Matériaux!$B$5:$F$12,MATCH(INDEX(Profils!$E$5:$E$34,$AE12),Matériaux!$A$5:$A$12,0),$D12)} -> fer | F12: Commun | G12: {=INDEX(Profils!$D$5:$D$34,$AE12)&" en "&$E12} -> Casque en fer | H12: {=INDEX(Matériaux!$B$16:$B$20,$D12)} -> 15 | I12: =IF(ISNUMBER($C$3),MIN(MAX(0,ROUND($C$3,0)),$AI12),$AI12) -> 0 | J12: =$H12+$I12 -> 15 | K12: — | L12: {=IF(AND(INDEX(Profils!$F$5:$F$34,$AE12)>0,INDEX(Profils!$U$5:$U$34,$AE12)<=$AH12),ROUND(INDEX(Profils!$F$5:$F$34,$AE12)*Paramètres!$E$22*$AG12*$AJ12,Paramètres!$F$22),0)} -> 6 | M12: {=IF(AND(INDEX(Profils!$G$5:$G$34,$AE12)>0,INDEX(Profils!$V$5:$V$34,$AE12)<=$AH12),ROUND(INDEX(Profils!$G$5:$G$34,$AE12)*Paramètres!$E$23*$AG12*$AJ12,Paramètres!$F$23),0)} -> 0 | N12: {=IF(AND(INDEX(Profils!$H$5:$H$34,$AE12)>0,INDEX(Profils!$W$5:$W$34,$AE12)<=$AH12),ROUND(INDEX(Profils!$H$5:$H$34,$AE12)*Paramètres!$E$24*$AG12*$AJ12,Paramètres!$F$24),0)} -> 3 | O12: {=IF(AND(INDEX(Profils!$I$5:$I$34,$AE12)>0,INDEX(Profils!$X$5:$X$34,$AE12)<=$AH12),ROUND(INDEX(Profils!$I$5:$I$34,$AE12)*Paramètres!$E$25*$AG12*$AJ12,Paramètres!$F$25),0)} -> 0 | P12: {=IF(AND(INDEX(Profils!$J$5:$J$34,$AE12)>0,INDEX(Profils!$Y$5:$Y$34,$AE12)<=$AH12),ROUND(INDEX(Profils!$J$5:$J$34,$AE12)*Paramètres!$E$26*$AG12*$AJ12,Paramètres!$F$26),0)} -> 0 | Q12: {=IF(AND(INDEX(Profils!$K$5:$K$34,$AE12)>0,INDEX(Profils!$Z$5:$Z$34,$AE12)<=$AH12),ROUND(INDEX(Profils!$K$5:$K$34,$AE12)*Paramètres!$E$27*$AG12*$AJ12,Paramètres!$F$27),0)} -> 0 | R12: {=IF(AND(INDEX(Profils!$L$5:$L$34,$AE12)>0,INDEX(Profils!$AA$5:$AA$34,$AE12)<=$AH12),ROUND(INDEX(Profils!$L$5:$L$34,$AE12)*Paramètres!$E$28*$AG12*$AJ12,Paramètres!$F$28),0)} -> 0 | S12: {=IF(AND(INDEX(Profils!$M$5:$M$34,$AE12)>0,INDEX(Profils!$AB$5:$AB$34,$AE12)<=$AH12),ROUND(INDEX(Profils!$M$5:$M$34,$AE12)*Paramètres!$E$29*$AG12*$AJ12,Paramètres!$F$29),0)} -> 0 | T12: {=IF(AND(INDEX(Profils!$N$5:$N$34,$AE12)>0,INDEX(Profils!$AC$5:$AC$34,$AE12)<=$AH12),ROUND(INDEX(Profils!$N$5:$N$34,$AE12)*Paramètres!$E$30*$AG12*$AJ12,Paramètres!$F$30),0)} -> 0 | U12: {=IF(AND(INDEX(Profils!$O$5:$O$34,$AE12)>0,INDEX(Profils!$AD$5:$AD$34,$AE12)<=$AH12),ROUND(INDEX(Profils!$O$5:$O$34,$AE12)*Paramètres!$E$31*$AG12*$AJ12,Paramètres!$F$31),0)} -> 0 | V12: {=IF(AND(INDEX(Profils!$P$5:$P$34,$AE12)>0,INDEX(Profils!$AE$5:$AE$34,$AE12)<=$AH12),ROUND(INDEX(Profils!$P$5:$P$34,$AE12)*Paramètres!$E$32*$AG12*$AJ12,Paramètres!$F$32),0)} -> 0 | W12: {=IF(AND(INDEX(Profils!$Q$5:$Q$34,$AE12)>0,INDEX(Profils!$AF$5:$AF$34,$AE12)<=$AH12),ROUND(INDEX(Profils!$Q$5:$Q$34,$AE12)*Paramètres!$E$33*$AG12*$AJ12,Paramètres!$F$33),0)} -> 0 | X12: {=IF(AND(INDEX(Profils!$R$5:$R$34,$AE12)>0,INDEX(Profils!$AG$5:$AG$34,$AE12)<=$AH12),ROUND(INDEX(Profils!$R$5:$R$34,$AE12)*Paramètres!$E$34*$AG12*$AJ12,Paramètres!$F$34),0)} -> 0 | Y12: {=IF(AND(INDEX(Profils!$S$5:$S$34,$AE12)>0,INDEX(Profils!$AH$5:$AH$34,$AE12)<=$AH12),ROUND(INDEX(Profils!$S$5:$S$34,$AE12)*Paramètres!$E$35*$AG12*$AJ12,Paramètres!$F$35),0)} -> 0 | Z12: =ROUND(L12/Paramètres!$E$22+M12/Paramètres!$E$23+N12/Paramètres!$E$24+O12/Paramètres!$E$25+P12/Paramètres!$E$26+Q12/Paramètres!$E$27+R12/Paramètres!$E$28+S12/Paramètres!$E$29+T12/Paramètres!$E$30+U12/Paramètres!$E$31+V12/Paramètres!$E$32+W12/Paramètres!$E$33+X12/Paramètres!$E$34+Y12/Paramètres!$E$35,1) -> 0.4 | AA12: — | AB12: — | AC12: =$E12 -> fer | AD12: {=IF($I12>=$AI12,"Max",ROUND(Paramètres!$B$40*($I12+1)^Paramètres!$B$41*INDEX(Paramètres!$H$6:$H$12,$AF12),0))} -> 3 | AE12: =MATCH($B12&"|"&$C12,Profils!$A$5:$A$34,0) -> 1 | AF12: 1 | AG12: {=INDEX(Paramètres!$C$6:$C$12,$AF12)} -> 1 | AH12: {=INDEX(Paramètres!$D$6:$D$12,$AF12)} -> 2 | AI12: {=INDEX(Matériaux!$C$16:$C$20,$D12)} -> 20 | AJ12: =Paramètres!$B$16+(1-Paramètres!$B$16)*(($J12-Paramètres!$B$14)/(Paramètres!$B$15-Paramètres!$B$14))^Paramètres!$B$17 -> 0.14084793
A13: GUE-CHA-P2-RAR | B13: Guerrier | C13: Chapeau | D13: 2 | E13: {=INDEX(Matériaux!$B$5:$F$12,MATCH(INDEX(Profils!$E$5:$E$34,$AE13),Matériaux!$A$5:$A$12,0),$D13)} -> fer | F13: Rare | G13: {=INDEX(Profils!$D$5:$D$34,$AE13)&" en "&$E13} -> Casque en fer | H13: {=INDEX(Matériaux!$B$16:$B$20,$D13)} -> 15 | I13: =IF(ISNUMBER($C$3),MIN(MAX(0,ROUND($C$3,0)),$AI13),$AI13) -> 0 | J13: =$H13+$I13 -> 15 | K13: — | L13: {=IF(AND(INDEX(Profils!$F$5:$F$34,$AE13)>0,INDEX(Profils!$U$5:$U$34,$AE13)<=$AH13),ROUND(INDEX(Profils!$F$5:$F$34,$AE13)*Paramètres!$E$22*$AG13*$AJ13,Paramètres!$F$22),0)} -> 7 | M13: {=IF(AND(INDEX(Profils!$G$5:$G$34,$AE13)>0,INDEX(Profils!$V$5:$V$34,$AE13)<=$AH13),ROUND(INDEX(Profils!$G$5:$G$34,$AE13)*Paramètres!$E$23*$AG13*$AJ13,Paramètres!$F$23),0)} -> 0 | N13: {=IF(AND(INDEX(Profils!$H$5:$H$34,$AE13)>0,INDEX(Profils!$W$5:$W$34,$AE13)<=$AH13),ROUND(INDEX(Profils!$H$5:$H$34,$AE13)*Paramètres!$E$24*$AG13*$AJ13,Paramètres!$F$24),0)} -> 3 | O13: {=IF(AND(INDEX(Profils!$I$5:$I$34,$AE13)>0,INDEX(Profils!$X$5:$X$34,$AE13)<=$AH13),ROUND(INDEX(Profils!$I$5:$I$34,$AE13)*Paramètres!$E$25*$AG13*$AJ13,Paramètres!$F$25),0)} -> 0 | P13: {=IF(AND(INDEX(Profils!$J$5:$J$34,$AE13)>0,INDEX(Profils!$Y$5:$Y$34,$AE13)<=$AH13),ROUND(INDEX(Profils!$J$5:$J$34,$AE13)*Paramètres!$E$26*$AG13*$AJ13,Paramètres!$F$26),0)} -> 0 | Q13: {=IF(AND(INDEX(Profils!$K$5:$K$34,$AE13)>0,INDEX(Profils!$Z$5:$Z$34,$AE13)<=$AH13),ROUND(INDEX(Profils!$K$5:$K$34,$AE13)*Paramètres!$E$27*$AG13*$AJ13,Paramètres!$F$27),0)} -> 0 | R13: {=IF(AND(INDEX(Profils!$L$5:$L$34,$AE13)>0,INDEX(Profils!$AA$5:$AA$34,$AE13)<=$AH13),ROUND(INDEX(Profils!$L$5:$L$34,$AE13)*Paramètres!$E$28*$AG13*$AJ13,Paramètres!$F$28),0)} -> 0 | S13: {=IF(AND(INDEX(Profils!$M$5:$M$34,$AE13)>0,INDEX(Profils!$AB$5:$AB$34,$AE13)<=$AH13),ROUND(INDEX(Profils!$M$5:$M$34,$AE13)*Paramètres!$E$29*$AG13*$AJ13,Paramètres!$F$29),0)} -> 0 | T13: {=IF(AND(INDEX(Profils!$N$5:$N$34,$AE13)>0,INDEX(Profils!$AC$5:$AC$34,$AE13)<=$AH13),ROUND(INDEX(Profils!$N$5:$N$34,$AE13)*Paramètres!$E$30*$AG13*$AJ13,Paramètres!$F$30),0)} -> 0 | U13: {=IF(AND(INDEX(Profils!$O$5:$O$34,$AE13)>0,INDEX(Profils!$AD$5:$AD$34,$AE13)<=$AH13),ROUND(INDEX(Profils!$O$5:$O$34,$AE13)*Paramètres!$E$31*$AG13*$AJ13,Paramètres!$F$31),0)} -> 4 | V13: {=IF(AND(INDEX(Profils!$P$5:$P$34,$AE13)>0,INDEX(Profils!$AE$5:$AE$34,$AE13)<=$AH13),ROUND(INDEX(Profils!$P$5:$P$34,$AE13)*Paramètres!$E$32*$AG13*$AJ13,Paramètres!$F$32),0)} -> 0 | W13: {=IF(AND(INDEX(Profils!$Q$5:$Q$34,$AE13)>0,INDEX(Profils!$AF$5:$AF$34,$AE13)<=$AH13),ROUND(INDEX(Profils!$Q$5:$Q$34,$AE13)*Paramètres!$E$33*$AG13*$AJ13,Paramètres!$F$33),0)} -> 0 | X13: {=IF(AND(INDEX(Profils!$R$5:$R$34,$AE13)>0,INDEX(Profils!$AG$5:$AG$34,$AE13)<=$AH13),ROUND(INDEX(Profils!$R$5:$R$34,$AE13)*Paramètres!$E$34*$AG13*$AJ13,Paramètres!$F$34),0)} -> 0 | Y13: {=IF(AND(INDEX(Profils!$S$5:$S$34,$AE13)>0,INDEX(Profils!$AH$5:$AH$34,$AE13)<=$AH13),ROUND(INDEX(Profils!$S$5:$S$34,$AE13)*Paramètres!$E$35*$AG13*$AJ13,Paramètres!$F$35),0)} -> 0 | Z13: =ROUND(L13/Paramètres!$E$22+M13/Paramètres!$E$23+N13/Paramètres!$E$24+O13/Paramètres!$E$25+P13/Paramètres!$E$26+Q13/Paramètres!$E$27+R13/Paramètres!$E$28+S13/Paramètres!$E$29+T13/Paramètres!$E$30+U13/Paramètres!$E$31+V13/Paramètres!$E$32+W13/Paramètres!$E$33+X13/Paramètres!$E$34+Y13/Paramètres!$E$35,1) -> 0.7 | AA13: — | AB13: — | AC13: =$E13 -> fer | AD13: {=IF($I13>=$AI13,"Max",ROUND(Paramètres!$B$40*($I13+1)^Paramètres!$B$41*INDEX(Paramètres!$H$6:$H$12,$AF13),0))} -> 4 | AE13: =MATCH($B13&"|"&$C13,Profils!$A$5:$A$34,0) -> 1 | AF13: 2 | AG13: {=INDEX(Paramètres!$C$6:$C$12,$AF13)} -> 1.2 | AH13: {=INDEX(Paramètres!$D$6:$D$12,$AF13)} -> 3 | AI13: {=INDEX(Matériaux!$C$16:$C$20,$D13)} -> 20 | AJ13: =Paramètres!$B$16+(1-Paramètres!$B$16)*(($J13-Paramètres!$B$14)/(Paramètres!$B$15-Paramètres!$B$14))^Paramètres!$B$17 -> 0.14084793
A14: GUE-CHA-P2-SRA | B14: Guerrier | C14: Chapeau | D14: 2 | E14: {=INDEX(Matériaux!$B$5:$F$12,MATCH(INDEX(Profils!$E$5:$E$34,$AE14),Matériaux!$A$5:$A$12,0),$D14)} -> fer | F14: Super rare | G14: {=INDEX(Profils!$D$5:$D$34,$AE14)&" en "&$E14} -> Casque en fer | H14: {=INDEX(Matériaux!$B$16:$B$20,$D14)} -> 15 | I14: =IF(ISNUMBER($C$3),MIN(MAX(0,ROUND($C$3,0)),$AI14),$AI14) -> 0 | J14: =$H14+$I14 -> 15 | K14: — | L14: {=IF(AND(INDEX(Profils!$F$5:$F$34,$AE14)>0,INDEX(Profils!$U$5:$U$34,$AE14)<=$AH14),ROUND(INDEX(Profils!$F$5:$F$34,$AE14)*Paramètres!$E$22*$AG14*$AJ14,Paramètres!$F$22),0)} -> 8 | M14: {=IF(AND(INDEX(Profils!$G$5:$G$34,$AE14)>0,INDEX(Profils!$V$5:$V$34,$AE14)<=$AH14),ROUND(INDEX(Profils!$G$5:$G$34,$AE14)*Paramètres!$E$23*$AG14*$AJ14,Paramètres!$F$23),0)} -> 0 | N14: {=IF(AND(INDEX(Profils!$H$5:$H$34,$AE14)>0,INDEX(Profils!$W$5:$W$34,$AE14)<=$AH14),ROUND(INDEX(Profils!$H$5:$H$34,$AE14)*Paramètres!$E$24*$AG14*$AJ14,Paramètres!$F$24),0)} -> 4 | O14: {=IF(AND(INDEX(Profils!$I$5:$I$34,$AE14)>0,INDEX(Profils!$X$5:$X$34,$AE14)<=$AH14),ROUND(INDEX(Profils!$I$5:$I$34,$AE14)*Paramètres!$E$25*$AG14*$AJ14,Paramètres!$F$25),0)} -> 0 | P14: {=IF(AND(INDEX(Profils!$J$5:$J$34,$AE14)>0,INDEX(Profils!$Y$5:$Y$34,$AE14)<=$AH14),ROUND(INDEX(Profils!$J$5:$J$34,$AE14)*Paramètres!$E$26*$AG14*$AJ14,Paramètres!$F$26),0)} -> 0 | Q14: {=IF(AND(INDEX(Profils!$K$5:$K$34,$AE14)>0,INDEX(Profils!$Z$5:$Z$34,$AE14)<=$AH14),ROUND(INDEX(Profils!$K$5:$K$34,$AE14)*Paramètres!$E$27*$AG14*$AJ14,Paramètres!$F$27),0)} -> 0 | R14: {=IF(AND(INDEX(Profils!$L$5:$L$34,$AE14)>0,INDEX(Profils!$AA$5:$AA$34,$AE14)<=$AH14),ROUND(INDEX(Profils!$L$5:$L$34,$AE14)*Paramètres!$E$28*$AG14*$AJ14,Paramètres!$F$28),0)} -> 0 | S14: {=IF(AND(INDEX(Profils!$M$5:$M$34,$AE14)>0,INDEX(Profils!$AB$5:$AB$34,$AE14)<=$AH14),ROUND(INDEX(Profils!$M$5:$M$34,$AE14)*Paramètres!$E$29*$AG14*$AJ14,Paramètres!$F$29),0)} -> 0 | T14: {=IF(AND(INDEX(Profils!$N$5:$N$34,$AE14)>0,INDEX(Profils!$AC$5:$AC$34,$AE14)<=$AH14),ROUND(INDEX(Profils!$N$5:$N$34,$AE14)*Paramètres!$E$30*$AG14*$AJ14,Paramètres!$F$30),0)} -> 0 | U14: {=IF(AND(INDEX(Profils!$O$5:$O$34,$AE14)>0,INDEX(Profils!$AD$5:$AD$34,$AE14)<=$AH14),ROUND(INDEX(Profils!$O$5:$O$34,$AE14)*Paramètres!$E$31*$AG14*$AJ14,Paramètres!$F$31),0)} -> 5 | V14: {=IF(AND(INDEX(Profils!$P$5:$P$34,$AE14)>0,INDEX(Profils!$AE$5:$AE$34,$AE14)<=$AH14),ROUND(INDEX(Profils!$P$5:$P$34,$AE14)*Paramètres!$E$32*$AG14*$AJ14,Paramètres!$F$32),0)} -> 0 | W14: {=IF(AND(INDEX(Profils!$Q$5:$Q$34,$AE14)>0,INDEX(Profils!$AF$5:$AF$34,$AE14)<=$AH14),ROUND(INDEX(Profils!$Q$5:$Q$34,$AE14)*Paramètres!$E$33*$AG14*$AJ14,Paramètres!$F$33),0)} -> 0 | X14: {=IF(AND(INDEX(Profils!$R$5:$R$34,$AE14)>0,INDEX(Profils!$AG$5:$AG$34,$AE14)<=$AH14),ROUND(INDEX(Profils!$R$5:$R$34,$AE14)*Paramètres!$E$34*$AG14*$AJ14,Paramètres!$F$34),0)} -> 0 | Y14: {=IF(AND(INDEX(Profils!$S$5:$S$34,$AE14)>0,INDEX(Profils!$AH$5:$AH$34,$AE14)<=$AH14),ROUND(INDEX(Profils!$S$5:$S$34,$AE14)*Paramètres!$E$35*$AG14*$AJ14,Paramètres!$F$35),0)} -> 0.003 | Z14: =ROUND(L14/Paramètres!$E$22+M14/Paramètres!$E$23+N14/Paramètres!$E$24+O14/Paramètres!$E$25+P14/Paramètres!$E$26+Q14/Paramètres!$E$27+R14/Paramètres!$E$28+S14/Paramètres!$E$29+T14/Paramètres!$E$30+U14/Paramètres!$E$31+V14/Paramètres!$E$32+W14/Paramètres!$E$33+X14/Paramètres!$E$34+Y14/Paramètres!$E$35,1) -> 1 | AA14: — | AB14: — | AC14: =$E14 -> fer | AD14: {=IF($I14>=$AI14,"Max",ROUND(Paramètres!$B$40*($I14+1)^Paramètres!$B$41*INDEX(Paramètres!$H$6:$H$12,$AF14),0))} -> 4 | AE14: =MATCH($B14&"|"&$C14,Profils!$A$5:$A$34,0) -> 1 | AF14: 3 | AG14: {=INDEX(Paramètres!$C$6:$C$12,$AF14)} -> 1.45 | AH14: {=INDEX(Paramètres!$D$6:$D$12,$AF14)} -> 4 | AI14: {=INDEX(Matériaux!$C$16:$C$20,$D14)} -> 20 | AJ14: =Paramètres!$B$16+(1-Paramètres!$B$16)*(($J14-Paramètres!$B$14)/(Paramètres!$B$15-Paramètres!$B$14))^Paramètres!$B$17 -> 0.14084793
A15: GUE-CHA-P2-EPI | B15: Guerrier | C15: Chapeau | D15: 2 | E15: {=INDEX(Matériaux!$B$5:$F$12,MATCH(INDEX(Profils!$E$5:$E$34,$AE15),Matériaux!$A$5:$A$12,0),$D15)} -> fer | F15: Épique | G15: {=INDEX(Profils!$D$5:$D$34,$AE15)&" en "&$E15} -> Casque en fer | H15: {=INDEX(Matériaux!$B$16:$B$20,$D15)} -> 15 | I15: =IF(ISNUMBER($C$3),MIN(MAX(0,ROUND($C$3,0)),$AI15),$AI15) -> 0 | J15: =$H15+$I15 -> 15 | K15: — | L15: {=IF(AND(INDEX(Profils!$F$5:$F$34,$AE15)>0,INDEX(Profils!$U$5:$U$34,$AE15)<=$AH15),ROUND(INDEX(Profils!$F$5:$F$34,$AE15)*Paramètres!$E$22*$AG15*$AJ15,Paramètres!$F$22),0)} -> 10 | M15: {=IF(AND(INDEX(Profils!$G$5:$G$34,$AE15)>0,INDEX(Profils!$V$5:$V$34,$AE15)<=$AH15),ROUND(INDEX(Profils!$G$5:$G$34,$AE15)*Paramètres!$E$23*$AG15*$AJ15,Paramètres!$F$23),0)} -> 0 | N15: {=IF(AND(INDEX(Profils!$H$5:$H$34,$AE15)>0,INDEX(Profils!$W$5:$W$34,$AE15)<=$AH15),ROUND(INDEX(Profils!$H$5:$H$34,$AE15)*Paramètres!$E$24*$AG15*$AJ15,Paramètres!$F$24),0)} -> 4 | O15: {=IF(AND(INDEX(Profils!$I$5:$I$34,$AE15)>0,INDEX(Profils!$X$5:$X$34,$AE15)<=$AH15),ROUND(INDEX(Profils!$I$5:$I$34,$AE15)*Paramètres!$E$25*$AG15*$AJ15,Paramètres!$F$25),0)} -> 0 | P15: {=IF(AND(INDEX(Profils!$J$5:$J$34,$AE15)>0,INDEX(Profils!$Y$5:$Y$34,$AE15)<=$AH15),ROUND(INDEX(Profils!$J$5:$J$34,$AE15)*Paramètres!$E$26*$AG15*$AJ15,Paramètres!$F$26),0)} -> 0 | Q15: {=IF(AND(INDEX(Profils!$K$5:$K$34,$AE15)>0,INDEX(Profils!$Z$5:$Z$34,$AE15)<=$AH15),ROUND(INDEX(Profils!$K$5:$K$34,$AE15)*Paramètres!$E$27*$AG15*$AJ15,Paramètres!$F$27),0)} -> 0 | R15: {=IF(AND(INDEX(Profils!$L$5:$L$34,$AE15)>0,INDEX(Profils!$AA$5:$AA$34,$AE15)<=$AH15),ROUND(INDEX(Profils!$L$5:$L$34,$AE15)*Paramètres!$E$28*$AG15*$AJ15,Paramètres!$F$28),0)} -> 0 | S15: {=IF(AND(INDEX(Profils!$M$5:$M$34,$AE15)>0,INDEX(Profils!$AB$5:$AB$34,$AE15)<=$AH15),ROUND(INDEX(Profils!$M$5:$M$34,$AE15)*Paramètres!$E$29*$AG15*$AJ15,Paramètres!$F$29),0)} -> 0 | T15: {=IF(AND(INDEX(Profils!$N$5:$N$34,$AE15)>0,INDEX(Profils!$AC$5:$AC$34,$AE15)<=$AH15),ROUND(INDEX(Profils!$N$5:$N$34,$AE15)*Paramètres!$E$30*$AG15*$AJ15,Paramètres!$F$30),0)} -> 0 | U15: {=IF(AND(INDEX(Profils!$O$5:$O$34,$AE15)>0,INDEX(Profils!$AD$5:$AD$34,$AE15)<=$AH15),ROUND(INDEX(Profils!$O$5:$O$34,$AE15)*Paramètres!$E$31*$AG15*$AJ15,Paramètres!$F$31),0)} -> 6 | V15: {=IF(AND(INDEX(Profils!$P$5:$P$34,$AE15)>0,INDEX(Profils!$AE$5:$AE$34,$AE15)<=$AH15),ROUND(INDEX(Profils!$P$5:$P$34,$AE15)*Paramètres!$E$32*$AG15*$AJ15,Paramètres!$F$32),0)} -> 0 | W15: {=IF(AND(INDEX(Profils!$Q$5:$Q$34,$AE15)>0,INDEX(Profils!$AF$5:$AF$34,$AE15)<=$AH15),ROUND(INDEX(Profils!$Q$5:$Q$34,$AE15)*Paramètres!$E$33*$AG15*$AJ15,Paramètres!$F$33),0)} -> 0.002 | X15: {=IF(AND(INDEX(Profils!$R$5:$R$34,$AE15)>0,INDEX(Profils!$AG$5:$AG$34,$AE15)<=$AH15),ROUND(INDEX(Profils!$R$5:$R$34,$AE15)*Paramètres!$E$34*$AG15*$AJ15,Paramètres!$F$34),0)} -> 0 | Y15: {=IF(AND(INDEX(Profils!$S$5:$S$34,$AE15)>0,INDEX(Profils!$AH$5:$AH$34,$AE15)<=$AH15),ROUND(INDEX(Profils!$S$5:$S$34,$AE15)*Paramètres!$E$35*$AG15*$AJ15,Paramètres!$F$35),0)} -> 0.004 | Z15: =ROUND(L15/Paramètres!$E$22+M15/Paramètres!$E$23+N15/Paramètres!$E$24+O15/Paramètres!$E$25+P15/Paramètres!$E$26+Q15/Paramètres!$E$27+R15/Paramètres!$E$28+S15/Paramètres!$E$29+T15/Paramètres!$E$30+U15/Paramètres!$E$31+V15/Paramètres!$E$32+W15/Paramètres!$E$33+X15/Paramètres!$E$34+Y15/Paramètres!$E$35,1) -> 1.4 | AA15: — | AB15: — | AC15: =$E15 -> fer | AD15: {=IF($I15>=$AI15,"Max",ROUND(Paramètres!$B$40*($I15+1)^Paramètres!$B$41*INDEX(Paramètres!$H$6:$H$12,$AF15),0))} -> 5 | AE15: =MATCH($B15&"|"&$C15,Profils!$A$5:$A$34,0) -> 1 | AF15: 4 | AG15: {=INDEX(Paramètres!$C$6:$C$12,$AF15)} -> 1.75 | AH15: {=INDEX(Paramètres!$D$6:$D$12,$AF15)} -> 5 | AI15: {=INDEX(Matériaux!$C$16:$C$20,$D15)} -> 20 | AJ15: =Paramètres!$B$16+(1-Paramètres!$B$16)*(($J15-Paramètres!$B$14)/(Paramètres!$B$15-Paramètres!$B$14))^Paramètres!$B$17 -> 0.14084793
A16: GUE-CHA-P2-MYT | B16: Guerrier | C16: Chapeau | D16: 2 | E16: {=INDEX(Matériaux!$B$5:$F$12,MATCH(INDEX(Profils!$E$5:$E$34,$AE16),Matériaux!$A$5:$A$12,0),$D16)} -> fer | F16: Mythique | G16: {=INDEX(Profils!$D$5:$D$34,$AE16)&" en "&$E16} -> Casque en fer | H16: {=INDEX(Matériaux!$B$16:$B$20,$D16)} -> 15 | I16: =IF(ISNUMBER($C$3),MIN(MAX(0,ROUND($C$3,0)),$AI16),$AI16) -> 0 | J16: =$H16+$I16 -> 15 | K16: — | L16: {=IF(AND(INDEX(Profils!$F$5:$F$34,$AE16)>0,INDEX(Profils!$U$5:$U$34,$AE16)<=$AH16),ROUND(INDEX(Profils!$F$5:$F$34,$AE16)*Paramètres!$E$22*$AG16*$AJ16,Paramètres!$F$22),0)} -> 12 | M16: {=IF(AND(INDEX(Profils!$G$5:$G$34,$AE16)>0,INDEX(Profils!$V$5:$V$34,$AE16)<=$AH16),ROUND(INDEX(Profils!$G$5:$G$34,$AE16)*Paramètres!$E$23*$AG16*$AJ16,Paramètres!$F$23),0)} -> 2 | N16: {=IF(AND(INDEX(Profils!$H$5:$H$34,$AE16)>0,INDEX(Profils!$W$5:$W$34,$AE16)<=$AH16),ROUND(INDEX(Profils!$H$5:$H$34,$AE16)*Paramètres!$E$24*$AG16*$AJ16,Paramètres!$F$24),0)} -> 5 | O16: {=IF(AND(INDEX(Profils!$I$5:$I$34,$AE16)>0,INDEX(Profils!$X$5:$X$34,$AE16)<=$AH16),ROUND(INDEX(Profils!$I$5:$I$34,$AE16)*Paramètres!$E$25*$AG16*$AJ16,Paramètres!$F$25),0)} -> 0 | P16: {=IF(AND(INDEX(Profils!$J$5:$J$34,$AE16)>0,INDEX(Profils!$Y$5:$Y$34,$AE16)<=$AH16),ROUND(INDEX(Profils!$J$5:$J$34,$AE16)*Paramètres!$E$26*$AG16*$AJ16,Paramètres!$F$26),0)} -> 0 | Q16: {=IF(AND(INDEX(Profils!$K$5:$K$34,$AE16)>0,INDEX(Profils!$Z$5:$Z$34,$AE16)<=$AH16),ROUND(INDEX(Profils!$K$5:$K$34,$AE16)*Paramètres!$E$27*$AG16*$AJ16,Paramètres!$F$27),0)} -> 0 | R16: {=IF(AND(INDEX(Profils!$L$5:$L$34,$AE16)>0,INDEX(Profils!$AA$5:$AA$34,$AE16)<=$AH16),ROUND(INDEX(Profils!$L$5:$L$34,$AE16)*Paramètres!$E$28*$AG16*$AJ16,Paramètres!$F$28),0)} -> 0 | S16: {=IF(AND(INDEX(Profils!$M$5:$M$34,$AE16)>0,INDEX(Profils!$AB$5:$AB$34,$AE16)<=$AH16),ROUND(INDEX(Profils!$M$5:$M$34,$AE16)*Paramètres!$E$29*$AG16*$AJ16,Paramètres!$F$29),0)} -> 0 | T16: {=IF(AND(INDEX(Profils!$N$5:$N$34,$AE16)>0,INDEX(Profils!$AC$5:$AC$34,$AE16)<=$AH16),ROUND(INDEX(Profils!$N$5:$N$34,$AE16)*Paramètres!$E$30*$AG16*$AJ16,Paramètres!$F$30),0)} -> 0 | U16: {=IF(AND(INDEX(Profils!$O$5:$O$34,$AE16)>0,INDEX(Profils!$AD$5:$AD$34,$AE16)<=$AH16),ROUND(INDEX(Profils!$O$5:$O$34,$AE16)*Paramètres!$E$31*$AG16*$AJ16,Paramètres!$F$31),0)} -> 7 | V16: {=IF(AND(INDEX(Profils!$P$5:$P$34,$AE16)>0,INDEX(Profils!$AE$5:$AE$34,$AE16)<=$AH16),ROUND(INDEX(Profils!$P$5:$P$34,$AE16)*Paramètres!$E$32*$AG16*$AJ16,Paramètres!$F$32),0)} -> 0 | W16: {=IF(AND(INDEX(Profils!$Q$5:$Q$34,$AE16)>0,INDEX(Profils!$AF$5:$AF$34,$AE16)<=$AH16),ROUND(INDEX(Profils!$Q$5:$Q$34,$AE16)*Paramètres!$E$33*$AG16*$AJ16,Paramètres!$F$33),0)} -> 0.003 | X16: {=IF(AND(INDEX(Profils!$R$5:$R$34,$AE16)>0,INDEX(Profils!$AG$5:$AG$34,$AE16)<=$AH16),ROUND(INDEX(Profils!$R$5:$R$34,$AE16)*Paramètres!$E$34*$AG16*$AJ16,Paramètres!$F$34),0)} -> 0 | Y16: {=IF(AND(INDEX(Profils!$S$5:$S$34,$AE16)>0,INDEX(Profils!$AH$5:$AH$34,$AE16)<=$AH16),ROUND(INDEX(Profils!$S$5:$S$34,$AE16)*Paramètres!$E$35*$AG16*$AJ16,Paramètres!$F$35),0)} -> 0.004 | Z16: =ROUND(L16/Paramètres!$E$22+M16/Paramètres!$E$23+N16/Paramètres!$E$24+O16/Paramètres!$E$25+P16/Paramètres!$E$26+Q16/Paramètres!$E$27+R16/Paramètres!$E$28+S16/Paramètres!$E$29+T16/Paramètres!$E$30+U16/Paramètres!$E$31+V16/Paramètres!$E$32+W16/Paramètres!$E$33+X16/Paramètres!$E$34+Y16/Paramètres!$E$35,1) -> 1.8 | AA16: — | AB16: — | AC16: =$E16 -> fer | AD16: {=IF($I16>=$AI16,"Max",ROUND(Paramètres!$B$40*($I16+1)^Paramètres!$B$41*INDEX(Paramètres!$H$6:$H$12,$AF16),0))} -> 6 | AE16: =MATCH($B16&"|"&$C16,Profils!$A$5:$A$34,0) -> 1 | AF16: 5 | AG16: {=INDEX(Paramètres!$C$6:$C$12,$AF16)} -> 2.1 | AH16: {=INDEX(Paramètres!$D$6:$D$12,$AF16)} -> 6 | AI16: {=INDEX(Matériaux!$C$16:$C$20,$D16)} -> 20 | AJ16: =Paramètres!$B$16+(1-Paramètres!$B$16)*(($J16-Paramètres!$B$14)/(Paramètres!$B$15-Paramètres!$B$14))^Paramètres!$B$17 -> 0.14084793
A17: GUE-CHA-P2-LEG | B17: Guerrier | C17: Chapeau | D17: 2 | E17: {=INDEX(Matériaux!$B$5:$F$12,MATCH(INDEX(Profils!$E$5:$E$34,$AE17),Matériaux!$A$5:$A$12,0),$D17)} -> fer | F17: Légendaire | G17: {=INDEX(Profils!$D$5:$D$34,$AE17)&" en "&$E17} -> Casque en fer | H17: {=INDEX(Matériaux!$B$16:$B$20,$D17)} -> 15 | I17: =IF(ISNUMBER($C$3),MIN(MAX(0,ROUND($C$3,0)),$AI17),$AI17) -> 0 | J17: =$H17+$I17 -> 15 | K17: — | L17: {=IF(AND(INDEX(Profils!$F$5:$F$34,$AE17)>0,INDEX(Profils!$U$5:$U$34,$AE17)<=$AH17),ROUND(INDEX(Profils!$F$5:$F$34,$AE17)*Paramètres!$E$22*$AG17*$AJ17,Paramètres!$F$22),0)} -> 14 | M17: {=IF(AND(INDEX(Profils!$G$5:$G$34,$AE17)>0,INDEX(Profils!$V$5:$V$34,$AE17)<=$AH17),ROUND(INDEX(Profils!$G$5:$G$34,$AE17)*Paramètres!$E$23*$AG17*$AJ17,Paramètres!$F$23),0)} -> 3 | N17: {=IF(AND(INDEX(Profils!$H$5:$H$34,$AE17)>0,INDEX(Profils!$W$5:$W$34,$AE17)<=$AH17),ROUND(INDEX(Profils!$H$5:$H$34,$AE17)*Paramètres!$E$24*$AG17*$AJ17,Paramètres!$F$24),0)} -> 6 | O17: {=IF(AND(INDEX(Profils!$I$5:$I$34,$AE17)>0,INDEX(Profils!$X$5:$X$34,$AE17)<=$AH17),ROUND(INDEX(Profils!$I$5:$I$34,$AE17)*Paramètres!$E$25*$AG17*$AJ17,Paramètres!$F$25),0)} -> 0 | P17: {=IF(AND(INDEX(Profils!$J$5:$J$34,$AE17)>0,INDEX(Profils!$Y$5:$Y$34,$AE17)<=$AH17),ROUND(INDEX(Profils!$J$5:$J$34,$AE17)*Paramètres!$E$26*$AG17*$AJ17,Paramètres!$F$26),0)} -> 0 | Q17: {=IF(AND(INDEX(Profils!$K$5:$K$34,$AE17)>0,INDEX(Profils!$Z$5:$Z$34,$AE17)<=$AH17),ROUND(INDEX(Profils!$K$5:$K$34,$AE17)*Paramètres!$E$27*$AG17*$AJ17,Paramètres!$F$27),0)} -> 0 | R17: {=IF(AND(INDEX(Profils!$L$5:$L$34,$AE17)>0,INDEX(Profils!$AA$5:$AA$34,$AE17)<=$AH17),ROUND(INDEX(Profils!$L$5:$L$34,$AE17)*Paramètres!$E$28*$AG17*$AJ17,Paramètres!$F$28),0)} -> 0.002 | S17: {=IF(AND(INDEX(Profils!$M$5:$M$34,$AE17)>0,INDEX(Profils!$AB$5:$AB$34,$AE17)<=$AH17),ROUND(INDEX(Profils!$M$5:$M$34,$AE17)*Paramètres!$E$29*$AG17*$AJ17,Paramètres!$F$29),0)} -> 0 | T17: {=IF(AND(INDEX(Profils!$N$5:$N$34,$AE17)>0,INDEX(Profils!$AC$5:$AC$34,$AE17)<=$AH17),ROUND(INDEX(Profils!$N$5:$N$34,$AE17)*Paramètres!$E$30*$AG17*$AJ17,Paramètres!$F$30),0)} -> 0 | U17: {=IF(AND(INDEX(Profils!$O$5:$O$34,$AE17)>0,INDEX(Profils!$AD$5:$AD$34,$AE17)<=$AH17),ROUND(INDEX(Profils!$O$5:$O$34,$AE17)*Paramètres!$E$31*$AG17*$AJ17,Paramètres!$F$31),0)} -> 8 | V17: {=IF(AND(INDEX(Profils!$P$5:$P$34,$AE17)>0,INDEX(Profils!$AE$5:$AE$34,$AE17)<=$AH17),ROUND(INDEX(Profils!$P$5:$P$34,$AE17)*Paramètres!$E$32*$AG17*$AJ17,Paramètres!$F$32),0)} -> 0 | W17: {=IF(AND(INDEX(Profils!$Q$5:$Q$34,$AE17)>0,INDEX(Profils!$AF$5:$AF$34,$AE17)<=$AH17),ROUND(INDEX(Profils!$Q$5:$Q$34,$AE17)*Paramètres!$E$33*$AG17*$AJ17,Paramètres!$F$33),0)} -> 0.003 | X17: {=IF(AND(INDEX(Profils!$R$5:$R$34,$AE17)>0,INDEX(Profils!$AG$5:$AG$34,$AE17)<=$AH17),ROUND(INDEX(Profils!$R$5:$R$34,$AE17)*Paramètres!$E$34*$AG17*$AJ17,Paramètres!$F$34),0)} -> 0 | Y17: {=IF(AND(INDEX(Profils!$S$5:$S$34,$AE17)>0,INDEX(Profils!$AH$5:$AH$34,$AE17)<=$AH17),ROUND(INDEX(Profils!$S$5:$S$34,$AE17)*Paramètres!$E$35*$AG17*$AJ17,Paramètres!$F$35),0)} -> 0.005 | Z17: =ROUND(L17/Paramètres!$E$22+M17/Paramètres!$E$23+N17/Paramètres!$E$24+O17/Paramètres!$E$25+P17/Paramètres!$E$26+Q17/Paramètres!$E$27+R17/Paramètres!$E$28+S17/Paramètres!$E$29+T17/Paramètres!$E$30+U17/Paramètres!$E$31+V17/Paramètres!$E$32+W17/Paramètres!$E$33+X17/Paramètres!$E$34+Y17/Paramètres!$E$35,1) -> 2.2 | AA17: — | AB17: — | AC17: =$E17 -> fer | AD17: {=IF($I17>=$AI17,"Max",ROUND(Paramètres!$B$40*($I17+1)^Paramètres!$B$41*INDEX(Paramètres!$H$6:$H$12,$AF17),0))} -> 8 | AE17: =MATCH($B17&"|"&$C17,Profils!$A$5:$A$34,0) -> 1 | AF17: 6 | AG17: {=INDEX(Paramètres!$C$6:$C$12,$AF17)} -> 2.4 | AH17: {=INDEX(Paramètres!$D$6:$D$12,$AF17)} -> 7 | AI17: {=INDEX(Matériaux!$C$16:$C$20,$D17)} -> 20 | AJ17: =Paramètres!$B$16+(1-Paramètres!$B$16)*(($J17-Paramètres!$B$14)/(Paramètres!$B$15-Paramètres!$B$14))^Paramètres!$B$17 -> 0.14084793
... A35: GUE-CHA-P5-LEG | B35: Guerrier | C35: Chapeau | D35: 5 | E35: {=INDEX(Matériaux!$B$5:$F$12,MATCH(INDEX(Profils!$E$5:$E$34,$AE35),Matériaux!$A$5:$A$12,0),$D35)} -> adamantite | F35: Légendaire | G35: {=INDEX(Profils!$D$5:$D$34,$AE35)&" en "&$E35} -> Casque en adamantite | H35: {=INDEX(Matériaux!$B$16:$B$20,$D35)} -> 70 | I35: =IF(ISNUMBER($C$3),MIN(MAX(0,ROUND($C$3,0)),$AI35),$AI35) -> 0 | J35: =$H35+$I35 -> 70 | K35: — | L35: {=IF(AND(INDEX(Profils!$F$5:$F$34,$AE35)>0,INDEX(Profils!$U$5:$U$34,$AE35)<=$AH35),ROUND(INDEX(Profils!$F$5:$F$34,$AE35)*Paramètres!$E$22*$AG35*$AJ35,Paramètres!$F$22),0)} -> 64 | M35: {=IF(AND(INDEX(Profils!$G$5:$G$34,$AE35)>0,INDEX(Profils!$V$5:$V$34,$AE35)<=$AH35),ROUND(INDEX(Profils!$G$5:$G$34,$AE35)*Paramètres!$E$23*$AG35*$AJ35,Paramètres!$F$23),0)} -> 12 | N35: {=IF(AND(INDEX(Profils!$H$5:$H$34,$AE35)>0,INDEX(Profils!$W$5:$W$34,$AE35)<=$AH35),ROUND(INDEX(Profils!$H$5:$H$34,$AE35)*Paramètres!$E$24*$AG35*$AJ35,Paramètres!$F$24),0)} -> 29 | O35: {=IF(AND(INDEX(Profils!$I$5:$I$34,$AE35)>0,INDEX(Profils!$X$5:$X$34,$AE35)<=$AH35),ROUND(INDEX(Profils!$I$5:$I$34,$AE35)*Paramètres!$E$25*$AG35*$AJ35,Paramètres!$F$25),0)} -> 0 | P35: {=IF(AND(INDEX(Profils!$J$5:$J$34,$AE35)>0,INDEX(Profils!$Y$5:$Y$34,$AE35)<=$AH35),ROUND(INDEX(Profils!$J$5:$J$34,$AE35)*Paramètres!$E$26*$AG35*$AJ35,Paramètres!$F$26),0)} -> 0 | Q35: {=IF(AND(INDEX(Profils!$K$5:$K$34,$AE35)>0,INDEX(Profils!$Z$5:$Z$34,$AE35)<=$AH35),ROUND(INDEX(Profils!$K$5:$K$34,$AE35)*Paramètres!$E$27*$AG35*$AJ35,Paramètres!$F$27),0)} -> 0 | R35: {=IF(AND(INDEX(Profils!$L$5:$L$34,$AE35)>0,INDEX(Profils!$AA$5:$AA$34,$AE35)<=$AH35),ROUND(INDEX(Profils!$L$5:$L$34,$AE35)*Paramètres!$E$28*$AG35*$AJ35,Paramètres!$F$28),0)} -> 0.01 | S35: {=IF(AND(INDEX(Profils!$M$5:$M$34,$AE35)>0,INDEX(Profils!$AB$5:$AB$34,$AE35)<=$AH35),ROUND(INDEX(Profils!$M$5:$M$34,$AE35)*Paramètres!$E$29*$AG35*$AJ35,Paramètres!$F$29),0)} -> 0 | T35: {=IF(AND(INDEX(Profils!$N$5:$N$34,$AE35)>0,INDEX(Profils!$AC$5:$AC$34,$AE35)<=$AH35),ROUND(INDEX(Profils!$N$5:$N$34,$AE35)*Paramètres!$E$30*$AG35*$AJ35,Paramètres!$F$30),0)} -> 0 | U35: {=IF(AND(INDEX(Profils!$O$5:$O$34,$AE35)>0,INDEX(Profils!$AD$5:$AD$34,$AE35)<=$AH35),ROUND(INDEX(Profils!$O$5:$O$34,$AE35)*Paramètres!$E$31*$AG35*$AJ35,Paramètres!$F$31),0)} -> 38 | V35: {=IF(AND(INDEX(Profils!$P$5:$P$34,$AE35)>0,INDEX(Profils!$AE$5:$AE$34,$AE35)<=$AH35),ROUND(INDEX(Profils!$P$5:$P$34,$AE35)*Paramètres!$E$32*$AG35*$AJ35,Paramètres!$F$32),0)} -> 0 | W35: {=IF(AND(INDEX(Profils!$Q$5:$Q$34,$AE35)>0,INDEX(Profils!$AF$5:$AF$34,$AE35)<=$AH35),ROUND(INDEX(Profils!$Q$5:$Q$34,$AE35)*Paramètres!$E$33*$AG35*$AJ35,Paramètres!$F$33),0)} -> 0.014 | X35: {=IF(AND(INDEX(Profils!$R$5:$R$34,$AE35)>0,INDEX(Profils!$AG$5:$AG$34,$AE35)<=$AH35),ROUND(INDEX(Profils!$R$5:$R$34,$AE35)*Paramètres!$E$34*$AG35*$AJ35,Paramètres!$F$34),0)} -> 0 | Y35: {=IF(AND(INDEX(Profils!$S$5:$S$34,$AE35)>0,INDEX(Profils!$AH$5:$AH$34,$AE35)<=$AH35),ROUND(INDEX(Profils!$S$5:$S$34,$AE35)*Paramètres!$E$35*$AG35*$AJ35,Paramètres!$F$35),0)} -> 0.024 | Z35: =ROUND(L35/Paramètres!$E$22+M35/Paramètres!$E$23+N35/Paramètres!$E$24+O35/Paramètres!$E$25+P35/Paramètres!$E$26+Q35/Paramètres!$E$27+R35/Paramètres!$E$28+S35/Paramètres!$E$29+T35/Paramètres!$E$30+U35/Paramètres!$E$31+V35/Paramètres!$E$32+W35/Paramètres!$E$33+X35/Paramètres!$E$34+Y35/Paramètres!$E$35,1) -> 10.4 | AA35: — | AB35: — | AC35: =$E35 -> adamantite | AD35: {=IF($I35>=$AI35,"Max",ROUND(Paramètres!$B$40*($I35+1)^Paramètres!$B$41*INDEX(Paramètres!$H$6:$H$12,$AF35),0))} -> 8 | AE35: =MATCH($B35&"|"&$C35,Profils!$A$5:$A$34,0) -> 1 | AF35: 6 | AG35: {=INDEX(Paramètres!$C$6:$C$12,$AF35)} -> 2.4 | AH35: {=INDEX(Paramètres!$D$6:$D$12,$AF35)} -> 7 | AI35: {=INDEX(Matériaux!$C$16:$C$20,$D35)} -> 30 | AJ35: =Paramètres!$B$16+(1-Paramètres!$B$16)*(($J35-Paramètres!$B$14)/(Paramètres!$B$15-Paramètres!$B$14))^Paramètres!$B$17 -> 0.66599939
